Workbook
Name a: #REF!
Name a: #REF!
Name ddd: #N/A
Name h: #REF!,#REF!
Name h: #REF!,#REF!
Name INDIC_ECOFIN: #REF!
Name INDIC_ECOFIN: #REF!

Sheet Índice

Sheet Pressupostos
C2: 2024 | D2: =+C2+1 -> 2025 | E2: =+D2+1 -> 2026 | F2: =+E2+1 -> 2027 | G2: =+F2+1 -> 2028 | H2: =+G2+1 -> 2029 | I2: =+H2+1 -> 2030 | J2: =+I2+1 -> 2031 | K2: =+J2+1 -> 2032 | ... Q2: =+P2+1 -> 2038
A3: Inflação | C3: 0.022 | D3: 0.022 | E3: 0.021 | F3: =+E3 -> 0.021 | G3: 0.02 | H3: =+G3 -> 0.02 | I3: 0.019 | J3: =+I3 -> 0.019 | K3: 0.018 | L3: =+K3 -> 0.018 | M3: 0.017 | N3: =+M3 -> 0.017 | O3: =+N3 -> 0.017 | P3: =+O3 -> 0.017 | Q3: =+P3 -> 0.017
A4: Índice Acumulado Inflação | C4: 1 | D4: =+C4*(1+D3) -> 1.022 | E4: =+D4*(1+E3) -> 1.043462 | F4: =+E4*(1+F3) -> 1.0653747 | G4: =+F4*(1+G3) -> 1.0866822 | H4: =+G4*(1+H3) -> 1.1084158 | I4: =+H4*(1+I3) -> 1.1294757 | J4: =+I4*(1+J3) -> 1.1509358 | K4: =+J4*(1+K3) -> 1.1716526 | ... Q4: =+P4*(1+Q3) -> 1.2976316
A6: Descrição
A7: Unidade monetária | B7: Euros
A8: 1º Ano actividade | B8: 2024
A10: Descrição
A11: Prazo médio de Recebimento (dias) | B11: 35
A12: Prazo médio de Pagamento (dias) | B12: 60
A13: Prazo médio de Stock (dias) | B13: 7
A14: Prazo Médio EOEP | B14: 30
A16: Descrição
A17: Taxa de IVA - Prestação Serviços | B17: 0.23
A18: Taxa de IVA - CMVMC | B18: 0.23
A19: Taxa de IVA - FSE | B19: 0.23
A20: Taxa de IVA - Investimento | B20: 0.23
A22: Descrição
A23: TSU - Entidade - órgãos sociais | B23: 0.2375
A24: TSU- Entidade - colaboradores | B24: 0.2375
A25: TSU - Pessoal - órgãos sociais | B25: 0.11
A26: TSU - Pessoal - colaboradores | B26: 0.11
A27: Taxa de IRC | B27: 0.21
A30: Índice

Sheet Previsão Receitas
A1: Descrição | B1: 2024 | C1: =+B1+1 -> 2025 | D1: =+C1+1 -> 2026 | E1: =+D1+1 -> 2027 | F1: =+E1+1 -> 2028 | G1: =+F1+1 -> 2029 | H1: =+G1+1 -> 2030
A3: Produtos atuais | B3: 16975038 | C3: =B3*1.02 -> 17314539 | D3: =C3*1.02 -> 17660830 | E3: =D3*1.02 -> 18014047 | F3: =E3*1.02 -> 18374327 | G3: =F3*1.02 -> 18741814 | H3: =G3*1.02 -> 19116650
A4: Novos produtos | C4: 0 | D4: =D3*0.025 -> 441520.75 | E4: =E3*0.03 -> 540421.4 | F4: =F3*0.045 -> 826844.74 | G4: =G3*0.04 -> 749672.56 | H4: =H3*0.025 -> 477916.26
A8: TOTAL | B8: =SUM(B2:B7) -> 16975038 | C8: =SUM(C2:C7) -> 17314539 | D8: =SUM(D2:D7) -> 18102351 | E8: =SUM(E2:E7) -> 18554468 | F8: =SUM(F2:F7) -> 19201172 | G8: =SUM(G2:G7) -> 19491487 | H8: =SUM(H2:H7) -> 19594567
C9: =C8/B8 -> 1.02 | D9: =D8/C8 -> 1.0455 | E9: =E8/D8 -> 1.0249756 | F9: =F8/E8 -> 1.0348544 | G9: =G8/F8 -> 1.0151196 | H9: =H8/G8 -> 1.0052885
A11: VOLUME DE NEGÓCIOS POR MERCADO 2022
A12: Mercado Nacional | B12: 1 | E12: =+$F$8*B12 -> 19201172 | F12: 448909.7
A13: França | B13: 0 | E13: =+$F$8*B13 -> 0 | F13: 138126.06
A14: Marrocos | B14: 0 | E14: =+$F$8*B14 -> 0 | F14: 34531.515
A15: Alemanha | B15: 0 | E15: =+$F$8*B15 -> 0 | F15: 34531.515
A16: Espanha | B16: 0 | E16: =+$F$8*B16 -> 0 | F16: 34531.515
B17: =SUM(B12:B16) -> 1 | E17: =SUM(E12:E16) -> 19201172
D20: =+D8*0.05 -> 905117.54 | E20: =+(F8-304916.94)/F8 -> 0.98411988

Sheet Fornecimento  Serviços Externos
A1: FSE´s PROJETO | B1: Valor Mês | C1: 2024 | D1: =+C1+1 -> 2025 | E1: =+D1+1 -> 2026 | F1: =+E1+1 -> 2027 | G1: =+F1+1 -> 2028 | H1: =+G1+1 -> 2029 | I1: =+H1+1 -> 2030 | J1: =+I1+1 -> 2031 | K1: =+J1+1 -> 2032 | L1: =+K1+1 -> 2033
A2: 621 - Subcontratos | B2: 0 | C2: 0 | D2: =+$B$2*12 -> 0 | E2: =D2*E19 -> 0 | F2: =E2*F19 -> 0 | G2: =F2*G19 -> 0 | H2: =G2*H19 -> 0 | I2: =H2*I19 -> 0 | J2: =I2*J19 -> 0 | K2: =J2*K19 -> 0 | L2: =K2*L19 -> 0
A3: 622 - Serviços Especializados | B3: 26000 | C3: 300843.14 | D3: =+$B$3*12 -> 312000 | E3: =D3*E19 -> 335400 | F3: =E3*F19 -> 358878 | G3: =F3*G19 -> 358878 | H3: =G3*H19 -> 369644.34 | I3: =H3*I19 -> 380733.67 | J3: =I3*J19 -> 392155.68 | K3: =J3*K19 -> 403920.35 | L3: =K3*L19 -> 416037.96
A4: 623 - Materiais | B4: 5000 | C4: 50737.41 | D4: =+B4*12 -> 60000 | E4: =D4*E19 -> 64500 | F4: =E4*F19 -> 69015 | G4: =F4*G19 -> 69015 | H4: =G4*H19 -> 71085.45 | I4: =H4*I19 -> 73218.014 | J4: =I4*J19 -> 75414.554 | K4: =J4*K19 -> 77676.991 | L4: =K4*L19 -> 80007.3
A5: 624 - Energia e Fluidos | B5: 22000 | C5: 255161.06 | D5: =+B5*12 -> 264000 | E5: =D5*E20 -> 277200 | F5: =E5*F20 -> 288288 | G5: =F5*G20 -> 288288 | H5: =G5*H20 -> 294053.76 | I5: =H5*I20 -> 299934.84 | J5: =I5*J20 -> 305933.53 | K5: =J5*K20 -> 312052.2 | L5: =K5*L20 -> 318293.25
A6: 625- Deslocações, Estadas e transportes | B6: 9500 | C6: 105923.98 | D6: =+$B$6*12 -> 114000 | E6: =D6*E19 -> 122550 | F6: =E6*F19 -> 131128.5 | G6: =F6*G19 -> 131128.5 | H6: =G6*H19 -> 135062.36 | I6: =H6*I19 -> 139114.23 | J6: =I6*J19 -> 143287.65 | K6: =J6*K19 -> 147586.28 | L6: =K6*L19 -> 152013.87
A7: 626 - Serviços Diversos | B7: 13500 | C7: 158625.38 | D7: =+$B$7*12 -> 162000 | E7: =D7*E20 -> 170100 | F7: =E7*F20 -> 176904 | G7: =F7*G20 -> 176904 | H7: =G7*H20 -> 180442.08 | I7: =H7*I20 -> 184050.92 | J7: =I7*J20 -> 187731.94 | K7: =J7*K20 -> 191486.58 | L7: =K7*L20 -> 195316.31
D8: =+$B$8*12 -> 0 | E8: =D8*E20 -> 0 | F8: =E8*F20 -> 0 | G8: =F8*G20 -> 0 | H8: =G8*H20 -> 0 | I8: =H8*I20 -> 0 | J8: =I8*J20 -> 0 | K8: =J8*K20 -> 0 | L8: =K8*L20 -> 0
D9: =+$B$9*12 -> 0 | E9: =D9*E19 -> 0 | F9: =E9*F19 -> 0 | G9: =F9*G19 -> 0 | H9: =G9*H19 -> 0 | I9: =H9*I19 -> 0 | J9: =I9*J19 -> 0 | K9: =J9*K19 -> 0 | L9: =K9*L19 -> 0
D10: =+$B$10*12 -> 0 | E10: =D10*E19 -> 0 | F10: =E10*F19 -> 0 | G10: =F10*G19 -> 0 | H10: =G10*H19 -> 0 | I10: =H10*I19 -> 0 | J10: =I10*J19 -> 0 | K10: =J10*K19 -> 0 | L10: =K10*L19 -> 0
D11: =+$B$11*12 -> 0 | E11: =D11*E20 -> 0 | F11: =E11*F20 -> 0 | G11: =F11*G20 -> 0 | H11: =G11*H20 -> 0 | I11: =H11*I20 -> 0 | J11: =I11*J20 -> 0 | K11: =J11*K20 -> 0 | L11: =K11*L20 -> 0
D12: =+$B$12*12 -> 0 | E12: =D12*E19 -> 0 | F12: =E12*F19 -> 0 | G12: =F12*G19 -> 0 | H12: =G12*H19 -> 0 | I12: =H12*I19 -> 0 | J12: =I12*J19 -> 0 | K12: =J12*K19 -> 0 | L12: =K12*L19 -> 0
D13: =+$B$13*12 -> 0 | E13: =D13*E19 -> 0 | F13: =E13*F19 -> 0 | G13: =F13*G19 -> 0 | H13: =G13*H19 -> 0 | I13: =H13*I19 -> 0 | J13: =I13*J19 -> 0 | K13: =J13*K19 -> 0 | L13: =K13*L19 -> 0
D14: =+$B$14*12 -> 0 | E14: =D14*E19 -> 0 | F14: =E14*F19 -> 0 | G14: =F14*G19 -> 0 | H14: =G14*H19 -> 0 | I14: =H14*I19 -> 0 | J14: =I14*J19 -> 0 | K14: =J14*K19 -> 0 | L14: =K14*L19 -> 0
D15: =+$B$15*12 -> 0 | E15: =D15*E19 -> 0 | F15: =E15*F19 -> 0 | G15: =F15*G19 -> 0 | H15: =G15*H19 -> 0 | I15: =H15*I19 -> 0 | J15: =I15*J19 -> 0 | K15: =J15*K19 -> 0 | L15: =K15*L19 -> 0
A16: 62- FSE´s Projeto
C18: =SUM(C2:C17) -> 871290.97 | D18: =SUM(D2:D17) -> 912000 | E18: =SUM(E2:E17) -> 969750 | F18: =SUM(F2:F17) -> 1024213.5 | G18: =SUM(G2:G17) -> 1024213.5 | H18: =SUM(H2:H17) -> 1050288 | I18: =SUM(I2:I17) -> 1077051.7 | J18: =SUM(J2:J17) -> 1104523.4 | ... L18: =SUM(L2:L17) -> 1161668.7
A19: Serviços especializados e RH related | E19: 1.075 | F19: 1.07 | G19: 1 | H19: 1.03 | I19: 1.03 | J19: 1.03 | K19: 1.03 | L19: 1.03
A20: Outros Serviços | E20: 1.05 | F20: 1.04 | G20: 1 | H20: 1.02 | I20: 1.02 | J20: 1.02 | K20: 1.02 | L20: 1.02
E21: =E18/D18 -> 1.0633224 | F21: =F18/E18 -> 1.0561624 | G21: =G18/F18 -> 1 | H21: =H18/G18 -> 1.0254581 | I21: =I18/H18 -> 1.0254822 | J21: =J18/I18 -> 1.0255064 | K21: =K18/J18 -> 1.0255305 | L21: =L18/K18 -> 1.0255546

Sheet Capital Circulante
B1: 2024 | C1: =+B1+1 -> 2025 | D1: =+C1+1 -> 2026 | E1: =+D1+1 -> 2027 | F1: =+E1+1 -> 2028 | G1: =+F1+1 -> 2029 | H1: =+G1+1 -> 2030
A2: Necessidades Financeiras de Exploração | B2: =SUM(B3:B4) -> 1920188.1 | C2: =SUM(C3:C4) -> 1958587 | D2: =SUM(D3:D4) -> 2047702.7 | E2: =SUM(E3:E4) -> 2098845.3 | F2: =SUM(F3:F4) -> 2167332.3 | G2: =SUM(G3:G4) -> 2202944.1 | H2: =SUM(H3:H4) -> 2214594.2
A3: Clientes | B3: =+'Previsão Receitas'!B8/360*Pressupostos!$B$11 -> 1650351 | C3: =+'Previsão Receitas'!C8/360*Pressupostos!$B$11 -> 1683358 | D3: =+'Previsão Receitas'!D8/360*Pressupostos!$B$11 -> 1759950.8 | E3: =+'Previsão Receitas'!E8/360*Pressupostos!$B$11 -> 1803906.6 | F3: =+'Previsão Receitas'!F8/360*Pressupostos!$B$11 -> 1866780.6 | G3: =+'Previsão Receitas'!G8/360*Pressupostos!$B$11 -> 1895005.6 | H3: =+'Previsão Receitas'!H8/360*Pressupostos!$B$11 -> 1905027.3
A4: Existências | B4: =B13/360*Pressupostos!$B$13 -> 269837.13 | C4: =C13/360*Pressupostos!$B$13 -> 275229.03 | D4: =D13/360*Pressupostos!$B$13 -> 287751.95 | E4: =E13/360*Pressupostos!$B$13 -> 294938.73 | F4: =F13/360*Pressupostos!$B$13 -> 300551.68 | G4: =G13/360*Pressupostos!$B$13 -> 307938.42 | H4: =H13/360*Pressupostos!$B$13 -> 309566.94
A5: Recursos Financeiros de Exploração | B5: =SUM(B6:B6) -> 2312889.7 | C5: =SUM(C6:C6) -> 2359106 | D5: =SUM(D6:D6) -> 2466445.3 | E5: =SUM(E6:E6) -> 2528046.3 | F5: =SUM(F6:F6) -> 2576157.3 | G5: =SUM(G6:G6) -> 2639472.1 | H5: =SUM(H6:H6) -> 2653430.9
A6: Fornecedores | B6: =(+'Fornecimento Serviços Externos'!C2+B18)/360*Pressupostos!$B$12 -> 2312889.7 | C6: =(+'Fornecimento Serviços Externos'!D2+C18)/360*Pressupostos!$B$12 -> 2359106 | D6: =(+'Fornecimento Serviços Externos'!E2+D18)/360*Pressupostos!$B$12 -> 2466445.3 | E6: =(+'Fornecimento Serviços Externos'!F2+E18)/360*Pressupostos!$B$12 -> 2528046.3 | F6: =(+'Fornecimento Serviços Externos'!G2+F18)/360*Pressupostos!$B$12 -> 2576157.3 | G6: =(+'Fornecimento Serviços Externos'!H2+G18)/360*Pressupostos!$B$12 -> 2639472.1 | H6: =(+'Fornecimento Serviços Externos'!I2+H18)/360*Pressupostos!$B$12 -> 2653430.9
A7: Fundo Maneio | B7: =B2-B5 -> -392701.59 | C7: =C2-C5 -> -400518.96 | D7: =D2-D5 -> -418742.57 | E7: =E2-E5 -> -429200.92 | F7: =F2-F5 -> -408824.96 | G7: =G2-G5 -> -436528.09 | H7: =H2-H5 -> -438836.65
A8: Variação Fundo Maneio | B8: =B7 -> -392701.59 | C8: =C7-B7 -> -7817.3689 | D8: =D7-C7 -> -18223.613 | E8: =E7-D7 -> -10458.351 | F8: =F7-E7 -> 20375.963 | G8: =G7-F7 -> -27703.127 | H8: =H7-G7 -> -2308.562
A10: Mapa das Compras
B12: 2024 | C12: =+B12+1 -> 2025 | D12: =+C12+1 -> 2026 | E12: =+D12+1 -> 2027 | F12: =+E12+1 -> 2028 | G12: =+F12+1 -> 2029 | H12: =+G12+1 -> 2030
A13: CMVMC | B13: =+B18 -> 13877338 | C13: =+C18 -> 14154636 | D13: =+D18 -> 14798672 | E13: =+E18 -> 15168278 | F13: =+F18 -> 15456944 | G13: =+G18 -> 15836833 | H13: =+H18 -> 15920585
A14: + Existências Finais | B14: 0 | C14: 0 | D14: 0 | E14: 0 | F14: 0 | G14: 0 | H14: 0
A15: - Existências Iniciais | B15: 0 | C15: =B14 -> 0 | D15: =C14 -> 0 | E15: =D14 -> 0 | F15: =E14 -> 0 | G15: =F14 -> 0 | H15: =G14 -> 0
A16: Compras | B16: =B13+B14-B15 -> 13877338 | C16: =C13+C14-C15 -> 14154636 | D16: =D13+D14-D15 -> 14798672 | E16: =E13+E14-E15 -> 15168278 | F16: =F13+F14-F15 -> 15456944 | G16: =G13+G14-G15 -> 15836833 | H16: =H13+H14-H15 -> 15920585
A18: CMVMC | B18: 13877338 | C18: =+'Previsão Receitas'!C8*0.8175 -> 14154636 | D18: =+'Previsão Receitas'!D8*0.8175 -> 14798672 | E18: =+'Previsão Receitas'!E8*0.8175 -> 15168278 | F18: =+'Previsão Receitas'!F8*0.805 -> 15456944 | G18: =+'Previsão Receitas'!G8*0.8125 -> 15836833 | H18: =+'Previsão Receitas'!H8*0.8125 -> 15920585
A20: Índice
B22: =B18/'Previsão Receitas'!B3 -> 0.81751438

Sheet 63_G. Pess.
A1: Recursos Humanos | C1: Encargos Mensais pessoal | G1: Valor Ano
B2: N | C2: Vencimento Base | D2: Outros encargos mensais | E2: Encargos Sociais | F2: Total
A3: RECURSOS HUMANOS ATUAIS | B3: 71 | C3: 1440 | D3: 26.33993 | E3: =+C3*0.2 -> 288 | F3: =+C3+E3+D3 -> 1754.3399 | G3: =+F3*14*B3-0.02 -> 1743813.9 | H3: Nota: Encargos patronais alterados para 20% por causa do IES 2024. Futuramente corrigir para 23,75%
A4: Técnico Informática | B4: 1 | C4: 2150 | D4: 0 | E4: =+C4*0.2375 -> 510.625 | F4: =+C4+E4+D4 -> 2660.625 | G4: =+F4*14*B4+0.25 -> 37249
A11: TOTAL € | B11: =SUM(B3:B10) -> 72 | C11: =SUM(C3:C10) -> 3590 | D11: =SUM(D3:D10) -> 26.33993 | E11: =SUM(E3:E10) -> 798.625 | F11: =SUM(F3:F3) -> 1754.3399 | G11: =SUM(G3:G10) -> 1781062.9
C14: 2024 | D14: =+C14+1 -> 2025 | E14: =+D14+1 -> 2026 | F14: =+E14+1 -> 2027 | G14: =+F14+1 -> 2028 | H14: =+G14+1 -> 2029 | I14: =+H14+1 -> 2030
A15: Encargos Totais Com o Pessoal | C15: =+G3 -> 1743813.9 | D15: =C15*1.02 -> 1778690.1 | E15: =+$G$11*1.04 -> 1852305.4 | F15: =E15*1.02 -> 1889351.5 | G15: =F15*1.02 -> 1927138.5 | H15: =G15*1.02 -> 1965681.3 | I15: =H15*1.02 -> 2004994.9
C17: 1743813.9
A19: Índice

Sheet Amortizações
A1: Investimento | L1: Mapa Amortizações
A2: Nº | B2: DESIGNAÇÃO | C2: 0 | D2: 2024 | E2: =+D2+1 -> 2025 | F2: =+E2+1 -> 2026 | G2: =+F2+1 -> 2027 | H2: =+G2+1 -> 2028 | I2: =+H2+1 -> 2029 | J2: =+I2+1 -> 2030 | K2: 2026 | L2: % | M2: 2024 | N2: =+M2+1 -> 2025 | O2: =+N2+1 -> 2026 | P2: =+O2+1 -> 2027 | Q2: =+P2+1 -> 2028 | R2: =+Q2+1 -> 2029 | S2: =+R2+1 -> 2030 | T2: =+S2+1 -> 2031
A4: ATIVO TANGÍVEL
B5: TOTAL | C5: =SUM(C6:C12) -> 1497425.5 | D5: =SUM(D6:D12) -> 1330054.7 | E5: =SUM(E6:E12) -> 1162683.9 | F5: =SUM(F6:F12) -> 995313.07 | G5: =SUM(G6:G12) -> 827942.26 | H5: =SUM(H6:H12) -> 660571.44 | I5: =SUM(I6:I12) -> 493200.63 | J5: =SUM(J6:J12) -> 325829.82
B6: Imobilizado Existente na Empresa | C6: =1330054.7+167370.81 -> 1497425.5 | D6: =+C6-M6 -> 1330054.7 | E6: =+D6-M6 -> 1162683.9 | F6: =+E6-N6 -> 995313.07 | G6: =+F6-O6 -> 827942.26 | H6: =+G6-P6 -> 660571.44 | I6: =+H6-Q6 -> 493200.63 | J6: =+I6-R6 -> 325829.82 | L6: 0.11177238 | M6: =+$C$6*$L$6 -> 167370.81 | N6: =+$C$6*$L$6 -> 167370.81 | O6: =+$C$6*$L$6 -> 167370.81 | P6: =+$C$6*$L$6 -> 167370.81 | Q6: =+$C$6*$L$6 -> 167370.81 | R6: =+$C$6*$L$6 -> 167370.81 | S6: =+$C$6*$L$6 -> 167370.81
B7: Investimento de reposição | E7: =+C7-N7 -> 0 | F7: =+E7-O7 -> 0 | G7: =+F7-P7 -> 0 | H7: =+G7-Q7 -> 0 | I7: =+H7-R7 -> 0 | L7: 0.2 | N7: =+$C$7*$L$7 -> 0 | O7: =+$C$7*$L$7 -> 0 | P7: =+$C$7*$L$7 -> 0 | Q7: =+$C$7*$L$7 -> 0 | R7: =+$C$7*$L$7 -> 0
F8: =+C8-O8 -> 0 | G8: =+F8-P8 -> 0 | H8: =+G8-Q8 -> 0 | I8: =+H8-R8 -> 0 | J8: =+I8-S8 -> 0 | L8: 0.2 | O8: =+$C$8*$L$8 -> 0 | P8: =+$C$8*$L$8 -> 0 | Q8: =+$C$8*$L$8 -> 0 | R8: =+$C$8*$L$8 -> 0 | S8: =+$C$8*$L$8 -> 0
E9: =+C9-N9 -> 0 | F9: =+E9-O9 -> 0 | G9: =+F9-P9 -> 0 | H9: =+G9-Q9 -> 0 | I9: =+H9-R9 -> 0 | L9: 0.2 | N9: =+$C$9*$L$9 -> 0 | O9: =+$C$9*$L$9 -> 0 | P9: =+$C$9*$L$9 -> 0 | Q9: =+$C$9*$L$9 -> 0 | R9: =+$C$9*$L$9 -> 0
E10: =+C10-N10 -> 0 | F10: =+E10-O10 -> 0 | G10: =+F10-P10 -> 0 | H10: =+G10-Q10 -> 0 | I10: =+H10-R10 -> 0 | L10: 0.2 | N10: =+$C$10*$L$10 -> 0 | O10: =+$C$10*$L$10 -> 0 | P10: =+$C$10*$L$10 -> 0 | Q10: =+$C$10*$L$10 -> 0 | R10: =+$C$10*$L$10 -> 0
A13: ATIVO INTANGÍVEL
B14: TOTAL | C14: =SUM(C15:C19) -> 75210 | D14: =SUM(D15:D19) -> 0 | E14: =SUM(E15:E19) -> 0 | F14: =SUM(F15:F19) -> 37605 | G14: =SUM(G15:G19) -> 62675 | H14: =SUM(H15:H19) -> 37605 | I14: =SUM(I15:I19) -> 12535 | J14: =SUM(J15:J19) -> 0
B15: Desenvolvimento e Banco de Dados | C15: 25000 | F15: 12500 | G15: =+F15-O15+12500 -> 20833.333 | H15: =+G15-P15 -> 12500 | I15: =+H15-Q15 -> 4166.6667 | J15: 0 | L15: 0.33333333 | N15: =+$E$15*$L$15 -> 0 | O15: =F15*L15 -> 4166.6667 | P15: =+$C$15*$L$15 -> 8333.3333 | Q15: =+$C$15*$L$15 -> 8333.3333 | R15: =+$C$15*$L$15-4166.67 -> 4166.6633 | S15: 0 | T15: =+$E$15*$L$15 -> 0
B16: Licenças e Ferramentas | C16: 9710 | F16: 4855 | G16: =+F16-O16+4855 -> 8091.6667 | H16: =+G16-P16 -> 4855 | I16: =+H16-Q16 -> 1618.3333 | L16: 0.33333333 | O16: =F16*L16 -> 1618.3333 | P16: =+$C$16*$L$16 -> 3236.6667 | Q16: =+$C$16*$L$16 -> 3236.6667 | R16: =+$C$16*$L$16-1618.33 -> 1618.3367 | S16: =+$E$16*$L$16 -> 0
B17: Consumo de Tokens | C17: 8000 | F17: 4000 | G17: =+F17-O17+4000 -> 6666.6667 | H17: =+G17-P17 -> 4000 | I17: =+H17-Q17 -> 1333.3333 | J17: 0 | L17: 0.33333333 | N17: =+$E$15*$L$15 -> 0 | O17: =F17*L17 -> 1333.3333 | P17: =+$C$17*$L$17 -> 2666.6667 | Q17: =+$C$17*$L$17 -> 2666.6667 | R17: =+$C$17*$L$17-1333.33 -> 1333.3367 | S17: 0 | T17: =+$E$15*$L$15 -> 0
B18: Consultoria (Integração e Formação) | C18: 30000 | F18: 15000 | G18: =+F18-O18+15000 -> 25000 | H18: =+G18-P18 -> 15000 | I18: =+H18-Q18 -> 5000 | J18: 0 | L18: 0.33333333 | N18: =+$E$15*$L$15 -> 0 | O18: =F18*L18 -> 5000 | P18: =+$C$18*$L$18 -> 10000 | Q18: =+$C$18*$L$18 -> 10000 | R18: =+$C$18*$L$18-5000 -> 5000 | S18: 0 | T18: =+$E$15*$L$15 -> 0
B19: Validação de Despesas (Outros Serviços de Consultoria) | C19: 2500 | F19: 1250 | G19: =+F19-O19+1250 -> 2083.3333 | H19: =+G19-P19 -> 1250 | I19: =+H19-Q19 -> 416.66667 | J19: 0 | L19: 0.33333333 | N19: =+$E$15*$L$15 -> 0 | O19: =F19*L19 -> 416.66667 | P19: =+$C$19*$L$19 -> 833.33333 | Q19: =+$C$19*$L$19 -> 833.33333 | R19: =+$C$19*$L$19-416.66 -> 416.67333 | S19: 0
D20: =SUM(D15:D19) -> 0 | E20: =SUM(E15:E19) -> 0 | F20: =SUM(F15:F19) -> 37605 | G20: =SUM(G15:G19) -> 62675 | H20: =SUM(H15:H19) -> 37605 | I20: =SUM(I15:I19) -> 12535 | M20: =SUM(M6:M16) -> 167370.81 | N20: =SUM(N6:N16) -> 167370.81 | O20: =SUM(O6:O16) -> 173155.81 | P20: =SUM(P6:P16) -> 178940.81 | Q20: =SUM(Q6:Q16) -> 178940.81 | R20: =SUM(R6:R16) -> 173155.81 | S20: =SUM(S6:S16) -> 167370.81 | T20: =SUM(T6:T16) -> 0
A24: Índice
B29: Desenvolvimento e Banco de Dados | C29: 12500 | D29: 12500 | E29: 167370.81
B30: Licenças e Ferramentas | C30: 4855 | D30: 4855
B31: Consumo de Tokens | C31: 4000 | D31: 4000
B32: Consultoria (Integração e formação) | C32: 15000 | D32: 15000

Sheet Serviço da Divida Emp. Bancario
A1: FINANCIAMENTO REEMBOLSÁVEL P2020
A3: Rubricas | C3: 2025 | D3: =+C3+1 -> 2026 | E3: =+D3+1 -> 2027 | F3: =+E3+1 -> 2028 | G3: =+F3+1 -> 2029 | H3: =+G3+1 -> 2030 | I3: =+H3+1 -> 2031 | J3: =+I3+1 -> 2032 | K3: =+J3+1 -> 2033 | L3: =+K3+1 -> 2034
A5: Capital em dívida (início período) | B5: =+'MAPA INVESTIMENTOS'!B21+'MAPA INVESTIMENTOS'!C21 -> 0 | C5: =+B5 -> 0 | D5: =+C5 -> 0 | E5: =+B5 -> 0 | F5: =+E8 -> 0 | G5: =+F8 -> 0 | H5: =+G8 -> 0 | I5: =+H8 -> 0 | J5: =+I8 -> 0 | K5: =+J8 -> 0 | L5: =+K8 -> 0
A6: Juro Anual | C6: =+C5*$B$10 -> 0 | D6: =+D5*$B$10 -> 0 | E6: =+E5*$B$10 -> 0 | F6: =+F5*$B$10 -> 0 | G6: =+G5*$B$10 -> 0 | H6: =+H5*$B$10 -> 0 | I6: =+I5*$B$10 -> 0 | J6: =+J5*$B$10 -> 0 | ... L6: =+L5*$B$10 -> 0
A7: Reembolso Anual | C7: 0 | D7: 0 | E7: =+$B$5/8 -> 0 | F7: =+$B$5/8 -> 0 | G7: =+$B$5/8 -> 0 | H7: =+$B$5/8 -> 0 | I7: =+$B$5/8 -> 0 | J7: =+$B$5/8 -> 0 | K7: =+$B$5/8 -> 0 | L7: =+$B$5/8 -> 0
A8: Valor em dívida | C8: =+C5-C7 -> 0 | D8: =+D5-D7 -> 0 | E8: =+E5-E7 -> 0 | F8: =+F5-F7 -> 0 | G8: =+G5-G7 -> 0 | H8: =+H5-H7 -> 0 | I8: =+I5-I7 -> 0 | J8: =+J5-J7 -> 0 | ... L8: =+L5-L7 -> 0
A10: Taxa de juro associada | B10: 0
A12: Nº DE ANOS REEMBOLSO | B12: 8
A14: FINANCIAMENTO EXISTENTE NA EMPRESA
A16: Rubricas | C16: 2024 | D16: =+C16+1 -> 2025 | E16: =+D16+1 -> 2026 | F16: =+E16+1 -> 2027 | G16: =+F16+1 -> 2028 | H16: =+G16+1 -> 2029 | I16: =+H16+1 -> 2030 | J16: =+I16+1 -> 2031 | K16: =+J16+1 -> 2032 | L16: =+K16+1 -> 2033
A18: Capital em dívida (início período) | B18: 299677.05 | C18: =+B18 -> 299677.05 | D18: =+C21 -> 262217.42 | E18: =+D21 -> 224757.79 | F18: =+E21 -> 187298.16 | G18: =+F21 -> 149838.52 | H18: =+G21 -> 112378.89 | I18: =+H21 -> 74919.262 | J18: =+I21 -> 37459.631 | K18: =+J21 -> 0
A19: Juro Anual | C19: =+C18*$B$23 -> 14983.853 | D19: =+D18*$B$23 -> 13110.871 | E19: =+E18*$B$23 -> 11237.889 | F19: =+F18*$B$23 -> 9364.9078 | G19: =+G18*$B$23 -> 7491.9263 | H19: =+H18*$B$23 -> 5618.9447 | I19: =+I18*$B$23 -> 3745.9631 | J19: =+J18*$B$23 -> 1872.9816 | ... L19: =+L18*$B$23 -> 0
A20: Reembolso Anual | C20: =+$B$18/$B$25 -> 37459.631 | D20: =+$B$18/$B$25 -> 37459.631 | E20: =+$B$18/$B$25 -> 37459.631 | F20: =+$B$18/$B$25 -> 37459.631 | G20: =+$B$18/$B$25 -> 37459.631 | H20: =+$B$18/$B$25 -> 37459.631 | I20: =+$B$18/$B$25 -> 37459.631 | J20: =+$B$18/8 -> 37459.631 | K20: =+$B$18/8 -> 37459.631 | L20: =+$B$18/$B$25 -> 37459.631
A21: Valor em dívida | C21: =+C18-C20 -> 262217.42 | D21: =+D18-D20 -> 224757.79 | E21: =+E18-E20 -> 187298.16 | F21: =+F18-F20 -> 149838.52 | G21: =+G18-G20 -> 112378.89 | H21: =+H18-H20 -> 74919.262 | I21: =+I18-I20 -> 37459.631 | J21: =+J18-J20 -> 0 | ... L21: =+L18-L20 -> -37459.631
A23: Taxa de juro associada | B23: 0.05
A25: Nº DE ANOS REEMBOLSO | B25: 8

Sheet Mov dos Impostos S Rendi
A3: Rubricas | B3: 2025 | C3: =+B3+1 -> 2026 | D3: =+C3+1 -> 2027 | E3: =+D3+1 -> 2028 | F3: =+E3+1 -> 2029 | G3: =+F3+1 -> 2030 | H3: =+G3+1 -> 2031
A4: Colecta de IRC 17% | B4: =-'DR SNC'!F30 -> 4250 | C4: =-'DR SNC'!G30 -> 4250 | D4: =-'DR SNC'!H30 -> 4250 | E4: =-'DR SNC'!I30 -> 4250 | F4: =-'DR SNC'!J30 -> 4250 | G4: =-'DR SNC'!K30 -> 0 | H4: =-'DR SNC'!L30 -> 0
A5: Colecta de IRC 21% | B5: =-'DR SNC'!F31 -> 52470.303 | C5: =-'DR SNC'!G31 -> 66044.461 | D5: =-'DR SNC'!H31 -> 63333.313 | E5: =-'DR SNC'!I31 -> 119189.88 | F5: =-'DR SNC'!J31 -> 88417.711 | G5: =-'DR SNC'!K31 -> 0 | H5: =-'DR SNC'!L31 -> 0
A6: Provisão para Impostos | B6: =SUM(B4:B5) -> 56720.303 | C6: =SUM(C4:C5) -> 70294.461 | D6: =SUM(D4:D5) -> 67583.313 | E6: =SUM(E4:E5) -> 123439.88 | F6: =SUM(F4:F5) -> 92667.711 | G6: =SUM(G4:G5) -> 0 | H6: =SUM(H4:H5) -> 0
A9: Índice

Sheet MEIOS LIBERTOS PROJETO
A1: Rubricas | B1: 2025 | C1: =+B1+1 -> 2026 | D1: =+C1+1 -> 2027 | E1: =+D1+1 -> 2028 | F1: =+E1+1 -> 2029 | G1: =+F1+1 -> 2030 | H1: =+G1+1 -> 2031
A2: Recebimentos do Ano
A3: Vendas do Ano | B3: =+'DR SNC'!F7 -> 17314539 | C3: =+'DR SNC'!G7 -> 18102351 | D3: =+'DR SNC'!H7 -> 18554468 | E3: =+'DR SNC'!I7 -> 19201172 | F3: =+'DR SNC'!J7 -> 19491487 | G3: =+'DR SNC'!K7 -> 0 | H3: =+'DR SNC'!L7 -> 0
A4: (+) Total dos Recebimentos | B4: =SUM(B3:B3) -> 17314539 | C4: =SUM(C3:C3) -> 18102351 | D4: =SUM(D3:D3) -> 18554468 | E4: =SUM(E3:E3) -> 19201172 | F4: =SUM(F3:F3) -> 19491487 | G4: =SUM(G3:G3) -> 0 | H4: =SUM(H3:H3) -> 0
A5: Pagamentos do Ano
A6: Compras pagas no ano | B6: =+'Capital Circulante'!B18 -> 13877338 | C6: =+'Capital Circulante'!C18 -> 14154636 | D6: =+'Capital Circulante'!D18 -> 14798672 | E6: =+'Capital Circulante'!E18 -> 15168278 | F6: =+'Capital Circulante'!F18 -> 15456944 | G6: =+'Capital Circulante'!G18 -> 15836833 | H6: =+'Capital Circulante'!H18 -> 15920585
A7: Encargos com Pessoal | B7: =+'63_G. Pess.'!C15 -> 1743813.9 | C7: =+'63_G. Pess.'!D15 -> 1778690.1 | D7: =+'63_G. Pess.'!E15 -> 1852305.4 | E7: =+'63_G. Pess.'!F15 -> 1889351.5 | F7: =+'63_G. Pess.'!G15 -> 1927138.5 | G7: =+'63_G. Pess.'!H15 -> 1965681.3 | H7: =+'63_G. Pess.'!I15 -> 2004994.9
A8: Fornecimentos e Serviços externos | B8: =+'Fornecimento Serviços Externos'!C18 -> 871290.97 | C8: =+'Fornecimento Serviços Externos'!D18 -> 912000 | D8: =+'Fornecimento Serviços Externos'!E18 -> 969750 | E8: =+'Fornecimento Serviços Externos'!F18 -> 1024213.5 | F8: =+'Fornecimento Serviços Externos'!G18 -> 1024213.5 | G8: =+'Fornecimento Serviços Externos'!H18 -> 1050288 | H8: =+'Fornecimento Serviços Externos'!I18 -> 1077051.7
A9: Encargos Financeiros ( Juros + Amort Capital) | B9: =+'Serviço da Divida Emp. Bancario'!C6+'Serviço da Divida Emp. Bancario'!C7 -> 0 | C9: =+'Serviço da Divida Emp. Bancario'!D6+'Serviço da Divida Emp. Bancario'!D7 -> 0 | D9: =+'Serviço da Divida Emp. Bancario'!E6+'Serviço da Divida Emp. Bancario'!E7 -> 0 | E9: =+'Serviço da Divida Emp. Bancario'!F6+'Serviço da Divida Emp. Bancario'!F7 -> 0 | F9: =+'Serviço da Divida Emp. Bancario'!G6+'Serviço da Divida Emp. Bancario'!G7 -> 0 | G9: =+'Serviço da Divida Emp. Bancario'!H6+'Serviço da Divida Emp. Bancario'!H7 -> 0 | H9: =+'Serviço da Divida Emp. Bancario'!I6+'Serviço da Divida Emp. Bancario'!I7 -> 0
A10: Imposto sobre o Rendimento | B10: =+'Mov dos Impostos S Rendi'!B6 -> 56720.303 | C10: =+'Mov dos Impostos S Rendi'!C6 -> 70294.461 | D10: =+'Mov dos Impostos S Rendi'!D6 -> 67583.313 | E10: =+'Mov dos Impostos S Rendi'!E6 -> 123439.88 | F10: =+'Mov dos Impostos S Rendi'!F6 -> 92667.711 | G10: =+'Mov dos Impostos S Rendi'!G6 -> 0 | H10: =+'Mov dos Impostos S Rendi'!H6 -> 0
A11: (-) Total dos Pagamentos | B11: =SUM(B6:B10) -> 16549163 | C11: =SUM(C6:C10) -> 16915620 | D11: =SUM(D6:D10) -> 17688310 | E11: =SUM(E6:E10) -> 18205282 | F11: =SUM(F6:F10) -> 18500963 | G11: =SUM(G6:G10) -> 18852802 | H11: =SUM(H6:H10) -> 19002632
A12: (=) Saldo do Ano | B12: =+B4-B11 -> 765375.98 | C12: =+C4-C11 -> 1186730.3 | D12: =+D4-D11 -> 866157.55 | E12: =+E4-E11 -> 995889.8 | F12: =+F4-F11 -> 990523.22 | G12: =+G4-G11 -> -18852802 | H12: =+H4-H11 -> -19002632
A15: Índice

Sheet Plano Financeiro 
B1: 2025 | C1: =+B1+1 -> 2026 | D1: =+C1+1 -> 2027 | E1: =+D1+1 -> 2028 | F1: =+E1+1 -> 2029 | G1: =+F1+1 -> 2030 | H1: =+G1+1 -> 2031
A2: Necessidades Financeiras
A3: Investimento em Imobilizado | C3: =Amortizações!F20 -> 37605 | D3: =Amortizações!G20 -> 62675 | E3: =Amortizações!H20 -> 37605 | F3: =Amortizações!I20 -> 12535 | G3: =Amortizações!J20 -> 0 | H3: =Amortizações!K20 -> 0
A4: Investimento em Fundo Maneio | B4: =IF('Capital Circulante'!B8>0,'Capital Circulante'!B8,0) -> 0 | C4: =IF('Capital Circulante'!C8>0,'Capital Circulante'!C8,0) -> 0 | D4: =IF('Capital Circulante'!D8>0,'Capital Circulante'!D8,0) -> 0 | E4: =IF('Capital Circulante'!E8>0,'Capital Circulante'!E8,0) -> 0 | F4: =IF('Capital Circulante'!F8>0,'Capital Circulante'!F8,0) -> 20375.963 | G4: =IF('Capital Circulante'!G8>0,'Capital Circulante'!G8,0) -> 0 | H4: =IF('Capital Circulante'!H8>0,'Capital Circulante'!H8,0) -> 0
A5: Reembolso de Empréstimos MLP | B5: =+'Serviço da Divida Emp. Bancario'!C7+'Serviço da Divida Emp. Bancario'!C20 -> 37459.631 | C5: =+'Serviço da Divida Emp. Bancario'!D7+'Serviço da Divida Emp. Bancario'!D20 -> 37459.631 | D5: =+'Serviço da Divida Emp. Bancario'!E7+'Serviço da Divida Emp. Bancario'!E20 -> 37459.631 | E5: =+'Serviço da Divida Emp. Bancario'!F7+'Serviço da Divida Emp. Bancario'!F20 -> 37459.631 | F5: =+'Serviço da Divida Emp. Bancario'!G7+'Serviço da Divida Emp. Bancario'!G20 -> 37459.631 | G5: =+'Serviço da Divida Emp. Bancario'!H7+'Serviço da Divida Emp. Bancario'!H20 -> 37459.631 | H5: =+'Serviço da Divida Emp. Bancario'!I7+'Serviço da Divida Emp. Bancario'!I20 -> 37459.631
A6: IRC | B6: =+'Mov dos Impostos S Rendi'!B6 -> 56720.303 | C6: =+'Mov dos Impostos S Rendi'!C6 -> 70294.461 | D6: =+'Mov dos Impostos S Rendi'!D6 -> 67583.313 | E6: =+'Mov dos Impostos S Rendi'!E6 -> 123439.88 | F6: =+'Mov dos Impostos S Rendi'!F6 -> 92667.711 | G6: =+'Mov dos Impostos S Rendi'!G6 -> 0 | H6: =+'Mov dos Impostos S Rendi'!H6 -> 0
A7: Juros de Empréstimos MLP | B7: =+'Serviço da Divida Emp. Bancario'!C19 -> 14983.853 | C7: =+'Serviço da Divida Emp. Bancario'!D19 -> 13110.871 | D7: =+'Serviço da Divida Emp. Bancario'!E19 -> 11237.889 | E7: =+'Serviço da Divida Emp. Bancario'!F19 -> 9364.9078 | F7: =+'Serviço da Divida Emp. Bancario'!G19 -> 7491.9263 | G7: =+'Serviço da Divida Emp. Bancario'!H19 -> 5618.9447 | H7: =+'Serviço da Divida Emp. Bancario'!I19 -> 3745.9631
A8: Total | B8: =SUM(B3:B7) -> 109163.79 | C8: =SUM(C3:C7) -> 158469.96 | D8: =SUM(D3:D7) -> 178955.83 | E8: =SUM(E3:E7) -> 207869.42 | F8: =SUM(F3:F7) -> 170530.23 | G8: =SUM(G3:G7) -> 43078.576 | H8: =SUM(H3:H7) -> 41205.594
A9: Recursos Financeiros
A10: Aumento de Capital | B10: 0
A11: Prestações Suplementares | B11: 0 | C11: =+'MAPA INVESTIMENTOS'!B19 -> 18713.5 | D11: =+'MAPA INVESTIMENTOS'!C19 -> 18713.5
A12: EBITDA | B12: =+'DR SNC'!F19 -> 469213.25 | C12: =+'DR SNC'!G19 -> 537764.12 | D12: =+'DR SNC'!H19 -> 528765.91 | E12: =+'DR SNC'!I19 -> 792876.56 | F12: =+'DR SNC'!J19 -> 638684.46 | G12: =+'DR SNC'!K19 -> 0 | H12: =+'DR SNC'!L19 -> 0
A13: Desinvestimento em Fundo Maneio | B13: =IF('Capital Circulante'!B8<0,-'Capital Circulante'!B8,0) -> 392701.59 | C13: =IF('Capital Circulante'!C8<0,-'Capital Circulante'!C8,0) -> 7817.3689 | D13: =IF('Capital Circulante'!D8<0,-'Capital Circulante'!D8,0) -> 18223.613 | E13: =IF('Capital Circulante'!E8<0,-'Capital Circulante'!E8,0) -> 10458.351 | F13: =IF('Capital Circulante'!F8<0,-'Capital Circulante'!F8,0) -> 0 | G13: =IF('Capital Circulante'!G8<0,-'Capital Circulante'!G8,0) -> 27703.127 | H13: =IF('Capital Circulante'!H8<0,-'Capital Circulante'!H8,0) -> 2308.562
A14: Empréstimos MLP P2020 | C14: =+'Serviço da Divida Emp. Bancario'!C5 -> 0 | D14: =[1]MapaServiçoDívida!G5 -> 0 | E14: =[1]MapaServiçoDívida!H5 -> 0 | F14: =[1]MapaServiçoDívida!I5 -> 0 | G14: 0 | H14: 0
A15: Total | B15: =SUM(B10:B14) -> 861914.84 | C15: =SUM(C10:C14) -> 564294.99 | D15: =SUM(D10:D14) -> 565703.02 | E15: =SUM(E10:E14) -> 803334.91 | F15: =SUM(F10:F14) -> 638684.46 | G15: =SUM(G10:G14) -> 27703.127 | H15: =SUM(H10:H14) -> 2308.562
A16: Saldo Anual | B16: =B15-B8 -> 752751.05 | C16: =C15-C8 -> 405825.02 | D16: =D15-D8 -> 386747.19 | E16: =E15-E8 -> 595465.5 | F16: =F15-F8 -> 468154.23 | G16: =G15-G8 -> -15375.449 | H16: =H15-H8 -> -38897.032
A17: Disponibilidades Iniciais | B17: =+'Balanço SNC'!D20 -> 163427.96 | C17: =B18 -> 916179.01 | D17: =C18 -> 1322004 | E17: =D18 -> 1708751.2 | F17: =E18 -> 2304216.7 | G17: =F18 -> 2772370.9 | H17: =G18 -> 2756995.5
A18: Disponibilidades Finais | B18: =B17+B16 -> 916179.01 | C18: =C17+C16 -> 1322004 | D18: =D17+D16 -> 1708751.2 | E18: =E17+E16 -> 2304216.7 | F18: =F17+F16 -> 2772370.9 | G18: =G17+G16 -> 2756995.5 | H18: =H17+H16 -> 2718098.5
A20: Índice

Sheet DR SNC
A3: Rúbricas | C3: 2022 | D3: 2023 | E3: 2024 | F3: 2025 | G3: 2026 | H3: 2027 | I3: 2028 | J3: 2029 | K3: 2030 | L3: 2031
A5: RENDIMENTOS E GASTOS
A7: Vendas e serviços prestados | E7: =+'Previsão Receitas'!B8 -> 16975038 | F7: =+'Previsão Receitas'!C8 -> 17314539 | G7: =+'Previsão Receitas'!D8 -> 18102351 | H7: =+'Previsão Receitas'!E8 -> 18554468 | I7: =+'Previsão Receitas'!F8 -> 19201172 | J7: =+'Previsão Receitas'!G8 -> 19491487
A8: Subsídios à exploração | E8: 33276.04 | G8: =+'MAPA INVESTIMENTOS'!B20 -> 56140.5 | H8: =+'MAPA INVESTIMENTOS'!C20 -> 56140.5
A9: Ganhos/perdas imputados de subsidiárias, associadas e empreend | E9: 47187.47
A10: Variação nos inventários da produção
A11: Custo das mercadorias vendidas e das matérias consumidas | E11: =-'Capital Circulante'!B18 -> -13877338 | F11: =-'Capital Circulante'!C18 -> -14154636 | G11: =-'Capital Circulante'!D18 -> -14798672 | H11: =-'Capital Circulante'!E18 -> -15168278 | I11: =-'Capital Circulante'!F18 -> -15456944 | J11: =-'Capital Circulante'!G18 -> -15836833
A12: Fornecimentos e serviços externos | E12: =-'Fornecimento Serviços Externos'!C18 -> -871290.97 | F12: =-'Fornecimento Serviços Externos'!D18 -> -912000 | G12: =-'Fornecimento Serviços Externos'!E18 -> -969750 | H12: =-'Fornecimento Serviços Externos'!F18 -> -1024213.5 | I12: =-'Fornecimento Serviços Externos'!G18 -> -1024213.5 | J12: =-'Fornecimento Serviços Externos'!H18 -> -1050288
A13: Gastos com o pessoal | E13: =-'63_G. Pess.'!C15 -> -1743813.9 | F13: =-'63_G. Pess.'!D15 -> -1778690.1 | G13: =-'63_G. Pess.'!E15 -> -1852305.4 | H13: =-'63_G. Pess.'!F15 -> -1889351.5 | I13: =-'63_G. Pess.'!G15 -> -1927138.5 | J13: =-'63_G. Pess.'!H15 -> -1965681.3
A14: Imparidade de dividas a receber (perdas/reversões) | E14: -6255.26
A15: Aumentos/reduções de justo valor | E15: -15666.4
A16: Outros rendimentos e ganhos | E16: 284128.46
A17: Outros gastos e perdas | E17: -523818.23
A19: Resultados antes de deprec, gastos de finan e impostos | C19: =SUM(C7:C18) -> 0 | E19: =SUM(E7:E18) -> 301447.6 | F19: =SUM(F7:F18) -> 469213.25 | G19: =SUM(G7:G18) -> 537764.12 | H19: =SUM(H7:H18) -> 528765.91 | I19: =SUM(I7:I18) -> 792876.56 | J19: =SUM(J7:J18) -> 638684.46 | K19: =SUM(K7:K18) -> 0 | L19: =SUM(L7:L18) -> 0
A21: Gastos/reversões de depreciação e de amortização | E21: =-Amortizações!M20 -> -167370.81 | F21: =-Amortizações!N20 -> -167370.81 | G21: =-Amortizações!O20 -> -173155.81 | H21: =-Amortizações!P20 -> -178940.81 | I21: =-Amortizações!Q20 -> -178940.81 | J21: =-Amortizações!R20 -> -173155.81
A22: Imparidade de invest depreciáveis/amortizáveis (perdas/reversões)
A24: Resultado operacional (antes de gastos de financiamento e impostos) | C24: =+C19+C21+C22 -> 0 | E24: =+E19+E21+E22 -> 134076.79 | F24: =+F19+F21+F22 -> 301842.44 | G24: =+G19+G21+G22 -> 364608.3 | H24: =+H19+H21+H22 -> 349825.09 | I24: =+I19+I21+I22 -> 613935.75 | J24: =+J19+J21+J22 -> 465528.64
A26: Juros e rendimentos similares obtidos
A27: Juros e gastos similares suportados | E27: -28132.94 | F27: =-'Serviço da Divida Emp. Bancario'!C19-12000 -> -26983.853 | G27: =-'Serviço da Divida Emp. Bancario'!D19-12000 -> -25110.871 | H27: =-'Serviço da Divida Emp. Bancario'!E19-12000 -> -23237.889 | I27: =-'Serviço da Divida Emp. Bancario'!F19-12000 -> -21364.908 | J27: =-'Serviço da Divida Emp. Bancario'!G19-12000 -> -19491.926
A29: Resultado antes de impostos | C29: =SUM(C24:C27) -> 0 | E29: =SUM(E24:E27) -> 105943.85 | F29: =SUM(F24:F27) -> 274858.58 | G29: =SUM(G24:G27) -> 339497.43 | H29: =SUM(H24:H27) -> 326587.2 | I29: =SUM(I24:I27) -> 592570.84 | J29: =SUM(J24:J27) -> 446036.72
B30: 0.17 | E30: -34451.18 | F30: =-25000*$B$30 -> -4250 | G30: =-25000*$B$30 -> -4250 | H30: =-25000*$B$30 -> -4250 | I30: =-25000*$B$30 -> -4250 | J30: =-25000*$B$30 -> -4250
A31: Imposto sobre o rendimento do período | B31: 0.21 | F31: =-(F29-25000)*$B$31 -> -52470.303 | G31: =-(G29-25000)*$B$31 -> -66044.461 | H31: =-(H29-25000)*$B$31 -> -63333.313 | I31: =-(I29-25000)*$B$31 -> -119189.88 | J31: =-(J29-25000)*$B$31 -> -88417.711 | M31: =4250+119189.88 -> 123439.88
A32: Resultado líquido do período | C32: =SUM(C29:C31) -> 0 | E32: =SUM(E29:E31) -> 71492.666 | F32: =SUM(F29:F31) -> 218138.28 | G32: =SUM(G29:G31) -> 269202.97 | H32: =SUM(H29:H31) -> 259003.89 | I32: =SUM(I29:I31) -> 469130.96 | J32: =SUM(J29:J31) -> 353369.01
A36: Índice
G39: =E7 -> 16975038 | H39: 100
A40: VBP | B40: Pré-Projeto 2024 | C40: Pós-Projeto 2028 | G40: =I7 -> 19201172 | H40: X
A41: Volume de Negócios | B41: =E7 -> 16975038 | C41: =I7 -> 19201172
A42: Variação nos inventários da produção | B42: 0 | C42: 0 | G42: =G40*H39/G39 -> 113.11416
A43: Trabalhos para a própria entidade | B43: 0 | C43: 0
A44: Rendimentos Suplementares | B44: =E16 -> 284128.46 | C44: 0
A45: Subsídios à Exploração | B45: =E8 -> 33276.04 | C45: =I8 -> 0
A46: Total | B46: =SUM(B41:B45) -> 17292443 | C46: =SUM(C41:C45) -> 19201172
A47: CI | B47: Pré-Projeto | C47: Pós-Projeto
A48: CMVMC | B48: =-E11 -> 13877338 | C48: =-I11 -> 15456944 | F48: =E7 -> 16975038 | G48: 100
A49: FSE | B49: =-E12 -> 871290.97 | C49: =-I12 -> 1024213.5 | F49: 1766441.7 | G49: x
A50: Impostos Indiretos | B50: 0 | C50: 0
A51: Total | B51: =SUM(B48:B50) -> 14748629 | C51: =SUM(C48:C50) -> 16481157 | F51: x | G51: =F49*G48/F48 -> 10.406113
A52: VAB | B52: =B46-B51 -> 2543813.9 | C52: =C46-C51 -> 2720015.1
F53: =I7 -> 19201172 | G53: 100
F54: x | G54: 14
...

Sheet Balanço SNC
A1: RUBRICAS | B1: Exercício
B2: 2022 | C2: 2023 | D2: 2024 | E2: 2025 | F2: =+E2+1 -> 2026 | G2: =+F2+1 -> 2027 | H2: =+G2+1 -> 2028 | I2: =+H2+1 -> 2029 | J2: =+I2+1 -> 2030 | K2: =+J2+1 -> 2031
A3: ACTIVO
A5: Activo não corrente:
A6: Activos fixos tangíveis | D6: 1330054.7 | E6: =Amortizações!E6 -> 1162683.9 | F6: =Amortizações!F6 -> 995313.07 | G6: =Amortizações!G6*1.15 -> 952133.6 | H6: =Amortizações!H6*1.3 -> 858742.88 | I6: =Amortizações!I6*1.6 -> 789121.01 | L6: 858742.88
A7: Propriedades de investimento | D7: 236590.85 | E7: =D7 -> 236590.85 | F7: =E7 -> 236590.85 | G7: =F7 -> 236590.85 | H7: =G7 -> 236590.85 | I7: =H7 -> 236590.85 | L7: 236590.85
A8: Activos intangíveis | D8: 670.71 | E8: =+Amortizações!E14 -> 0 | F8: =+Amortizações!F14 -> 37605 | G8: =+Amortizações!G14 -> 62675 | H8: =+Amortizações!H14 -> 37605 | I8: =+Amortizações!I14 -> 12535 | L8: 37605
A9: Participações Financeiras - Método da equivalência patrimonial | D9: 102416.64 | E9: =D9 -> 102416.64 | F9: =E9 -> 102416.64 | G9: =F9 -> 102416.64 | H9: =G9 -> 102416.64 | I9: =H9 -> 102416.64 | L9: 102416.64
A10: Investimentos Financeiros
B11: =SUM(B6:B9) -> 0 | D11: =SUM(D6:D10) -> 1669732.9 | E11: =SUM(E6:E10) -> 1501691.4 | F11: =SUM(F6:F10) -> 1371925.6 | G11: =SUM(G6:G10) -> 1353816.1 | H11: =SUM(H6:H10) -> 1235355.4 | I11: =SUM(I6:I10) -> 1140663.5 | L11: 1235355.4
A13: Activo corrente:
A14: Inventários | D14: 248036.51 | E14: =+'Capital Circulante'!B4 -> 269837.13 | F14: =+'Capital Circulante'!C4 -> 275229.03 | G14: =+'Capital Circulante'!D4 -> 287751.95 | H14: =+'Capital Circulante'!E4 -> 294938.73 | I14: =+'Capital Circulante'!F4 -> 300551.68 | L14: 294938.73
A15: Clientes | D15: 1498877.9 | E15: =+'Capital Circulante'!B3 -> 1650351 | F15: =+'Capital Circulante'!C3 -> 1683358 | G15: =+'Capital Circulante'!D3 -> 1759950.8 | H15: =+'Capital Circulante'!E3 -> 1803906.6 | I15: =+'Capital Circulante'!F3 -> 1866780.6 | L15: 1803906.6
A16: Adiantamentos a Fornecedores | D16: 653.83
A17: Estado E Outros Entes Públicos | D17: 393681.53 | E17: =D17*1.04 -> 409428.79 | F17: =E17*1.03 -> 421711.65 | G17: =F17*1.02 -> 430145.89 | H17: =G17*1.02 -> 438748.81 | I17: =H17*1.02 -> 447523.78 | L17: 438748.81
A18: Outras Contas a Receber | D18: 463434.78 | E18: =D18 -> 463434.78 | F18: =E18 -> 463434.78 | G18: =F18 -> 463434.78 | H18: =G18 -> 463434.78 | I18: =H18 -> 463434.78 | L18: 463434.78
A19: Diferimentos | D19: 34872.57 | E19: =D19*1.04 -> 36267.473 | F19: =E19*1.03 -> 37355.497 | G19: =F19*1.02 -> 38102.607 | H19: =G19*1.02 -> 38864.659 | I19: =H19*1.02 -> 39641.952 | L19: 38864.659
A20: Caixa e depósitos bancários | D20: 163427.96 | E20: =+'Plano Financeiro '!B18-669876.8 -> 246302.21 | F20: =+'Plano Financeiro '!C18-730211.75 -> 591792.29 | G20: =+'Plano Financeiro '!D18-884325.49 -> 824425.73 | H20: =+'Plano Financeiro '!E18-896757.68 -> 1407459 | I20: =+'Plano Financeiro '!F18-1033047.57 -> 1739323.4 | L20: 1407459
B21: =SUM(B14:B20) -> 0 | D21: =SUM(D14:D20) -> 2802985 | E21: =SUM(E14:E20) -> 3075621.3 | F21: =SUM(F14:F20) -> 3472881.2 | G21: =SUM(G14:G20) -> 3803811.7 | H21: =SUM(H14:H20) -> 4447352.6 | I21: =SUM(I14:I20) -> 4857256.2 | L21: 4447352.6
A23: Total do Activo | B23: =+B11+B21 -> 0 | D23: =+D11+D21 -> 4472717.9 | E23: =+E11+E21 -> 4577312.7 | F23: =+F11+F21 -> 4844806.8 | G23: =+G11+G21 -> 5157627.8 | H23: =+H11+H21 -> 5682708 | I23: =+I11+I21 -> 5997919.7 | L23: 5682708
A26: CAPITAL PRÓPRIO E PASSIVO
A28: Capital próprio:
A29: Capital realizado | D29: 50000 | E29: =D29 -> 50000 | F29: =E29 -> 50000 | G29: =F29 -> 50000 | H29: =G29 -> 50000 | I29: =H29 -> 50000 | L29: 50000
A30: Acções (quotas) próprias
A31: Outros instrumentos de capital próprio | F31: =+'MAPA INVESTIMENTOS'!B19 -> 18713.5 | G31: =+F31+'MAPA INVESTIMENTOS'!C19 -> 37427 | H31: =+G31 -> 37427 | I31: =+H31 -> 37427 | L31: 37427
A32: Reservas legais | D32: 15832.13 | E32: 1000 | F32: 1000 | G32: 1000 | H32: 1000 | I32: 1000 | L32: 1000
A33: Outras reservas | D33: 80000
A34: Resultados transitados | D34: 931579.86 | E34: =+D34+D37 -> 1003072.5 | F34: =+E34+E37 -> 1221210.8 | G34: =+F34+F37 -> 1490413.8 | H34: =+G34+G37 -> 1749417.7 | I34: =+H34+H37 -> 2218548.6 | L34: 1749417.7
A35: Outras variações no capital próprio | D35: 47991.79 | E35: =D35 -> 47991.79 | F35: =E35 -> 47991.79 | G35: =F35 -> 47991.79 | H35: =G35 -> 47991.79 | I35: =H35 -> 47991.79 | L35: 47991.79
A37: Resultado líquido do período | B37: 0 | D37: =+'DR SNC'!E32 -> 71492.666 | E37: =+'DR SNC'!F32 -> 218138.28 | F37: =+'DR SNC'!G32 -> 269202.97 | G37: =+'DR SNC'!H32 -> 259003.89 | H37: =+'DR SNC'!I32 -> 469130.96 | I37: =+'DR SNC'!J32 -> 353369.01 | L37: 469130.96
A38: Interesses minoritários
A40: Total do capital próprio | B40: =SUM(B29:B39) -> 0 | D40: =SUM(D29:D38) -> 1196896.4 | E40: =SUM(E29:E39) -> 1320202.6 | F40: =SUM(F29:F39) -> 1608119.1 | G40: =SUM(G28:G39) -> 1885836.5 | H40: =SUM(H28:H39) -> 2354967.4 | I40: =SUM(I28:I39) -> 2708336.4 | L40: 2354967.4
A42: Passivo
A44: Passivo não corrente:
A45: Financiamentos obtidos | D45: 299677.05 | E45: ='Serviço da Divida Emp. Bancario'!D18 -> 262217.42 | F45: ='Serviço da Divida Emp. Bancario'!E18 -> 224757.79 | G45: ='Serviço da Divida Emp. Bancario'!F18 -> 187298.16 | H45: ='Serviço da Divida Emp. Bancario'!G18 -> 149838.52 | I45: ='Serviço da Divida Emp. Bancario'!H18 -> 112378.89 | L45: 149838.52
A46: Outras contas a pagar
B48: =SUM(B45:B47) -> 0 | D48: =SUM(D45:D47) -> 299677.05 | E48: =SUM(E45:E47) -> 262217.42 | F48: =SUM(F45:F47) -> 224757.79 | G48: =SUM(G45:G47) -> 187298.16 | H48: =SUM(H45:H47) -> 149838.52 | I48: =SUM(I45:I47) -> 112378.89 | L48: 149838.52
A49: Passivo corrente:
A50: Fornecedores | D50: 2289504 | E50: =+'Capital Circulante'!B6 -> 2312889.7 | F50: =+'Capital Circulante'!C6 -> 2359106 | G50: =+'Capital Circulante'!D6 -> 2466445.3 | H50: =+'Capital Circulante'!E6 -> 2528046.3 | I50: =+'Capital Circulante'!F6 -> 2576157.3 | L50: 2528046.3
A51: Adiantamento de Clientes
...

Sheet Avaliação Investimento
A1: Rubricas | B1: 0 | C1: 2024 | D1: =+C1+1 -> 2025 | E1: =+D1+1 -> 2026 | F1: =+E1+1 -> 2027 | G1: =+F1+1 -> 2028 | H1: =+G1+1 -> 2029 | I1: =+H1+1 -> 2030
A2: Resultado Liquido | B2: 0 | C2: =+'DR SNC'!F32 -> 218138.28 | D2: =+'DR SNC'!G32 -> 269202.97 | E2: =+'DR SNC'!H32 -> 259003.89 | F2: =+'DR SNC'!I32 -> 469130.96 | G2: =+'DR SNC'!J32 -> 353369.01 | H2: =+'DR SNC'!K32 -> 0 | I2: =+'DR SNC'!L32 -> 0
A3: Amortizações | B3: 0 | C3: =-'DR SNC'!F21 -> 167370.81 | D3: =-'DR SNC'!G21 -> 173155.81 | E3: =-'DR SNC'!H21 -> 178940.81 | F3: =-'DR SNC'!I21 -> 178940.81 | G3: =-'DR SNC'!J21 -> 173155.81 | H3: =-'DR SNC'!K21 -> 0 | I3: =-'DR SNC'!L21 -> 0
A4: Cash Flow de Exploração | B4: =SUM(B2:B3) -> 0 | C4: =SUM(C2:C3) -> 385509.1 | D4: =SUM(D2:D3) -> 442358.79 | E4: =SUM(E2:E3) -> 437944.7 | F4: =SUM(F2:F3) -> 648071.78 | G4: =SUM(G2:G3) -> 526524.82 | H4: =SUM(H2:H3) -> 0 | I4: =SUM(I2:I3) -> 0
A5: Investimento em Capital Circulante
A6: Investimento em Capital Fixo | B6: ='MAPA INVESTIMENTOS'!B12+'MAPA INVESTIMENTOS'!C12 -> 149708
A7: Cash Flow Total | B7: =-B6 -> -149708 | C7: =+C4+C5+C6 -> 385509.1 | D7: =+D4+D5+D6 -> 442358.79 | E7: =+E4+E5+E6 -> 437944.7 | F7: =+F4+F5+F6 -> 648071.78 | G7: =+G4+G5+G6 -> 526524.82 | H7: =+H4+H5+H6 -> 0 | I7: =+I4+I5+I6 -> 0
A8: Cash Flow Acumulado | B8: =+B7 -> -149708 | C8: =+B8+C7 -> 235801.1 | D8: =+C8+D7 -> 678159.88 | E8: =+D8+E7 -> 1116104.6 | F8: =+E8+F7 -> 1764176.4 | G8: =+F8+G7 -> 2290701.2 | H8: =+G8+H7 -> 2290701.2 | I8: =+H8+I7 -> 2290701.2
A10: TIR | B10: =IRR(B7:I7) -> 2.6940796
A11: VAL | B11: =NPV(B17,B7,C7:I7) -> 1850195.5
A13: Descrição | B13: %
A14: Taxa de Aplicações Sem Risco (Rf) | B14: 0.02
A15: Taxa de Rendibilidade do Mercado Accionista (Rm) | B15: 0.05
A16: Beta Negócio Sem Efeito de Alavanca (Bu) | B16: 1
A17: Taxa Rendibilidade Desejada (Keu) | B17: 0.05
B19: PAY BACK PERIOD
B21: ANO | C21: Cash-Flows | D21: Cash Flows acumulados
A22: 0 | B22: 0 | C22: =+B8 -> -149708 | D22: =+C22 -> -149708
A23: 2019 | B23: 1 | C23: =+C7 -> 385509.1 | D23: =+D22+C23 -> 235801.1
A24: =+A23+1 -> 2020 | B24: =+B23+1 -> 2 | C24: =+D7 -> 442358.79 | D24: =+D23+C24 -> 678159.88
A25: =+A24+1 -> 2021 | B25: =+B24+1 -> 3 | C25: =+E7 -> 437944.7 | D25: =+D24+C25 -> 1116104.6
A26: =+A25+1 -> 2022 | B26: =+B25+1 -> 4 | C26: =+F7 -> 648071.78 | D26: =+D25+C26 -> 1764176.4
A27: =+A26+1 -> 2023 | B27: =+B26+1 -> 5 | C27: =+G7 -> 526524.82 | D27: =+D26+C27 -> 2290701.2
B30: Payback Simples | C30: =5+(1-D27/C27) -> 1.6493956 | D30: ANOS
A33: Índice

Sheet MAPA INVESTIMENTOS
A1: Designação | B1: INVESTIMENTO 2026 | C1: INVESTIMENTO 2027
A2: Desenvolvimento e Banco de Dados | B2: 12500 | C2: 12500
A3: Licenças e Ferramentas | B3: 4855 | C3: 4855
A4: Consumo de Tokens | B4: 4000 | C4: 4000
A5: Consultoria (Integração e formação) | B5: 15000 | C5: 15000
A6: Contratação RH | B6: 37249 | C6: 37249
A7: Validação de Despesas | B7: 1250 | C7: 1250
B12: =SUM(B2:B11) -> 74854 | C12: =SUM(C2:C11) -> 74854
A14: SUB TOTAL FES´S | B14: =+B9+B10 -> 0 | C14: =+C9+C10 -> 0
A16: INVESTIMENTO TOTAL | B16: =+B12+C12 -> 149708
A17: FINANCIAMENTO PRR GLOBAL | B17: =+B12*0.75 -> 56140.5 | C17: =+C12*0.75 -> 56140.5
A19: CAPITAIS PRÓPRIOS | B19: =+B12*0.25 -> 18713.5 | C19: =+C12*0.25 -> 18713.5 | D19: =SUM(B19:C19) -> 37427
A20: FINANCIAMENTO P2020 FUNDO PERDIDO 75% DO VALOR GLOBAL | B20: =+B12*0.75 -> 56140.5 | C20: =+C12*0.75 -> 56140.5 | D20: =SUM(B20:C20) -> 112281
A21: FINANCIAMENTO P2020 REEMBOLSÁVEL 0% DO VALOR GLOBAL | B21: =+B17*0 -> 0 | C21: =+C17*0 -> 0 | D21: =SUM(B21:C21) -> 0
A22: TOTAL FINANCIAMENTO | B22: =SUM(B19:B21) -> 74854 | C22: =SUM(C19:C21) -> 74854 | D22: =SUM(B22:C22) -> 149708
