Workbook

Sheet Pressupostos
B2: Pressupostos para o Projeto Financeiro
B4: Promotor | C4: AGRITORRES
B5: Tipologia do Projeto | C5: INTERNACIONALIZAÇÃO
B6: NUTS II
B8: Taxa de Comparticipação Internacionalização | C8: 0.45
B9: Taxa de Comparticipação Inovação (fundo Perdido) | C9: 0.3
B10: Ano pré-projeto | C10: 2018
B11: Estamos no ano de | C11: 2020
B12: Ano de início do projeto | C12: 2020
B13: Ano Pós-Projeto | C13: 2023
B14: Dias de operação anuais | C14: 360
C16: =C11 -> 2020 | D16: =C16+1 -> 2021 | E16: =D16+1 -> 2022 | F16: =E16+1 -> 2023 | G16: =F16+1 -> 2024 | H16: =G16+1 -> 2025 | I16: =H16+1 -> 2026 | J16: =I16+1 -> 2027 | K16: =J16+1 -> 2028 | L16: =K16+1 -> 2029 | M16: Perpet.
B17: Inflação anual prevista | C17: 0.01 | D17: 0.01 | E17: 0.01 | F17: 0.01 | G17: 0.01 | H17: 0.01 | I17: 0.01 | J17: 0.01 | K17: 0.01 | L17: 0.01 | M17: 0.01
B19: Crescimento Real das Vendas | C19: =C11 -> 2020 | D19: =$C$19+1 -> 2021 | E19: =$C$19+2 -> 2022 | F19: =+E19+1 -> 2023 | G19: =+F19+1 -> 2024 | H19: =+G19+1 -> 2025 | I19: =+H19+1 -> 2026 | J19: =+I19+1 -> 2027 | K19: =+J19+1 -> 2028 | L19: =+K19+1 -> 2029 | M19: Perpet.
B20: Vendas | C20: 1.05 | D20: 1.05 | E20: 1.05 | F20: 1.05 | G20: 1.01 | H20: 1.01 | I20: 1.01 | J20: 1.01 | K20: 1.01 | L20: 1.01 | M20: 1
B21: Prestação de Serviços | C21: 1.05 | D21: 1.05 | E21: 1.05 | F21: 1.05 | G21: 1.01 | H21: 1.01 | I21: 1.01 | J21: 1.01 | K21: 1.01 | L21: 1.01 | M21: 1
B23: Quantos meses de trabalho a considerar | C23: 14 | D23: =C23 -> 14 | E23: =D23 -> 14 | F23: =E23 -> 14 | G23: =F23 -> 14 | H23: =G23 -> 14 | I23: =H23 -> 14 | J23: =I23 -> 14 | K23: =J23 -> 14 | ... M23: =L23 -> 14
B24: Taxa de crescimento nominal dos Salários | C24: 1.02 | D24: 1.02 | E24: 1.02 | F24: 1.02 | G24: 1.02 | H24: 1.02 | I24: 1.02 | J24: 1.02 | K24: 1.02 | L24: 1.02 | M24: 1.02
B25: Taxa Social (23,75%) mais seguros diversos (2.5%) | C25: =0.2375+0.025 -> 0.2625 | D25: =C25 -> 0.2625 | E25: =D25 -> 0.2625 | F25: =E25 -> 0.2625 | G25: =F25 -> 0.2625 | H25: =G25 -> 0.2625 | I25: =H25 -> 0.2625 | J25: =I25 -> 0.2625 | K25: =J25 -> 0.2625 | ... M25: =L25 -> 0.2625
B26: Qual é o diferimento da SS (meses) | C26: 2 | D26: =C26 -> 2 | E26: =D26 -> 2 | F26: =E26 -> 2 | G26: =F26 -> 2 | H26: =G26 -> 2 | I26: =H26 -> 2 | J26: =I26 -> 2 | K26: =J26 -> 2 | ... M26: =L26 -> 2
B27: Qual é a Taxa do IVA | C27: 0.23 | D27: =C27 -> 0.23 | E27: =D27 -> 0.23 | F27: =E27 -> 0.23 | G27: =F27 -> 0.23 | H27: =G27 -> 0.23 | I27: =H27 -> 0.23 | J27: =I27 -> 0.23 | K27: =J27 -> 0.23 | ... M27: =L27 -> 0.23
B28: Qual é o diferimento do IVA (meses) | C28: 1 | D28: =C28 -> 1 | E28: =D28 -> 1 | F28: =E28 -> 1 | G28: =F28 -> 1 | H28: =G28 -> 1 | I28: =H28 -> 1 | J28: =I28 -> 1 | K28: =J28 -> 1 | ... M28: =L28 -> 1
B30: Qual é o imposto de selo | C30: 0.005
B32: Tx. Sem risco (10y OTs) | C32: 0.0035 | D32: German Government Bonds 10Y (25/10/2018)
B33: Prémio risco mercado | C33: 0.0665 | D33: Prémio globalmente aceite para países desenvolvidos
B34: Beta dos ativos | C34: 1
B35: Taxa de Atualização (Ra) | C35: =C32+C33*C34 -> 0.07 | D35: CAPM
B37: IRC | C37: 0.21
B38: Derrama (Porto) | C38: 0.015
B39: Taxa Imposto (IRC+Derrama) | C39: =C37+C38 -> 0.225
B41: Prazos Médios (dias)
B42: Clientes - PMR | C42: 90
B43: Fornecedores - PMP | C43: 60
B44: Existências | C44: 30
B46: Taxa Juro Empréstimo Normal | C46: =C47+C48 -> 0.04765
B47: Taxa | C47: -0.00235 | D47: Euribor 6 meses - 02/01/2019
B48: Spread | C48: 0.05
B49: Taxa Juro Bonificada | C49: 0

Sheet DR
B2: DEMONSTRAÇÃO DE RESULTADOS DO PROMOTOR
B3: DEMONSTRAÇÃO DOS RESULTADOS POR NATUREZAS | C3: UNIDADE: EUROS
B4: RÚBRICAS | C4: CÓDIGO | D4: =Pressupostos!C11-3 -> 2017 | E4: =D4+1 -> 2018 | F4: =E4+1 -> 2019
C5: SNC
B6: Vendas e serviços prestados | D6: =D36+D39 -> 0 | E6: =E36+E39 -> 0 | F6: =+F39 -> 3479532.1
B7: Subsídios à exploração | F7: 49.26
B8: Ganhos/perdas imputados de subsidiárias, associadas e empreendimentos conjuntos | F8: 0
B9: Variação nos inventários da produção
B10: Trabalhos para a própria entidade
B11: Custo das mercadorias vendidas e das matérias consumidas | F11: 2780591.1 | I11: =+F11/F6 -> 0.79912788
B12: Fornecimentos e serviços externos | F12: 506782.86 | G12: =D12/D6 -> #DIV/0! | H12: =E12/E6 -> #DIV/0! | I12: =F12/F6 -> 0.14564684
B13: Gastos com o pessoal | F13: 169363.3
B14: Imparidade de inventários (perdas/reversões) | F14: 0
B15: Imparidade de dívidas a receber (perdas/reversões) | F15: 40.26
B16: Provisões (aumentos/reduções)
B17: Imparidade de investimentos não depreciáveis/amortizáveis (perdas/reversões)
B18: Outras imparidades (perdas/reversões)/Imparidades
B19: Aumentos/reduções de justo valor
B20: Outros rendimentos e ganhos | F20: 73417.34
B21: Outros gastos e perdas | F21: 37622.48
B22: Resultado antes de depreciações, gastos de financiamento e impostos | D22: =D6+D7+D8+D9+D10-D11-D12-D13-D14-D15-D16-D17-D18+D19+D20-D21 -> 0 | E22: =E6+E7+E8+E9+E10-E11-E12-E13-E14-E15-E16-E17-E18+E19+E20-E21 -> 0 | F22: =F6+F7+F8+F9+F10-F11-F12-F13-F14-F15-F16-F17-F18+F19+F20-F21 -> 58598.69 | G22: =58598.69-F22 -> 0
B23: Gastos/reversões de depreciação e de amortização | F23: 15247.25
B24: Imparidade de investimentos depreciáveis/amortizáveis
B25: Resultado operacional (antes de gastos de financiamento e impostos) | D25: =D22-D23-D24 -> 0 | E25: =E22-E23-E24 -> 0 | F25: =F22-F23-F24 -> 43351.44
B26: Juros e rendimentos similares obtidos | F26: 0
B27: Juros e gastos similares suportados | F27: 1053
B28: Resultado antes de impostos | D28: =D25+D26-D27 -> 0 | E28: =E25+E26-E27 -> 0 | F28: =F25+F26-F27 -> 42298.44
B29: Imposto sobre o rendimento do período | F29: 10443.87
B30: Resultado líquido do período | D30: =D28-D29 -> 0 | E30: =E28-E29 -> 0 | F30: =F28-F29 -> 31854.57 | G30: =+F30/F6 -> 0.0091548429 | I30: =+Balanço!E22/DR!F6 -> 0.21786974 | J30: =+I30*12 -> 2.6144369
B32: Compras | D32: 0 | E32: 0 | F32: 0
B34: Meios Libertos | D34: =D30+D23+D24 -> 0 | E34: =E30+E23+E24+(E16-D16) -> 0 | F34: =F30+F23+F24+(F16-E16) -> 47101.82
B36: Vendas | D36: =D37+D38 -> 0 | E36: =E37+E38 -> 0 | F36: =F37+F38 -> 0
B37: Produtos
B38: Mercadorias
B39: Prestação de Serviços | F39: =80.52+3479451.62 -> 3479532.1
B40: Diferença | D40: =(D37+D38+D39)-D6 -> 0 | E40: =(E37+E38+E39)-E6 -> 0 | F40: =(F37+F38+F39)-F6 -> 0
D84: 40405.59
C85: 0 | D85: 0
C86: 1348.55 | D86: 1348.55

Sheet Balanço
B2: BALANÇOS DO PROMOTOR
B3: UNIDADE: EUROS
B4: RÚBRICAS | C4: =Pressupostos!C11-3 -> 2017 | D4: =C4+1 -> 2018 | E4: =D4+1 -> 2019
B5: ATIVO
B6: Ativo não corrente
B7: Ativos fixos tangíveis | E7: 84625.24
B8: Propriedades de investimento | E8: 102152.86
B9: Goodwill
B10: Ativos intangíveis
B11: Ativos biológicos
B12: Participações financeiras - método da equivalência patrimonial
B13: Participações financeiras - outros métodos
B14: Acionistas/sócios
B15: Outros ativos financeiros | E15: 347.82
B16: Ativos por impostos diferidos
B17: Investimentos financeiros (utilização exclusiva pelas pequenas entidades e microentidades)
B18: SOMA | C18: =SUM(C7:C17) -> 0 | D18: =SUM(D7:D17) -> 0 | E18: =SUM(E7:E17) -> 187125.92
B19: Ativo Corrente
B20: Inventários | E20: 343630.82
B21: Ativos biológicos | E21: 0
B22: Clientes | E22: 758084.77
B23: Adiantamentos a fornecedores
B24: Estado e outros entes públicos | E24: 21003.43
B25: Acionistas/sócios
B26: Outras contas a receber | E26: 80826.21
B27: Diferimentos | E27: 955.33
B28: Ativos financeiros detidos para negociação
B29: Outros ativos financeiros
B30: Ativos não correntes detidos para venda
B31: Outros ativos correntes
B32: Caixa e depósitos bancários | E32: 215805.41
B33: SOMA | C33: =SUM(C20:C32) -> 0 | D33: =SUM(D20:D32) -> 0 | E33: =SUM(E20:E32) -> 1420306
B34: TOTAL DO ATIVO | C34: =C18+C33 -> 0 | D34: =D18+D33 -> 0 | E34: =E18+E33 -> 1607431.9
B35: CAPITAL PRÓPRIO E PASSIVO
B36: Capital Próprio
B37: Capital realizado | E37: 300000
B38: Ações (quotas) próprias
B39: Outros instrumentos de capital próprio
B40: Prémios de emissão
B41: Reservas legais | E41: 14785.57
...

Sheet Vendas+PrestServ
B2: VENDAS DE PRODUTOS (TRANSFORMADOS / COMERCIALIZADOS)
B3: Designação | C3: UNIDADE | D3: =Pressupostos!C11 -> 2020 | E3: =D3+1 -> 2021 | F3: =E3+1 -> 2022 | G3: =F3+1 -> 2023 | H3: =G3+1 -> 2024 | I3: =H3+1 -> 2025 | J3: =I3+1 -> 2026 | K3: =J3+1 -> 2027 | L3: =K3+1 -> 2028 | M3: =L3+1 -> 2029
B4: Vários | C4: Valor euros | D4: =DR!F37*Pressupostos!C20*(1+Pressupostos!C17) -> 0 | E4: =D4*Pressupostos!D20*(1+Pressupostos!D17) -> 0 | F4: =E4*Pressupostos!E20*(1+Pressupostos!E17) -> 0 | G4: =F4*Pressupostos!F20*(1+Pressupostos!F17) -> 0 | H4: =G4*Pressupostos!G20*(1+Pressupostos!G17) -> 0 | I4: =H4*Pressupostos!H20*(1+Pressupostos!H17) -> 0 | J4: =I4*Pressupostos!I20*(1+Pressupostos!I17) -> 0 | K4: =J4*Pressupostos!J20*(1+Pressupostos!J17) -> 0 | L4: =K4*Pressupostos!K20*(1+Pressupostos!K17) -> 0 | M4: =L4*Pressupostos!L20*(1+Pressupostos!L17) -> 0
C5: Valor euros
C6: Valor euros
C7: Valor euros
B8: TOTAL DO VALOR | D8: =SUM(D4:D7) -> 0 | E8: =SUM(E4:E7) -> 0 | F8: =SUM(F4:F7) -> 0 | G8: =SUM(G4:G7) -> 0 | H8: =SUM(H4:H7) -> 0 | I8: =SUM(I4:I7) -> 0 | J8: =SUM(J4:J7) -> 0 | K8: =SUM(K4:K7) -> 0 | ... M8: =SUM(M4:M7) -> 0
B10: VENDAS DE MERCADORIAS
B11: Designação | C11: UNIDADE | D11: =D3 -> 2020 | E11: =D11+1 -> 2021 | F11: =E11+1 -> 2022 | G11: =F11+1 -> 2023 | H11: =G11+1 -> 2024 | I11: =H11+1 -> 2025 | J11: =I11+1 -> 2026 | K11: =J11+1 -> 2027 | L11: =K11+1 -> 2028 | M11: =L11+1 -> 2029
B12: Vários | C12: Valor euros | E12: =D12*Pressupostos!D20*(1+Pressupostos!D17) -> 0 | F12: =E12*Pressupostos!E20*(1+Pressupostos!E17) -> 0 | G12: =F12*Pressupostos!F20*(1+Pressupostos!F17) -> 0 | H12: =G12*Pressupostos!G20*(1+Pressupostos!G17) -> 0 | I12: =H12*Pressupostos!H20*(1+Pressupostos!H17) -> 0 | J12: =I12*Pressupostos!I20*(1+Pressupostos!I17) -> 0 | K12: =J12*Pressupostos!J20*(1+Pressupostos!J17) -> 0 | L12: =K12*Pressupostos!K20*(1+Pressupostos!K17) -> 0 | M12: =L12*Pressupostos!L20*(1+Pressupostos!L17) -> 0
C13: Valor euros
C14: Valor euros
C15: Valor euros
B16: TOTAL DO VALOR | D16: =SUM(D12:D15) -> 0 | E16: =SUM(E12:E15) -> 0 | F16: =SUM(F12:F15) -> 0 | G16: =SUM(G12:G15) -> 0 | H16: =SUM(H12:H15) -> 0 | I16: =SUM(I12:I15) -> 0 | J16: =SUM(J12:J15) -> 0 | K16: =SUM(K12:K15) -> 0 | ... M16: =SUM(M12:M15) -> 0
B18: TOTAL DAS VENDAS | C18: EUROS | D18: =D8+D16 -> 0 | E18: =E8+E16 -> 0 | F18: =F8+F16 -> 0 | G18: =G8+G16 -> 0 | H18: =H8+H16 -> 0 | I18: =I8+I16 -> 0 | J18: =J8+J16 -> 0 | K18: =K8+K16 -> 0 | ... M18: =M8+M16 -> 0
B20: PRESTAÇÃO DE SERVIÇOS
B21: Designação | C21: UNIDADE | D21: =D3 -> 2020 | E21: =D21+1 -> 2021 | F21: =E21+1 -> 2022 | G21: =F21+1 -> 2023 | H21: =G21+1 -> 2024 | I21: =H21+1 -> 2025 | J21: =I21+1 -> 2026 | K21: =J21+1 -> 2027 | L21: =K21+1 -> 2028 | M21: =L21+1 -> 2029
B22: Vários | C22: EUROS | D22: =DR!F39*Pressupostos!C21*(1+Pressupostos!C17) -> 3690043.8 | E22: =D22*Pressupostos!D21*(1+Pressupostos!D17) -> 3913291.5 | F22: =E22*Pressupostos!E21*(1+Pressupostos!E17) -> 4150045.6 | G22: =F22*Pressupostos!F21*(1+Pressupostos!F17) -> 4401123.4 | H22: =G22*Pressupostos!G21*(1+Pressupostos!G17) -> 4489586 | I22: =H22*Pressupostos!H21*(1+Pressupostos!H17) -> 4579826.6 | J22: =I22*Pressupostos!I21*(1+Pressupostos!I17) -> 4671881.2 | K22: =J22*Pressupostos!J21*(1+Pressupostos!J17) -> 4765786 | L22: =K22*Pressupostos!K21*(1+Pressupostos!K17) -> 4861578.3 | M22: =L22*Pressupostos!L21*(1+Pressupostos!L17) -> 4959296
C23: EUROS
C24: EUROS
C25: EUROS
C26: EUROS
B27: TOTAL DA PRESTAÇÃO DE SERVIÇOS | D27: =SUM(D22:D26) -> 3690043.8 | E27: =SUM(E22:E26) -> 3913291.5 | F27: =SUM(F22:F26) -> 4150045.6 | G27: =SUM(G22:G26) -> 4401123.4 | H27: =SUM(H22:H26) -> 4489586 | I27: =SUM(I22:I26) -> 4579826.6 | J27: =SUM(J22:J26) -> 4671881.2 | K27: =SUM(K22:K26) -> 4765786 | ... M27: =SUM(M22:M26) -> 4959296
B29: VENDAS + PRESTAÇÃO DE SERVIÇOS | C29: =D29-1 -> 2019 | D29: =D3 -> 2020 | E29: =E3 -> 2021 | F29: =F3 -> 2022 | G29: =G3 -> 2023 | H29: =H3 -> 2024 | I29: =I3 -> 2025 | J29: =J3 -> 2026 | K29: =K3 -> 2027 | ... M29: =M3 -> 2029
C30: =DR!F6 -> 3479532.1 | D30: =D18+D27 -> 3690043.8 | E30: =E18+E27 -> 3913291.5 | F30: =F18+F27 -> 4150045.6 | G30: =G18+G27 -> 4401123.4 | H30: =H18+H27 -> 4489586 | I30: =I18+I27 -> 4579826.6 | J30: =J18+J27 -> 4671881.2 | K30: =K18+K27 -> 4765786 | ... M30: =M18+M27 -> 4959296

Sheet CMVMC
B2: CUSTO DAS MERCADORIAS VENDIDAS E MATÉRIAS CONSUMIDAS
C3: UNIDADE | D3: =Pressupostos!C11 -> 2020 | E3: =D3+1 -> 2021 | F3: =E3+1 -> 2022 | G3: =F3+1 -> 2023 | H3: =G3+1 -> 2024 | I3: =H3+1 -> 2025 | J3: =I3+1 -> 2026 | K3: =J3+1 -> 2027 | L3: =K3+1 -> 2028 | M3: =L3+1 -> 2029
B4: PRODUTOS | C4: Valor euros | D4: =D11*D12 -> 2896684.4 | E4: =E11*E12 -> 3071933.8 | F4: =F11*F12 -> 3237035.6 | G4: =G11*G12 -> 3432876.2 | H4: =H11*H12 -> 3501877 | I4: =I11*I12 -> 3572264.8 | J4: =J11*J12 -> 3644067.3 | K4: =K11*K12 -> 3717313.1 | ... M4: =M11*M12 -> 3868250.9
B5: MERCADORIAS | C5: Valor euros | D5: =IFERROR(D9*'Vendas+PrestServ'!D16,"0") -> 0 | E5: =IFERROR(E9*'Vendas+PrestServ'!E16,"0") -> 0 | F5: =IFERROR(F9*'Vendas+PrestServ'!F16,"0") -> 0 | G5: =IFERROR(G9*'Vendas+PrestServ'!G16,"0") -> 0 | H5: =IFERROR(H9*'Vendas+PrestServ'!H16,"0") -> 0 | I5: =IFERROR(I9*'Vendas+PrestServ'!I16,"0") -> 0 | J5: =IFERROR(J9*'Vendas+PrestServ'!J16,"0") -> 0 | K5: =IFERROR(K9*'Vendas+PrestServ'!K16,"0") -> 0 | ... M5: =IFERROR(M9*'Vendas+PrestServ'!M16,"0") -> 0
B6: TOTAL DO VALOR | D6: =D4+D5 -> 2896684.4 | E6: =E4+E5 -> 3071933.8 | F6: =F4+F5 -> 3237035.6 | G6: =G4+G5 -> 3432876.2 | H6: =H4+H5 -> 3501877 | I6: =I4+I5 -> 3572264.8 | J6: =J4+J5 -> 3644067.3 | K6: =K4+K5 -> 3717313.1 | ... M6: =M4+M5 -> 3868250.9
B8: Produtos | D8: =IFERROR(DR!F11/DR!F37,0) -> 0 | E8: =D8 -> 0 | F8: =E8 -> 0 | G8: =F8 -> 0 | H8: =G8 -> 0 | I8: =H8 -> 0 | J8: =I8 -> 0 | K8: =J8 -> 0 | L8: =K8 -> 0 | M8: =L8 -> 0
B9: Mercadorias (representatividade sobre as vendas de produtos) | D9: =IFERROR(DR!F11/DR!F38,0) -> 0 | E9: =D9 -> 0 | F9: =E9 -> 0 | G9: =F9 -> 0 | H9: =G9 -> 0 | I9: =H9 -> 0 | J9: =I9 -> 0 | K9: =J9 -> 0 | L9: =K9 -> 0 | M9: =L9 -> 0
B11: VN | D11: ='DR Empresa'!C5 -> 3690043.8 | E11: ='DR Empresa'!D5 -> 3913291.5 | F11: ='DR Empresa'!E5 -> 4150045.6 | G11: ='DR Empresa'!F5 -> 4401123.4 | H11: ='DR Empresa'!G5 -> 4489586 | I11: ='DR Empresa'!H5 -> 4579826.6 | J11: ='DR Empresa'!I5 -> 4671881.2 | K11: ='DR Empresa'!J5 -> 4765786 | ... M11: ='DR Empresa'!L5 -> 4959296
B12: % | D12: 0.785 | E12: 0.785 | F12: 0.78 | G12: 0.78 | H12: 0.78 | I12: 0.78 | J12: 0.78 | K12: 0.78 | L12: 0.78 | M12: 0.78

Sheet FSE
B2: FORNECIMENTOS E SERVIÇOS EXTERNOS | M2: UNIDADE: EUROS
D3: =Pressupostos!C11 -> 2020 | E3: =D3+1 -> 2021 | F3: =E3+1 -> 2022 | G3: =F3+1 -> 2023 | H3: =G3+1 -> 2024 | I3: =H3+1 -> 2025 | J3: =I3+1 -> 2026 | K3: =J3+1 -> 2027 | L3: =K3+1 -> 2028 | M3: =L3+1 -> 2029
B4: FSE sem projeto | D4: =DR!F12*(1+Pressupostos!C17) -> 511850.69 | E4: =E12*'Vendas+PrestServ'!E30 -> 528294.35 | F4: =F12*'Vendas+PrestServ'!F30 -> 560256.16 | G4: =G12*'Vendas+PrestServ'!G30 -> 594151.66 | H4: =H12*'Vendas+PrestServ'!H30 -> 606094.1 | I4: =I12*'Vendas+PrestServ'!I30 -> 618276.6 | J4: =J12*'Vendas+PrestServ'!J30 -> 630703.96 | K4: =K12*'Vendas+PrestServ'!K30 -> 643381.11 | L4: =L12*'Vendas+PrestServ'!L30 -> 656313.07 | M4: =M12*'Vendas+PrestServ'!M30 -> 669504.96
B5: FSE do Projeto | D5: =Faturas!E310 -> 20625.25 | E5: =Faturas!E311 -> 18340 | F5: =Faturas!E312 -> 14800 | G5: =Faturas!E313 -> 0 | H5: 0 | I5: 0 | J5: 0 | K5: 0 | L5: 0 | M5: 0
B6: TOTAL DO VALOR | D6: =SUM(D4:D5) -> 532475.94 | E6: =SUM(E4:E5) -> 546634.35 | F6: =SUM(F4:F5) -> 575056.16 | G6: =SUM(G4:G5) -> 594151.66 | H6: =SUM(H4:H5) -> 606094.1 | I6: =SUM(I4:I5) -> 618276.6 | J6: =SUM(J4:J5) -> 630703.96 | K6: =SUM(K4:K5) -> 643381.11 | ... M6: =SUM(M4:M5) -> 669504.96
B8: Volume de Negócios | D8: ='DR Empresa'!C5 -> 3690043.8 | E8: ='DR Empresa'!D5 -> 3913291.5 | F8: ='DR Empresa'!E5 -> 4150045.6 | G8: ='DR Empresa'!F5 -> 4401123.4 | H8: ='DR Empresa'!G5 -> 4489586 | I8: ='DR Empresa'!H5 -> 4579826.6 | J8: ='DR Empresa'!I5 -> 4671881.2 | K8: ='DR Empresa'!J5 -> 4765786 | ... M8: ='DR Empresa'!L5 -> 4959296
B9: FSE / Vlolume Negócios | D9: =D6/D8 -> 0.14430071 | E9: =E6/E8 -> 0.13968659 | F9: =F6/F8 -> 0.13856623 | G9: =G6/G8 -> 0.135 | H9: =H6/H8 -> 0.135 | I9: =I6/I8 -> 0.135 | J9: =J6/J8 -> 0.135 | K9: =K6/K8 -> 0.135 | ... M9: =M6/M8 -> 0.135
B11: % FSE / VN | C11: =D11-1 -> 2019 | D11: =D3 -> 2020 | E11: =E3 -> 2021 | F11: =F3 -> 2022 | G11: =G3 -> 2023 | H11: =H3 -> 2024 | I11: =I3 -> 2025 | J11: =J3 -> 2026 | K11: =K3 -> 2027 | ... M11: =M3 -> 2029
C12: =DR!F12/DR!F6 -> 0.14564684 | D12: 0.135 | E12: =+D12 -> 0.135 | F12: =+E12 -> 0.135 | G12: =+F12 -> 0.135 | H12: =+G12 -> 0.135 | I12: =+H12 -> 0.135 | J12: =+I12 -> 0.135 | K12: =+J12 -> 0.135 | L12: =+K12 -> 0.135 | M12: =+L12 -> 0.135

Sheet RH
B2: RECURSOS HUMANOS - CUSTOS | O2: Administração/Direção
D3: =Pressupostos!C11 -> 2020 | E3: =D3+1 -> 2021 | F3: =E3+1 -> 2022 | G3: =F3+1 -> 2023 | H3: =G3+1 -> 2024 | I3: =H3+1 -> 2025 | J3: =I3+1 -> 2026 | K3: =J3+1 -> 2027 | L3: =K3+1 -> 2028 | M3: =L3+1 -> 2029 | O3: Administrativa/Financeira
B4: Remunerações | D4: =(DR!F13*Pressupostos!C24)+K13 -> 172750.57 | E4: =(D4*Pressupostos!D24)+K14+M13 -> 201405.58 | F4: =(E4*Pressupostos!E24)+K15+M14 -> 213833.69 | G4: =(F4*Pressupostos!F24)+K16+M15 -> 218110.36 | H4: =(G4*Pressupostos!G24)+K17+M16 -> 222472.57 | I4: =(H4*Pressupostos!H24)+K18+M17 -> 226922.02 | J4: =(I4*Pressupostos!I24)+M18 -> 231460.46 | K4: =(J4*Pressupostos!J24) -> 236089.67 | L4: =(K4*Pressupostos!K24) -> 240811.46 | M4: =(L4*Pressupostos!L24) -> 245627.69 | O4: Aprovisionamento
B5: Encargos Sociais | D5: =D4*Pressupostos!$C$25 -> 45347.024 | E5: =E4*Pressupostos!$C$25 -> 52868.964 | F5: =F4*Pressupostos!$C$25 -> 56131.343 | G5: =G4*Pressupostos!$C$25 -> 57253.97 | H5: =H4*Pressupostos!$C$25 -> 58399.05 | I5: =I4*Pressupostos!$C$25 -> 59567.031 | J5: =J4*Pressupostos!$C$25 -> 60758.371 | K5: =K4*Pressupostos!$C$25 -> 61973.539 | ... M5: =M4*Pressupostos!$C$25 -> 64477.27 | O5: Comercial/Marketing
B6: TOTAL | D6: =SUM(D4:D5) -> 218097.59 | E6: =SUM(E4:E5) -> 254274.54 | F6: =SUM(F4:F5) -> 269965.03 | G6: =SUM(G4:G5) -> 275364.33 | H6: =SUM(H4:H5) -> 280871.62 | I6: =SUM(I4:I5) -> 286489.05 | J6: =SUM(J4:J5) -> 292218.83 | K6: =SUM(K4:K5) -> 298063.21 | ... M6: =SUM(M4:M5) -> 310104.96 | O6: Engenharia, Conceção e Projeto
O7: Investigação
B8: Nº RHs | C8: =D3-1 -> 2019 | D8: =F56 -> 0 | O8: Qualidade
B9: Nº RHs Pós-Projeto | D9: =I56 -> 0 | O9: Operacional (Produtiva)
B10: Falta acrescentar no quadro infra | D10: =-(COUNTA(E13:E24)+D8)+D9 -> -2 | O10: Operacional (Turismo) - Receção/Portaria
B11: RHs a Contratar (dentro e fora do âmbito do projeto) | O11: Operacional (Turismo) - Quartos/Limpeza
B12: Quantidade | C12: Área / Função | D12: Ano de Entrada | E12: Mês de Entrada | F12: Vencim. Base (€) | G12: Total | J12: Nº RHs a entar | O12: Operacional (Turismo) - Restaurante/Bar
B13: 1 | C13: Comercial/Marketing | D13: 2021 | E13: 4 | F13: 1200 | G13: =(13-E13)*F13+(F13*1/6)*(13-E13) -> 12600 | H13: =F13*14 -> 16800 | I13: =D3 -> 2020 | J13: =COUNTIF(D13:D24,D3) -> 0 | K13: =SUMIF(D13:D24,D3,G13:G24) -> 0 | L13: =SUMIF($D$13:$D$24,D3,$G$13:$G$24) -> 0 | M13: =L13-K13 -> 0 | O13: Operacional (Turismo) - Cozinha
B14: 2 | C14: Comercial/Marketing | D14: 2021 | E14: 4 | F14: 1200 | G14: =(13-E14)*F14+(F14*1/6)*(13-E14) -> 12600 | H14: =F14*14 -> 16800 | I14: =I13+1 -> 2021 | J14: =COUNTIF(D13:D24,E3) -> 2 | K14: =SUMIF(D13:D24,E3,G13:G24) -> 25200 | L14: =SUMIF($D$13:$D$24,E3,$H$13:$H$24) -> 33600 | M14: =L14-K14 -> 8400 | O14: Operacional (Turismo) - Animação
B15: 3 | G15: =(13-E15)*F15+(F15*1/6)*(13-E15) -> 0 | H15: =F15*14 -> 0 | I15: =I14+1 -> 2022 | J15: =COUNTIF(D13:D24,F3) -> 0 | K15: =SUMIF(D13:D24,F3,G13:G24) -> 0 | L15: =SUMIF($D$13:$D$24,F3,$H$13:$H$24) -> 0 | M15: =L15-K15 -> 0 | O15: Operacional (Turismo) - Outras
B16: 4 | G16: =(13-E16)*F16+(F16*1/6)*(13-E16) -> 0 | H16: =F16*14 -> 0 | I16: =I15+1 -> 2023 | J16: =COUNTIF(D13:D24,G3) -> 0 | K16: =SUMIF(D13:D24,G3,G13:G24) -> 0 | L16: =SUMIF($D$13:$D$24,G3,$H$13:$H$24) -> 0 | M16: =L16-K16 -> 0 | O16: Outros
B17: 5 | G17: =(13-E17)*F17+(F17*1/6)*(13-E17) -> 0 | H17: =F17*14 -> 0 | I17: =I16+1 -> 2024 | J17: =COUNTIF(D13:D24,H3) -> 0 | K17: =SUMIF(D13:D24,H3,G13:G24) -> 0 | L17: =SUMIF($D$13:$D$24,H3,$H$13:$H$24) -> 0 | M17: =L17-K17 -> 0
B18: 6 | G18: =(13-E18)*F18+(F18*1/6)*(13-E18) -> 0 | H18: =F18*14 -> 0 | I18: =I17+1 -> 2025 | J18: =COUNTIF(D13:D24,I3) -> 0 | K18: =SUMIF(D13:D24,I3,G13:G24) -> 0 | L18: =SUMIF($D$13:$D$24,I3,$H$13:$H$24) -> 0 | M18: =L18-K18 -> 0
B19: 7 | G19: =(13-E19)*F19+(F19*1/6)*(13-E19) -> 0 | H19: =F19*14 -> 0 | O19: Nível 1
B20: 8 | G20: =(13-E20)*F20+(F20*1/6)*(13-E20) -> 0 | H20: =F20*14 -> 0 | O20: Nível 2
B21: 9 | G21: =(13-E21)*F21+(F21*1/6)*(13-E21) -> 0 | H21: =F21*14 -> 0 | O21: Nível 3
B22: 10 | G22: =(13-E22)*F22+(F22*1/6)*(13-E22) -> 0 | H22: =F22*14 -> 0 | O22: Nível 4
B23: 11 | G23: =(13-E23)*F23+(F23*1/6)*(13-E23) -> 0 | H23: =F23*14 -> 0 | O23: Nível 5
B24: 12 | G24: =(13-E24)*F24+(F24*1/6)*(13-E24) -> 0 | H24: =F24*14 -> 0 | O24: Nível 6
O25: Nível 7
O26: Nível 8
B27: Área Funcional | C27: Nível de Qualificação | D27: Ano Pré-Projeto | G27: Ano Pós-Projeto
D28: Mulheres | E28: Homens | F28: Total | G28: Mulheres | H28: Homens | I28: Total
F29: =D29+E29 -> 0 | I29: =G29+H29 -> 0
F30: =D30+E30 -> 0 | I30: =G30+H30 -> 0
F31: =D31+E31 -> 0 | I31: =G31+H31 -> 0
F32: =D32+E32 -> 0 | I32: =G32+H32 -> 0
F33: =D33+E33 -> 0 | I33: =G33+H33 -> 0
F34: =D34+E34 -> 0 | I34: =G34+H34 -> 0
F35: =D35+E35 -> 0 | I35: =G35+H35 -> 0
F36: =D36+E36 -> 0 | I36: =G36+H36 -> 0
F37: =D37+E37 -> 0 | I37: =G37+H37 -> 0
F38: =D38+E38 -> 0 | I38: =G38+H38 -> 0
F39: =D39+E39 -> 0 | I39: =G39+H39 -> 0
F40: =D40+E40 -> 0 | I40: =G40+H40 -> 0
... F55: =D55+E55 -> 0 | I55: =G55+H55 -> 0
...

Sheet Faturas
B2: FATURAS PRÓFORMA / ORÇAMENTOS - INVESTIMENTO
F3: (Em Euros)
B4: Nº | C4: DESCRIÇÃO | D4: Data (mês/ano) | E4: VALOR | F4: ANO
B6: Nº | C6: OBRAS | D6: Data (mês/ano) | E6: VALOR | F6: ANO
B7: 1 | F7: =YEAR(D7) -> 1900
B8: 2 | F8: =YEAR(D8) -> 1900
B9: 3 | F9: =YEAR(D9) -> 1900
B10: 4 | F10: =YEAR(D10) -> 1900
B11: 5 | F11: =YEAR(D11) -> 1900
B12: 6 | F12: =YEAR(D12) -> 1900
B13: 7 | F13: =YEAR(D13) -> 1900
B14: 8 | F14: =YEAR(D14) -> 1900
B15: 9 | F15: =YEAR(D15) -> 1900
B16: 10 | F16: =YEAR(D16) -> 1900
B17: 11 | F17: =YEAR(D17) -> 1900
B18: 12 | F18: =YEAR(D18) -> 1900
... B22: 16 | F22: =YEAR(D22) -> 1900
E23: =SUM(E7:E22) -> 0
B25: Nº | C25: EQUIPAMENTO | D25: Data (mês/ano) | E25: VALOR | F25: ANO | G25: É Biológico?
B26: 1 | C26: Ativos 2020 | D26: 43831 | F26: =YEAR(D26) -> 2020 | G26: Não
B27: =B26+1 -> 2 | C27: Ativos 2021 | D27: 44197 | E27: =+[1]Folha2!$H$42 -> 40000 | F27: =YEAR(D27) -> 2021 | G27: Não
B28: =B27+1 -> 3 | C28: Ativos 2022 | D28: 44562 | E28: 0 | F28: =YEAR(D28) -> 2022 | G28: Não
B29: =B28+1 -> 4 | F29: =YEAR(D29) -> 1900 | G29: Não
B30: =B29+1 -> 5 | F30: =YEAR(D30) -> 1900 | G30: Não
B31: =B30+1 -> 6 | F31: =YEAR(D31) -> 1900 | G31: Não
B32: =B31+1 -> 7 | F32: =YEAR(D32) -> 1900 | G32: Não
B33: =B32+1 -> 8 | F33: =YEAR(D33) -> 1900 | G33: Não
B34: =B33+1 -> 9 | F34: =YEAR(D34) -> 1900 | G34: Não
B35: =B34+1 -> 10 | F35: =YEAR(D35) -> 1900 | G35: Não
B36: =B35+1 -> 11 | F36: =YEAR(D36) -> 1900 | G36: Não
B37: =B36+1 -> 12 | F37: =YEAR(D37) -> 1900 | G37: Não
B38: =B37+1 -> 13 | F38: =YEAR(D38) -> 1900 | G38: Não
B39: =B38+1 -> 14 | F39: =YEAR(D39) -> 1900 | G39: Não
B40: =B39+1 -> 15 | F40: =YEAR(D40) -> 1900 | G40: Não
... B60: =B59+1 -> 35 | F60: =YEAR(D60) -> 1900 | G60: Não
E61: =SUM(E26:E60) -> 40000
B63: Nº | C63: INTANGÍVEL | D63: Data (mês/ano) | E63: VALOR | F63: ANO
B64: 1 | F64: =YEAR(D64) -> 1900
B65: 2 | F65: =YEAR(D65) -> 1900
B66: 3 | F66: =YEAR(D66) -> 1900
...

Sheet PlanoInvest
B2: PLANO DE INVESTIMENTO | D2: UNIDADE: EUROS
B3: RUBRICAS DO INVESTIMENTO | C3: Sujeito a iva | D3: CUSTO TOTAL DO INVESTIMENTO | E3: =Pressupostos!C11 -> 2020 | G3: =E3+1 -> 2021 | I3: =G3+1 -> 2022 | K3: =I3+1 -> 2023 | M3: =K3+1 -> 2024 | O3: =M3+1 -> 2025 | Q3: =O3+1 -> 2026 | S3: =Q3+1 -> 2027 | U3: =S3+1 -> 2028 | W3: =U3+1 -> 2029
E4: 1º SEM | F4: 2º SEM | G4: 1º SEM | H4: 2º SEM | I4: 1º SEM | J4: 2º SEM | K4: 1º SEM | L4: 2º SEM | M4: 1º SEM | N4: 2º SEM | O4: 1º SEM | P4: 2º SEM | Q4: 1º SEM | R4: 2º SEM | S4: 1º SEM | T4: 2º SEM | U4: 1º SEM | V4: 2º SEM | W4: 1º SEM | X4: 2º SEM
B5: OBRAS
A6: 1 | B6: =IF(Faturas!C7=0,"",Faturas!C7) | C6: Não | D6: =IF(Faturas!E7=0,"",Faturas!E7) | F6: =IF(Faturas!F7=$E$3,Faturas!E7,"0") -> 0 | H6: =IF(Faturas!F7=$G$3,Faturas!E7,"0") -> 0 | J6: =IF(Faturas!F7=$I$3,Faturas!E7,"0") -> 0 | L6: =IF(Faturas!F7=$K$3,Faturas!E7,"0") -> 0
A7: 2 | B7: =IF(Faturas!C8=0,"",Faturas!C8) | C7: Não | D7: =IF(Faturas!E8=0,"",Faturas!E8) | F7: =IF(Faturas!F8=$E$3,Faturas!E8,"0") -> 0 | H7: =IF(Faturas!F8=$G$3,Faturas!E8,"0") -> 0 | J7: =IF(Faturas!F8=$I$3,Faturas!E8,"0") -> 0 | L7: =IF(Faturas!F8=$K$3,Faturas!E8,"0") -> 0
A8: 3 | B8: =IF(Faturas!C9=0,"",Faturas!C9) | C8: Não | D8: =IF(Faturas!E9=0,"",Faturas!E9) | F8: =IF(Faturas!F9=$E$3,Faturas!E9,"0") -> 0 | H8: =IF(Faturas!F9=$G$3,Faturas!E9,"0") -> 0 | J8: =IF(Faturas!F9=$I$3,Faturas!E9,"0") -> 0 | L8: =IF(Faturas!F9=$K$3,Faturas!E9,"0") -> 0
A9: 4 | B9: =IF(Faturas!C10=0,"",Faturas!C10) | C9: Não | D9: =IF(Faturas!E10=0,"",Faturas!E10) | F9: =IF(Faturas!F10=$E$3,Faturas!E10,"0") -> 0 | H9: =IF(Faturas!F10=$G$3,Faturas!E10,"0") -> 0 | J9: =IF(Faturas!F10=$I$3,Faturas!E10,"0") -> 0 | L9: =IF(Faturas!F10=$K$3,Faturas!E10,"0") -> 0
A10: 5 | B10: =IF(Faturas!C11=0,"",Faturas!C11) | C10: Não | D10: =IF(Faturas!E11=0,"",Faturas!E11) | F10: =IF(Faturas!F11=$E$3,Faturas!E11,"0") -> 0 | H10: =IF(Faturas!F11=$G$3,Faturas!E11,"0") -> 0 | J10: =IF(Faturas!F11=$I$3,Faturas!E11,"0") -> 0 | L10: =IF(Faturas!F11=$K$3,Faturas!E11,"0") -> 0
A11: 6 | B11: =IF(Faturas!C12=0,"",Faturas!C12) | C11: Não | D11: =IF(Faturas!E12=0,"",Faturas!E12) | F11: =IF(Faturas!F12=$E$3,Faturas!E12,"0") -> 0 | H11: =IF(Faturas!F12=$G$3,Faturas!E12,"0") -> 0 | J11: =IF(Faturas!F12=$I$3,Faturas!E12,"0") -> 0 | L11: =IF(Faturas!F12=$K$3,Faturas!E12,"0") -> 0
A12: 7 | B12: =IF(Faturas!C13=0,"",Faturas!C13) | C12: Não | D12: =IF(Faturas!E13=0,"",Faturas!E13) | F12: =IF(Faturas!F13=$E$3,Faturas!E13,"0") -> 0 | H12: =IF(Faturas!F13=$G$3,Faturas!E13,"0") -> 0 | J12: =IF(Faturas!F13=$I$3,Faturas!E13,"0") -> 0 | L12: =IF(Faturas!F13=$K$3,Faturas!E13,"0") -> 0
A13: 8 | B13: =IF(Faturas!C14=0,"",Faturas!C14) | C13: Não | D13: =IF(Faturas!E14=0,"",Faturas!E14) | F13: =IF(Faturas!F14=$E$3,Faturas!E14,"0") -> 0 | H13: =IF(Faturas!F14=$G$3,Faturas!E14,"0") -> 0 | J13: =IF(Faturas!F14=$I$3,Faturas!E14,"0") -> 0 | L13: =IF(Faturas!F14=$K$3,Faturas!E14,"0") -> 0
A14: 9 | B14: =IF(Faturas!C15=0,"",Faturas!C15) | C14: Não | D14: =IF(Faturas!E15=0,"",Faturas!E15) | F14: =IF(Faturas!F15=$E$3,Faturas!E15,"0") -> 0 | H14: =IF(Faturas!F15=$G$3,Faturas!E15,"0") -> 0 | J14: =IF(Faturas!F15=$I$3,Faturas!E15,"0") -> 0 | L14: =IF(Faturas!F15=$K$3,Faturas!E15,"0") -> 0
A15: 10 | B15: =IF(Faturas!C16=0,"",Faturas!C16) | C15: Não | D15: =IF(Faturas!E16=0,"",Faturas!E16) | F15: =IF(Faturas!F16=$E$3,Faturas!E16,"0") -> 0 | H15: =IF(Faturas!F16=$G$3,Faturas!E16,"0") -> 0 | J15: =IF(Faturas!F16=$I$3,Faturas!E16,"0") -> 0 | L15: =IF(Faturas!F16=$K$3,Faturas!E16,"0") -> 0
A16: 11 | B16: =IF(Faturas!C17=0,"",Faturas!C17) | C16: Não | D16: =IF(Faturas!E17=0,"",Faturas!E17) | F16: =IF(Faturas!F17=$E$3,Faturas!E17,"0") -> 0 | H16: =IF(Faturas!F17=$G$3,Faturas!E17,"0") -> 0 | J16: =IF(Faturas!F17=$I$3,Faturas!E17,"0") -> 0 | L16: =IF(Faturas!F17=$K$3,Faturas!E17,"0") -> 0
A17: 12 | B17: =IF(Faturas!C18=0,"",Faturas!C18) | C17: Não | D17: =IF(Faturas!E18=0,"",Faturas!E18) | F17: =IF(Faturas!F18=$E$3,Faturas!E18,"0") -> 0 | H17: =IF(Faturas!F18=$G$3,Faturas!E18,"0") -> 0 | J17: =IF(Faturas!F18=$I$3,Faturas!E18,"0") -> 0 | L17: =IF(Faturas!F18=$K$3,Faturas!E18,"0") -> 0
... A21: 16 | B21: =IF(Faturas!C22=0,"",Faturas!C22) | C21: Não | D21: =IF(Faturas!E22=0,"",Faturas!E22) | F21: =IF(Faturas!F22=$E$3,Faturas!E22,"0") -> 0 | H21: =IF(Faturas!F22=$G$3,Faturas!E22,"0") -> 0 | J21: =IF(Faturas!F22=$I$3,Faturas!E22,"0") -> 0 | L21: =IF(Faturas!F22=$K$3,Faturas!E22,"0") -> 0
B22: SUBTOTAL | D22: =SUM(D6:D21) -> 0 | E22: =SUM(E6:E21) -> 0 | F22: =SUM(F6:F21) -> 0 | G22: =SUM(G6:G21) -> 0 | H22: =SUM(H6:H21) -> 0 | I22: =SUM(I6:I21) -> 0 | J22: =SUM(J6:J21) -> 0 | K22: =SUM(K6:K21) -> 0 | ... X22: =SUM(X6:X21) -> 0
B23: EQUIPAMENTO
A24: 1 | B24: =IF(Faturas!C26=0,"",Faturas!C26) -> Ativos 2020 | C24: Sim | D24: =IF(Faturas!E26=0,"",Faturas!E26) | F24: =IF(Faturas!F26=$E$3,Faturas!E26,"0") -> 0 | H24: =IF(Faturas!F26=$G$3,Faturas!E26,"0") -> 0 | J24: =IF(Faturas!F26=$I$3,Faturas!E26,"0") -> 0 | L24: =IF(Faturas!F26=$K$3,Faturas!E26,"0") -> 0
A25: 2 | B25: =IF(Faturas!C27=0,"",Faturas!C27) -> Ativos 2021 | C25: Sim | D25: =IF(Faturas!E27=0,"",Faturas!E27) -> 40000 | F25: =IF(Faturas!F27=$E$3,Faturas!E27,"0") -> 0 | H25: =IF(Faturas!F27=$G$3,Faturas!E27,"0") -> 40000 | J25: =IF(Faturas!F27=$I$3,Faturas!E27,"0") -> 0 | L25: =IF(Faturas!F27=$K$3,Faturas!E27,"0") -> 0
A26: 3 | B26: =IF(Faturas!C28=0,"",Faturas!C28) -> Ativos 2022 | C26: Sim | D26: =IF(Faturas!E28=0,"",Faturas!E28) | F26: =IF(Faturas!F28=$E$3,Faturas!E28,"0") -> 0 | H26: =IF(Faturas!F28=$G$3,Faturas!E28,"0") -> 0 | J26: =IF(Faturas!F28=$I$3,Faturas!E28,"0") -> 0 | L26: =IF(Faturas!F28=$K$3,Faturas!E28,"0") -> 0
A27: 4 | B27: =IF(Faturas!C29=0,"",Faturas!C29) | C27: Sim | D27: =IF(Faturas!E29=0,"",Faturas!E29) | F27: =IF(Faturas!F29=$E$3,Faturas!E29,"0") -> 0 | H27: =IF(Faturas!F29=$G$3,Faturas!E29,"0") -> 0 | J27: =IF(Faturas!F29=$I$3,Faturas!E29,"0") -> 0 | L27: =IF(Faturas!F29=$K$3,Faturas!E29,"0") -> 0
A28: 5 | B28: =IF(Faturas!C30=0,"",Faturas!C30) | C28: Sim | D28: =IF(Faturas!E30=0,"",Faturas!E30) | F28: =IF(Faturas!F30=$E$3,Faturas!E30,"0") -> 0 | H28: =IF(Faturas!F30=$G$3,Faturas!E30,"0") -> 0 | J28: =IF(Faturas!F30=$I$3,Faturas!E30,"0") -> 0 | L28: =IF(Faturas!F30=$K$3,Faturas!E30,"0") -> 0
A29: 6 | B29: =IF(Faturas!C31=0,"",Faturas!C31) | C29: Sim | D29: =IF(Faturas!E31=0,"",Faturas!E31) | F29: =IF(Faturas!F31=$E$3,Faturas!E31,"0") -> 0 | H29: =IF(Faturas!F31=$G$3,Faturas!E31,"0") -> 0 | J29: =IF(Faturas!F31=$I$3,Faturas!E31,"0") -> 0 | L29: =IF(Faturas!F31=$K$3,Faturas!E31,"0") -> 0
A30: 7 | B30: =IF(Faturas!C32=0,"",Faturas!C32) | C30: Sim | D30: =IF(Faturas!E32=0,"",Faturas!E32) | F30: =IF(Faturas!F32=$E$3,Faturas!E32,"0") -> 0 | H30: =IF(Faturas!F32=$G$3,Faturas!E32,"0") -> 0 | J30: =IF(Faturas!F32=$I$3,Faturas!E32,"0") -> 0 | L30: =IF(Faturas!F32=$K$3,Faturas!E32,"0") -> 0
A31: 8 | B31: =IF(Faturas!C33=0,"",Faturas!C33) | C31: Sim | D31: =IF(Faturas!E33=0,"",Faturas!E33) | F31: =IF(Faturas!F33=$E$3,Faturas!E33,"0") -> 0 | H31: =IF(Faturas!F33=$G$3,Faturas!E33,"0") -> 0 | J31: =IF(Faturas!F33=$I$3,Faturas!E33,"0") -> 0 | L31: =IF(Faturas!F33=$K$3,Faturas!E33,"0") -> 0
A32: 9 | B32: =IF(Faturas!C34=0,"",Faturas!C34) | C32: Sim | D32: =IF(Faturas!E34=0,"",Faturas!E34) | F32: =IF(Faturas!F34=$E$3,Faturas!E34,"0") -> 0 | H32: =IF(Faturas!F34=$G$3,Faturas!E34,"0") -> 0 | J32: =IF(Faturas!F34=$I$3,Faturas!E34,"0") -> 0 | L32: =IF(Faturas!F34=$K$3,Faturas!E34,"0") -> 0
A33: 10 | B33: =IF(Faturas!C35=0,"",Faturas!C35) | C33: Sim | D33: =IF(Faturas!E35=0,"",Faturas!E35) | F33: =IF(Faturas!F35=$E$3,Faturas!E35,"0") -> 0 | H33: =IF(Faturas!F35=$G$3,Faturas!E35,"0") -> 0 | J33: =IF(Faturas!F35=$I$3,Faturas!E35,"0") -> 0 | L33: =IF(Faturas!F35=$K$3,Faturas!E35,"0") -> 0
A34: 11 | B34: =IF(Faturas!C36=0,"",Faturas!C36) | C34: Sim | D34: =IF(Faturas!E36=0,"",Faturas!E36) | F34: =IF(Faturas!F36=$E$3,Faturas!E36,"0") -> 0 | H34: =IF(Faturas!F36=$G$3,Faturas!E36,"0") -> 0 | J34: =IF(Faturas!F36=$I$3,Faturas!E36,"0") -> 0 | L34: =IF(Faturas!F36=$K$3,Faturas!E36,"0") -> 0
A35: 12 | B35: =IF(Faturas!C37=0,"",Faturas!C37) | C35: Sim | D35: =IF(Faturas!E37=0,"",Faturas!E37) | F35: =IF(Faturas!F37=$E$3,Faturas!E37,"0") -> 0 | H35: =IF(Faturas!F37=$G$3,Faturas!E37,"0") -> 0 | J35: =IF(Faturas!F37=$I$3,Faturas!E37,"0") -> 0 | L35: =IF(Faturas!F37=$K$3,Faturas!E37,"0") -> 0
... A58: 35 | B58: =IF(Faturas!C60=0,"",Faturas!C60) | C58: Sim | D58: =IF(Faturas!E60=0,"",Faturas!E60) | F58: =IF(Faturas!F60=$E$3,Faturas!E60,"0") -> 0 | H58: =IF(Faturas!F60=$G$3,Faturas!E60,"0") -> 0 | J58: =IF(Faturas!F60=$I$3,Faturas!E60,"0") -> 0 | L58: =IF(Faturas!F60=$K$3,Faturas!E60,"0") -> 0
B59: SUB-TOTAL | D59: =SUM(D24:D58) -> 40000 | E59: =SUM(E24:E58) -> 0 | F59: =SUM(F24:F58) -> 0 | G59: =SUM(G24:G58) -> 0 | H59: =SUM(H24:H58) -> 40000 | I59: =SUM(I24:I58) -> 0 | J59: =SUM(J24:J58) -> 0 | K59: =SUM(K24:K58) -> 0 | ... X59: =SUM(X24:X58) -> 0
B60: INTANGÍVEL
A61: 1 | B61: =IF(Faturas!C64=0,"",Faturas!C64) | C61: Sim | D61: =IF(Faturas!E64=0,"",Faturas!E64) | F61: =IF(Faturas!F64=$E$3,Faturas!E64,"0") -> 0 | H61: =IF(Faturas!F64=$G$3,Faturas!E64,"0") -> 0 | J61: =IF(Faturas!F64=$I$3,Faturas!E64,"0") -> 0 | L61: =IF(Faturas!F64=$K$3,Faturas!E64,"0") -> 0
A62: 2 | B62: =IF(Faturas!C65=0,"",Faturas!C65) | C62: Sim | D62: =IF(Faturas!E65=0,"",Faturas!E65) | F62: =IF(Faturas!F65=$E$3,Faturas!E65,"0") -> 0 | H62: =IF(Faturas!F65=$G$3,Faturas!E65,"0") -> 0 | J62: =IF(Faturas!F65=$I$3,Faturas!E65,"0") -> 0 | L62: =IF(Faturas!F65=$K$3,Faturas!E65,"0") -> 0
A63: 3 | B63: =IF(Faturas!C66=0,"",Faturas!C66) | C63: Sim | D63: =IF(Faturas!E66=0,"",Faturas!E66) | F63: =IF(Faturas!F66=$E$3,Faturas!E66,"0") -> 0 | H63: =IF(Faturas!F66=$G$3,Faturas!E66,"0") -> 0 | J63: =IF(Faturas!F66=$I$3,Faturas!E66,"0") -> 0 | L63: =IF(Faturas!F66=$K$3,Faturas!E66,"0") -> 0
A64: 4 | B64: =IF(Faturas!C67=0,"",Faturas!C67) | C64: Sim | D64: =IF(Faturas!E67=0,"",Faturas!E67) | F64: =IF(Faturas!F67=$E$3,Faturas!E67,"0") -> 0 | H64: =IF(Faturas!F67=$G$3,Faturas!E67,"0") -> 0 | J64: =IF(Faturas!F67=$I$3,Faturas!E67,"0") -> 0 | L64: =IF(Faturas!F67=$K$3,Faturas!E67,"0") -> 0
A65: 5 | B65: =IF(Faturas!C68=0,"",Faturas!C68) | C65: Sim | D65: =IF(Faturas!E68=0,"",Faturas!E68) | F65: =IF(Faturas!F68=$E$3,Faturas!E68,"0") -> 0 | H65: =IF(Faturas!F68=$G$3,Faturas!E68,"0") -> 0 | J65: =IF(Faturas!F68=$I$3,Faturas!E68,"0") -> 0 | L65: =IF(Faturas!F68=$K$3,Faturas!E68,"0") -> 0
A66: 6 | B66: =IF(Faturas!C69=0,"",Faturas!C69) | C66: Sim | D66: =IF(Faturas!E69=0,"",Faturas!E69) | F66: =IF(Faturas!F69=$E$3,Faturas!E69,"0") -> 0 | H66: =IF(Faturas!F69=$G$3,Faturas!E69,"0") -> 0 | J66: =IF(Faturas!F69=$I$3,Faturas!E69,"0") -> 0 | L66: =IF(Faturas!F69=$K$3,Faturas!E69,"0") -> 0
...

Sheet Amortização
B2: PLANO DE AMORTIZAÇÃO | K2: UNIDADE: EUROS
B3: RUBRICAS DO INVESTIMENTO | C3: TAXA | D3: VALOR | E3: =Pressupostos!C11 -> 2020 | F3: =E3+1 -> 2021 | G3: =F3+1 -> 2022 | H3: =G3+1 -> 2023 | I3: =H3+1 -> 2024 | J3: =I3+1 -> 2025 | K3: =J3+1 -> 2026 | L3: =K3+1 -> 2027 | M3: =L3+1 -> 2028 | N3: =M3+1 -> 2029 | O3: VALOR RESIDUAL
B5: OBRAS
A6: 1 | B6: =IF(Faturas!C7=0,"",Faturas!C7) | C6: 0 | D6: =IF(Faturas!E7=0,"",Faturas!E7) | K6: =IF($B6="","",IF($C6=0,0,IF(K$3-$E$3<1/$C6,$D6*$C6,0))) | L6: =IF($B6="","",IF($C6=0,0,IF(L$3-$E$3<1/$C6,$D6*$C6,0))) | M6: =IF($B6="","",IF($C6=0,0,IF(M$3-$E$3<1/$C6,$D6*$C6,0))) | N6: =IF($B6="","",IF($C6=0,0,IF(N$3-$E$3<1/$C6,$D6*$C6,0))) | O6: =IF($B6="","",D6-SUM(E6:N6))
A7: 2 | B7: =IF(Faturas!C8=0,"",Faturas!C8) | C7: 0 | D7: =IF(Faturas!E8=0,"",Faturas!E8) | K7: =IF($B7="","",IF($C7=0,0,IF(K$3-$E$3<1/$C7,$D7*$C7,0))) | L7: =IF($B7="","",IF($C7=0,0,IF(L$3-$E$3<1/$C7,$D7*$C7,0))) | M7: =IF($B7="","",IF($C7=0,0,IF(M$3-$E$3<1/$C7,$D7*$C7,0))) | N7: =IF($B7="","",IF($C7=0,0,IF(N$3-$E$3<1/$C7,$D7*$C7,0))) | O7: =IF($B7="","",D7-SUM(E7:N7))
A8: 3 | B8: =IF(Faturas!C9=0,"",Faturas!C9) | C8: 0 | D8: =IF(Faturas!E9=0,"",Faturas!E9) | K8: =IF($B8="","",IF($C8=0,0,IF(K$3-$E$3<1/$C8,$D8*$C8,0))) | L8: =IF($B8="","",IF($C8=0,0,IF(L$3-$E$3<1/$C8,$D8*$C8,0))) | M8: =IF($B8="","",IF($C8=0,0,IF(M$3-$E$3<1/$C8,$D8*$C8,0))) | N8: =IF($B8="","",IF($C8=0,0,IF(N$3-$E$3<1/$C8,$D8*$C8,0))) | O8: =IF($B8="","",D8-SUM(E8:N8))
A9: 4 | B9: =IF(Faturas!C10=0,"",Faturas!C10) | C9: 0 | D9: =IF(Faturas!E10=0,"",Faturas!E10) | K9: =IF($B9="","",IF($C9=0,0,IF(K$3-$E$3<1/$C9,$D9*$C9,0))) | L9: =IF($B9="","",IF($C9=0,0,IF(L$3-$E$3<1/$C9,$D9*$C9,0))) | M9: =IF($B9="","",IF($C9=0,0,IF(M$3-$E$3<1/$C9,$D9*$C9,0))) | N9: =IF($B9="","",IF($C9=0,0,IF(N$3-$E$3<1/$C9,$D9*$C9,0))) | O9: =IF($B9="","",D9-SUM(E9:N9))
A10: 5 | B10: =IF(Faturas!C11=0,"",Faturas!C11) | C10: 0 | D10: =IF(Faturas!E11=0,"",Faturas!E11) | K10: =IF($B10="","",IF($C10=0,0,IF(K$3-$E$3<1/$C10,$D10*$C10,0))) | L10: =IF($B10="","",IF($C10=0,0,IF(L$3-$E$3<1/$C10,$D10*$C10,0))) | M10: =IF($B10="","",IF($C10=0,0,IF(M$3-$E$3<1/$C10,$D10*$C10,0))) | N10: =IF($B10="","",IF($C10=0,0,IF(N$3-$E$3<1/$C10,$D10*$C10,0))) | O10: =IF($B10="","",D10-SUM(E10:N10))
A11: 6 | B11: =IF(Faturas!C12=0,"",Faturas!C12) | C11: 0 | D11: =IF(Faturas!E12=0,"",Faturas!E12) | K11: =IF($B11="","",IF($C11=0,0,IF(K$3-$E$3<1/$C11,$D11*$C11,0))) | L11: =IF($B11="","",IF($C11=0,0,IF(L$3-$E$3<1/$C11,$D11*$C11,0))) | M11: =IF($B11="","",IF($C11=0,0,IF(M$3-$E$3<1/$C11,$D11*$C11,0))) | N11: =IF($B11="","",IF($C11=0,0,IF(N$3-$E$3<1/$C11,$D11*$C11,0))) | O11: =IF($B11="","",D11-SUM(E11:N11))
A12: 7 | B12: =IF(Faturas!C13=0,"",Faturas!C13) | C12: 0 | D12: =IF(Faturas!E13=0,"",Faturas!E13) | K12: =IF($B12="","",IF($C12=0,0,IF(K$3-$E$3<1/$C12,$D12*$C12,0))) | L12: =IF($B12="","",IF($C12=0,0,IF(L$3-$E$3<1/$C12,$D12*$C12,0))) | M12: =IF($B12="","",IF($C12=0,0,IF(M$3-$E$3<1/$C12,$D12*$C12,0))) | N12: =IF($B12="","",IF($C12=0,0,IF(N$3-$E$3<1/$C12,$D12*$C12,0))) | O12: =IF($B12="","",D12-SUM(E12:N12))
A13: 8 | B13: =IF(Faturas!C14=0,"",Faturas!C14) | C13: 0 | D13: =IF(Faturas!E14=0,"",Faturas!E14) | K13: =IF($B13="","",IF($C13=0,0,IF(K$3-$E$3<1/$C13,$D13*$C13,0))) | L13: =IF($B13="","",IF($C13=0,0,IF(L$3-$E$3<1/$C13,$D13*$C13,0))) | M13: =IF($B13="","",IF($C13=0,0,IF(M$3-$E$3<1/$C13,$D13*$C13,0))) | N13: =IF($B13="","",IF($C13=0,0,IF(N$3-$E$3<1/$C13,$D13*$C13,0))) | O13: =IF($B13="","",D13-SUM(E13:N13))
A14: 9 | B14: =IF(Faturas!C15=0,"",Faturas!C15) | C14: 0 | D14: =IF(Faturas!E15=0,"",Faturas!E15) | K14: =IF($B14="","",IF($C14=0,0,IF(K$3-$E$3<1/$C14,$D14*$C14,0))) | L14: =IF($B14="","",IF($C14=0,0,IF(L$3-$E$3<1/$C14,$D14*$C14,0))) | M14: =IF($B14="","",IF($C14=0,0,IF(M$3-$E$3<1/$C14,$D14*$C14,0))) | N14: =IF($B14="","",IF($C14=0,0,IF(N$3-$E$3<1/$C14,$D14*$C14,0))) | O14: =IF($B14="","",D14-SUM(E14:N14))
A15: 10 | B15: =IF(Faturas!C16=0,"",Faturas!C16) | C15: 0 | D15: =IF(Faturas!E16=0,"",Faturas!E16) | K15: =IF($B15="","",IF($C15=0,0,IF(K$3-$E$3<1/$C15,$D15*$C15,0))) | L15: =IF($B15="","",IF($C15=0,0,IF(L$3-$E$3<1/$C15,$D15*$C15,0))) | M15: =IF($B15="","",IF($C15=0,0,IF(M$3-$E$3<1/$C15,$D15*$C15,0))) | N15: =IF($B15="","",IF($C15=0,0,IF(N$3-$E$3<1/$C15,$D15*$C15,0))) | O15: =IF($B15="","",D15-SUM(E15:N15))
A16: 11 | B16: =IF(Faturas!C17=0,"",Faturas!C17) | C16: 0 | D16: =IF(Faturas!E17=0,"",Faturas!E17) | K16: =IF($B16="","",IF($C16=0,0,IF(K$3-$E$3<1/$C16,$D16*$C16,0))) | L16: =IF($B16="","",IF($C16=0,0,IF(L$3-$E$3<1/$C16,$D16*$C16,0))) | M16: =IF($B16="","",IF($C16=0,0,IF(M$3-$E$3<1/$C16,$D16*$C16,0))) | N16: =IF($B16="","",IF($C16=0,0,IF(N$3-$E$3<1/$C16,$D16*$C16,0))) | O16: =IF($B16="","",D16-SUM(E16:N16))
A17: 12 | B17: =IF(Faturas!C18=0,"",Faturas!C18) | C17: 0 | D17: =IF(Faturas!E18=0,"",Faturas!E18) | K17: =IF($B17="","",IF($C17=0,0,IF(K$3-$E$3<1/$C17,$D17*$C17,0))) | L17: =IF($B17="","",IF($C17=0,0,IF(L$3-$E$3<1/$C17,$D17*$C17,0))) | M17: =IF($B17="","",IF($C17=0,0,IF(M$3-$E$3<1/$C17,$D17*$C17,0))) | N17: =IF($B17="","",IF($C17=0,0,IF(N$3-$E$3<1/$C17,$D17*$C17,0))) | O17: =IF($B17="","",D17-SUM(E17:N17))
... A21: 16 | B21: =IF(Faturas!C22=0,"",Faturas!C22) | C21: 0 | D21: =IF(Faturas!E22=0,"",Faturas!E22) | K21: =IF($B21="","",IF($C21=0,0,IF(K$3-$E$3<1/$C21,$D21*$C21,0))) | L21: =IF($B21="","",IF($C21=0,0,IF(L$3-$E$3<1/$C21,$D21*$C21,0))) | M21: =IF($B21="","",IF($C21=0,0,IF(M$3-$E$3<1/$C21,$D21*$C21,0))) | N21: =IF($B21="","",IF($C21=0,0,IF(N$3-$E$3<1/$C21,$D21*$C21,0))) | O21: =IF($B21="","",D21-SUM(E21:N21))
B22: Total Obras | D22: =SUM(D6:D21) -> 0 | E22: =SUM(E6:E21) -> 0 | F22: =SUM(F6:F21) -> 0 | G22: =SUM(G6:G21) -> 0 | H22: =SUM(H6:H21) -> 0 | I22: =SUM(I6:I21) -> 0 | J22: =SUM(J6:J21) -> 0 | K22: =SUM(K6:K21) -> 0 | ... O22: =SUM(O6:O21) -> 0
B24: EQUIPAMENTO
A25: 1 | B25: =IF(Faturas!C26=0,"",Faturas!C26) -> Ativos 2020 | C25: 0.25 | D25: =IF(Faturas!E26=0,"",Faturas!E26) | K25: =IF($B25="","",IF($C25=0,0,IF(K$3-$E$3<1/$C25,$D25*$C25,0))) -> 0 | L25: =IF($B25="","",IF($C25=0,0,IF(L$3-$E$3<1/$C25,$D25*$C25,0))) -> 0 | M25: =IF($B25="","",IF($C25=0,0,IF(M$3-$E$3<1/$C25,$D25*$C25,0))) -> 0 | N25: =IF($B25="","",IF($C25=0,0,IF(N$3-$E$3<1/$C25,$D25*$C25,0))) -> 0 | O25: =IF($B25="","",D25-SUM(E25:N25)) -> #VALUE!
A26: 2 | B26: =IF(Faturas!C27=0,"",Faturas!C27) -> Ativos 2021 | C26: 0.25 | D26: =IF(Faturas!E27=0,"",Faturas!E27) -> 40000 | F26: =$D$26*$C$26 -> 10000 | G26: =$D$26*$C$26 -> 10000 | H26: =$D$26*$C$26 -> 10000 | I26: =$D$26*$C$26 -> 10000 | K26: =IF($B26="","",IF($C26=0,0,IF(K$3-$E$3<1/$C26,$D26*$C26,0))) -> 0 | L26: =IF($B26="","",IF($C26=0,0,IF(L$3-$E$3<1/$C26,$D26*$C26,0))) -> 0 | M26: =IF($B26="","",IF($C26=0,0,IF(M$3-$E$3<1/$C26,$D26*$C26,0))) -> 0 | N26: =IF($B26="","",IF($C26=0,0,IF(N$3-$E$3<1/$C26,$D26*$C26,0))) -> 0 | O26: =IF($B26="","",D26-SUM(E26:N26)) -> 0
A27: 3 | B27: =IF(Faturas!C28=0,"",Faturas!C28) -> Ativos 2022 | C27: 0.25 | D27: =IF(Faturas!E28=0,"",Faturas!E28) | K27: =IF($B27="","",IF($C27=0,0,IF(K$3-$E$3<1/$C27,$D27*$C27,0))) -> 0 | L27: =IF($B27="","",IF($C27=0,0,IF(L$3-$E$3<1/$C27,$D27*$C27,0))) -> 0 | M27: =IF($B27="","",IF($C27=0,0,IF(M$3-$E$3<1/$C27,$D27*$C27,0))) -> 0 | N27: =IF($B27="","",IF($C27=0,0,IF(N$3-$E$3<1/$C27,$D27*$C27,0))) -> 0 | O27: =IF($B27="","",D27-SUM(E27:N27)) -> #VALUE!
A28: 4 | B28: =IF(Faturas!C29=0,"",Faturas!C29) | C28: 0 | D28: =IF(Faturas!E29=0,"",Faturas!E29) | K28: =IF($B28="","",IF($C28=0,0,IF(K$3-$E$3<1/$C28,$D28*$C28,0))) | L28: =IF($B28="","",IF($C28=0,0,IF(L$3-$E$3<1/$C28,$D28*$C28,0))) | M28: =IF($B28="","",IF($C28=0,0,IF(M$3-$E$3<1/$C28,$D28*$C28,0))) | N28: =IF($B28="","",IF($C28=0,0,IF(N$3-$E$3<1/$C28,$D28*$C28,0))) | O28: =IF($B28="","",D28-SUM(E28:N28))
A29: 5 | B29: =IF(Faturas!C30=0,"",Faturas!C30) | C29: 0 | D29: =IF(Faturas!E30=0,"",Faturas!E30) | K29: =IF($B29="","",IF($C29=0,0,IF(K$3-$E$3<1/$C29,$D29*$C29,0))) | L29: =IF($B29="","",IF($C29=0,0,IF(L$3-$E$3<1/$C29,$D29*$C29,0))) | M29: =IF($B29="","",IF($C29=0,0,IF(M$3-$E$3<1/$C29,$D29*$C29,0))) | N29: =IF($B29="","",IF($C29=0,0,IF(N$3-$E$3<1/$C29,$D29*$C29,0))) | O29: =IF($B29="","",D29-SUM(E29:N29))
A30: 6 | B30: =IF(Faturas!C31=0,"",Faturas!C31) | C30: 0 | D30: =IF(Faturas!E31=0,"",Faturas!E31) | K30: =IF($B30="","",IF($C30=0,0,IF(K$3-$E$3<1/$C30,$D30*$C30,0))) | L30: =IF($B30="","",IF($C30=0,0,IF(L$3-$E$3<1/$C30,$D30*$C30,0))) | M30: =IF($B30="","",IF($C30=0,0,IF(M$3-$E$3<1/$C30,$D30*$C30,0))) | N30: =IF($B30="","",IF($C30=0,0,IF(N$3-$E$3<1/$C30,$D30*$C30,0))) | O30: =IF($B30="","",D30-SUM(E30:N30))
A31: 7 | B31: =IF(Faturas!C32=0,"",Faturas!C32) | C31: 0 | D31: =IF(Faturas!E32=0,"",Faturas!E32) | K31: =IF($B31="","",IF($C31=0,0,IF(K$3-$E$3<1/$C31,$D31*$C31,0))) | L31: =IF($B31="","",IF($C31=0,0,IF(L$3-$E$3<1/$C31,$D31*$C31,0))) | M31: =IF($B31="","",IF($C31=0,0,IF(M$3-$E$3<1/$C31,$D31*$C31,0))) | N31: =IF($B31="","",IF($C31=0,0,IF(N$3-$E$3<1/$C31,$D31*$C31,0))) | O31: =IF($B31="","",D31-SUM(E31:N31))
A32: 8 | B32: =IF(Faturas!C33=0,"",Faturas!C33) | C32: 0 | D32: =IF(Faturas!E33=0,"",Faturas!E33) | K32: =IF($B32="","",IF($C32=0,0,IF(K$3-$E$3<1/$C32,$D32*$C32,0))) | L32: =IF($B32="","",IF($C32=0,0,IF(L$3-$E$3<1/$C32,$D32*$C32,0))) | M32: =IF($B32="","",IF($C32=0,0,IF(M$3-$E$3<1/$C32,$D32*$C32,0))) | N32: =IF($B32="","",IF($C32=0,0,IF(N$3-$E$3<1/$C32,$D32*$C32,0))) | O32: =IF($B32="","",D32-SUM(E32:N32))
A33: 9 | B33: =IF(Faturas!C34=0,"",Faturas!C34) | C33: 0 | D33: =IF(Faturas!E34=0,"",Faturas!E34) | K33: =IF($B33="","",IF($C33=0,0,IF(K$3-$E$3<1/$C33,$D33*$C33,0))) | L33: =IF($B33="","",IF($C33=0,0,IF(L$3-$E$3<1/$C33,$D33*$C33,0))) | M33: =IF($B33="","",IF($C33=0,0,IF(M$3-$E$3<1/$C33,$D33*$C33,0))) | N33: =IF($B33="","",IF($C33=0,0,IF(N$3-$E$3<1/$C33,$D33*$C33,0))) | O33: =IF($B33="","",D33-SUM(E33:N33))
A34: 10 | B34: =IF(Faturas!C35=0,"",Faturas!C35) | C34: 0 | D34: =IF(Faturas!E35=0,"",Faturas!E35) | K34: =IF($B34="","",IF($C34=0,0,IF(K$3-$E$3<1/$C34,$D34*$C34,0))) | L34: =IF($B34="","",IF($C34=0,0,IF(L$3-$E$3<1/$C34,$D34*$C34,0))) | M34: =IF($B34="","",IF($C34=0,0,IF(M$3-$E$3<1/$C34,$D34*$C34,0))) | N34: =IF($B34="","",IF($C34=0,0,IF(N$3-$E$3<1/$C34,$D34*$C34,0))) | O34: =IF($B34="","",D34-SUM(E34:N34))
A35: 11 | B35: =IF(Faturas!C36=0,"",Faturas!C36) | C35: 0 | D35: =IF(Faturas!E36=0,"",Faturas!E36) | K35: =IF($B35="","",IF($C35=0,0,IF(K$3-$E$3<1/$C35,$D35*$C35,0))) | L35: =IF($B35="","",IF($C35=0,0,IF(L$3-$E$3<1/$C35,$D35*$C35,0))) | M35: =IF($B35="","",IF($C35=0,0,IF(M$3-$E$3<1/$C35,$D35*$C35,0))) | N35: =IF($B35="","",IF($C35=0,0,IF(N$3-$E$3<1/$C35,$D35*$C35,0))) | O35: =IF($B35="","",D35-SUM(E35:N35))
A36: 12 | B36: =IF(Faturas!C37=0,"",Faturas!C37) | C36: 0 | D36: =IF(Faturas!E37=0,"",Faturas!E37) | K36: =IF($B36="","",IF($C36=0,0,IF(K$3-$E$3<1/$C36,$D36*$C36,0))) | L36: =IF($B36="","",IF($C36=0,0,IF(L$3-$E$3<1/$C36,$D36*$C36,0))) | M36: =IF($B36="","",IF($C36=0,0,IF(M$3-$E$3<1/$C36,$D36*$C36,0))) | N36: =IF($B36="","",IF($C36=0,0,IF(N$3-$E$3<1/$C36,$D36*$C36,0))) | O36: =IF($B36="","",D36-SUM(E36:N36))
A37: 13 | B37: =IF(Faturas!C38=0,"",Faturas!C38) | C37: 0 | D37: =IF(Faturas!E38=0,"",Faturas!E38) | K37: =IF($B37="","",IF($C37=0,0,IF(K$3-$E$3<1/$C37,$D37*$C37,0))) | L37: =IF($B37="","",IF($C37=0,0,IF(L$3-$E$3<1/$C37,$D37*$C37,0))) | M37: =IF($B37="","",IF($C37=0,0,IF(M$3-$E$3<1/$C37,$D37*$C37,0))) | N37: =IF($B37="","",IF($C37=0,0,IF(N$3-$E$3<1/$C37,$D37*$C37,0))) | O37: =IF($B37="","",D37-SUM(E37:N37))
A38: 14 | B38: =IF(Faturas!C39=0,"",Faturas!C39) | C38: 0 | D38: =IF(Faturas!E39=0,"",Faturas!E39) | K38: =IF($B38="","",IF($C38=0,0,IF(K$3-$E$3<1/$C38,$D38*$C38,0))) | L38: =IF($B38="","",IF($C38=0,0,IF(L$3-$E$3<1/$C38,$D38*$C38,0))) | M38: =IF($B38="","",IF($C38=0,0,IF(M$3-$E$3<1/$C38,$D38*$C38,0))) | N38: =IF($B38="","",IF($C38=0,0,IF(N$3-$E$3<1/$C38,$D38*$C38,0))) | O38: =IF($B38="","",D38-SUM(E38:N38))
... A59: 35 | B59: =IF(Faturas!C60=0,"",Faturas!C60) | C59: 0 | D59: =IF(Faturas!E60=0,"",Faturas!E60) | K59: =IF($B59="","",IF($C59=0,0,IF(K$3-$E$3<1/$C59,$D59*$C59,0))) | L59: =IF($B59="","",IF($C59=0,0,IF(L$3-$E$3<1/$C59,$D59*$C59,0))) | M59: =IF($B59="","",IF($C59=0,0,IF(M$3-$E$3<1/$C59,$D59*$C59,0))) | N59: =IF($B59="","",IF($C59=0,0,IF(N$3-$E$3<1/$C59,$D59*$C59,0))) | O59: =IF($B59="","",D59-SUM(E59:N59))
B60: Total Equipamento | D60: =SUM(D25:D59) -> 40000 | E60: =SUM(E25:E59) -> 0 | F60: =SUM(F25:F59) -> 10000 | G60: =SUM(G25:G59) -> 10000 | H60: =SUM(H25:H59) -> 10000 | I60: =SUM(I25:I59) -> 10000 | J60: =SUM(J25:J59) -> 0 | K60: =SUM(K25:K59) -> 0 | ... O60: =SUM(O25:O59) -> #VALUE!
B62: INTANGÍVEL
A63: 1 | B63: =IF(Faturas!C64=0,"",Faturas!C64) | C63: 0.3333333 | D63: =IF(Faturas!E64=0,"",Faturas!E64) | K63: =IF($B63="","",IF($C63=0,0,IF(K$3-$E$3<1/$C63,$D63*$C63,0))) | L63: =IF($B63="","",IF($C63=0,0,IF(L$3-$E$3<1/$C63,$D63*$C63,0))) | M63: =IF($B63="","",IF($C63=0,0,IF(M$3-$E$3<1/$C63,$D63*$C63,0))) | N63: =IF($B63="","",IF($C63=0,0,IF(N$3-$E$3<1/$C63,$D63*$C63,0))) | O63: =IF($B63="","",D63-SUM(E63:N63))
A64: 2 | B64: =IF(Faturas!C65=0,"",Faturas!C65) | C64: 0 | D64: =IF(Faturas!E65=0,"",Faturas!E65) | K64: =IF($B64="","",IF($C64=0,0,IF(K$3-$E$3<1/$C64,$D64*$C64,0))) | L64: =IF($B64="","",IF($C64=0,0,IF(L$3-$E$3<1/$C64,$D64*$C64,0))) | M64: =IF($B64="","",IF($C64=0,0,IF(M$3-$E$3<1/$C64,$D64*$C64,0))) | N64: =IF($B64="","",IF($C64=0,0,IF(N$3-$E$3<1/$C64,$D64*$C64,0))) | O64: =IF($B64="","",D64-SUM(E64:N64))
A65: 3 | B65: =IF(Faturas!C66=0,"",Faturas!C66) | C65: 0 | D65: =IF(Faturas!E66=0,"",Faturas!E66) | K65: =IF($B65="","",IF($C65=0,0,IF(K$3-$E$3<1/$C65,$D65*$C65,0))) | L65: =IF($B65="","",IF($C65=0,0,IF(L$3-$E$3<1/$C65,$D65*$C65,0))) | M65: =IF($B65="","",IF($C65=0,0,IF(M$3-$E$3<1/$C65,$D65*$C65,0))) | N65: =IF($B65="","",IF($C65=0,0,IF(N$3-$E$3<1/$C65,$D65*$C65,0))) | O65: =IF($B65="","",D65-SUM(E65:N65))
A66: 4 | B66: =IF(Faturas!C67=0,"",Faturas!C67) | C66: 0 | D66: =IF(Faturas!E67=0,"",Faturas!E67) | K66: =IF($B66="","",IF($C66=0,0,IF(K$3-$E$3<1/$C66,$D66*$C66,0))) | L66: =IF($B66="","",IF($C66=0,0,IF(L$3-$E$3<1/$C66,$D66*$C66,0))) | M66: =IF($B66="","",IF($C66=0,0,IF(M$3-$E$3<1/$C66,$D66*$C66,0))) | N66: =IF($B66="","",IF($C66=0,0,IF(N$3-$E$3<1/$C66,$D66*$C66,0))) | O66: =IF($B66="","",D66-SUM(E66:N66))
A67: 5 | B67: =IF(Faturas!C68=0,"",Faturas!C68) | C67: 0 | D67: =IF(Faturas!E68=0,"",Faturas!E68) | K67: =IF($B67="","",IF($C67=0,0,IF(K$3-$E$3<1/$C67,$D67*$C67,0))) | L67: =IF($B67="","",IF($C67=0,0,IF(L$3-$E$3<1/$C67,$D67*$C67,0))) | M67: =IF($B67="","",IF($C67=0,0,IF(M$3-$E$3<1/$C67,$D67*$C67,0))) | N67: =IF($B67="","",IF($C67=0,0,IF(N$3-$E$3<1/$C67,$D67*$C67,0))) | O67: =IF($B67="","",D67-SUM(E67:N67))
...

Sheet Relatório
B2: Pré-Projeto | AB2: Vendas | AC2: Portugal
B3: Ano | C3: VN Total | D3: VN Nacional | E3: VN Internacional | F3: % IE | I3: Atividade económica por mercado (volume de negócios) | AB3: Compras | AC3: Afeganistão
B4: =Pressupostos!C10 -> 2018 | C4: =SUMIF(DR!D4:F5,Relatório!B4,DR!D6:F6) -> 0 | E4: =C4-D4 -> 0 | F4: =(C4-D4)/C4 -> #DIV/0! | AC4: África do Sul
I5: Tipo | J5: Bem / Serviço | K5: Mercado (País) | L5: Ano Pré-Projeto | N5: Ano Pós-Projeto | AB5: Transportes marítimos | AC5: Albânia
B6: Total Investimento | C6: =Faturas!E285 -> 93765.25 | L6: Quant. | M6: Valor | N6: Quant. | O6: Valor | AB6: Transportes aéreos | AC6: Alemanha
B7: VN Pós Projeto | C7: =C15 -> 4401123.4 | M7: =C18 -> 0 | O7: =G18 -> 4401123.4 | AB7: Transportes rodoviários | AC7: Andorra
B8: VN Pós Projeto (mínimo) | C8: =C4+(C6*1.1)/C10 -> #DIV/0! | M8: =C19 -> 0 | O8: =G19 -> #DIV/0! | AB8: Outros transportes | AC8: Angola
B9: Diferença | C9: =C7-C8 -> #DIV/0! | M9: =C20 -> 0 | O9: =G20 -> #DIV/0! | AB9: Fretes de mercadorias | AC9: Anguila
B10: % IE Pós-Projeto (prevista) | M10: =C21 -> 0 | O10: =G21 -> #DIV/0! | AB10: Passagens | AC10: Antárctica
B11: Pós Projeto: VN Intern. Mínimo | C11: =E4+C6 -> 93765.25 | M11: =C22 -> 0 | O11: =G22 -> #DIV/0! | AB11: Outros serviços de transporte | AC11: Antígua e Barbuda
M12: =C23 -> 0 | O12: =G23 -> #DIV/0! | AB12: Viagens e turismo | AC12: Antilhas Holandesas
B13: Pós-Projeto | M13: =C24 -> 0 | O13: =G24 -> #DIV/0! | AB13: Serviços de comunicação | AC13: Arábia Saudita
B14: Ano | C14: VN Total | D14: VN Nacional | E14: VN Internacional | F14: % IE | M14: =C25 -> 0 | O14: =G25 -> #DIV/0! | AB14: Serviços de construção | AC14: Argélia
B15: =Pressupostos!C13 -> 2023 | C15: =SUMIF('DR Empresa'!C4:L4,B15,'DR Empresa'!C5:L5) -> 4401123.4 | D15: =C15-E15 -> 4401123.4 | E15: =C15*F15 -> 0 | F15: =C10 -> 0 | AB15: Seguros | AC15: Argentina
AB16: Serviços financeiros | AC16: Arménia
B17: Países | C17: VN Pré-Projeto | D17: € Invest. | E17: % Invest. | F17: VN Pós-Projeto indicativo | G17: VN Pós-Projeto efetivo | AB17: Serviços de informação e informática | AC17: Aruba
B18: Portugal | C18: =D4 -> 0 | D18: 0 | F18: =D15 -> 4401123.4 | G18: =F18 -> 4401123.4 | AB18: Serviços de intermediação comercial | AC18: Austrália
E19: =D19/$D$31 -> #DIV/0! | F19: =$E$15*E19 -> #DIV/0! | G19: =F19 -> #DIV/0! | AB19: Serviços de aluguer sem tripulação | AC19: Áustria
E20: =D20/$D$31 -> #DIV/0! | F20: =$E$15*E20 -> #DIV/0! | G20: =F20 -> #DIV/0! | AB20: Serviços agrícolas, mineiros e industriais | AC20: Azerbaijão
E21: =D21/$D$31 -> #DIV/0! | F21: =$E$15*E21 -> #DIV/0! | G21: =F21 -> #DIV/0! | AB21: Serviços de investigação e desenvolvimento | AC21: Bahamas
E22: =D22/$D$31 -> #DIV/0! | F22: =$E$15*E22 -> #DIV/0! | G22: =F22 -> #DIV/0! | AB22: Serv. jurídicos, contab. e consult. em gestão e de relações públicas | AC22: Bangladesh
E23: =D23/$D$31 -> #DIV/0! | F23: =$E$15*E23 -> #DIV/0! | G23: =F23 -> #DIV/0! | AB23: Serviços de arquitetura, de engenharia e de consultadoria técnica | AC23: Barbados
E24: =D24/$D$31 -> #DIV/0! | F24: =$E$15*E24 -> #DIV/0! | G24: =F24 -> #DIV/0! | AB24: Serviços de publicidade, estudos de mercado e de opinião pública | AC24: Barém
E25: =D25/$D$31 -> #DIV/0! | F25: =$E$15*E25 -> #DIV/0! | G25: =F25 -> #DIV/0! | AB25: Serviços entre empresas afiliadas | AC25: Bélgica
E26: =D26/$D$31 -> #DIV/0! | F26: =$E$15*E26 -> #DIV/0! | G26: =F26 -> #DIV/0! | AB26: Outros serviços fornecidos por empresas | AC26: Belize
E27: =D27/$D$31 -> #DIV/0! | F27: =$E$15*E27 -> #DIV/0! | G27: =F27 -> #DIV/0! | AB27: Direitos de utilização | AC27: Benim
E28: =D28/$D$31 -> #DIV/0! | F28: =$E$15*E28 -> #DIV/0! | G28: =F28 -> #DIV/0! | AB28: Serviços de natureza pessoal, cultural e recreativa | AC28: Bermudas
E29: =D29/$D$31 -> #DIV/0! | F29: =$E$15*E29 -> #DIV/0! | G29: =F29 -> #DIV/0! | AB29: Operações governamentais | AC29: Bielorrússia
E30: =D30/$D$31 -> #DIV/0! | F30: =$E$15*E30 -> #DIV/0! | G30: =F30 -> #DIV/0! | AB30: 01 - Animais vivos | AC30: Bolívia, Estado Plurinacional da
C31: =SUM(C18:C30) -> 0 | D31: =SUM(D19:D30) -> 0 | E31: =SUM(E19:E30) -> #DIV/0! | F31: =SUM(F18:F30) -> #DIV/0! | G31: =SUM(G18:G30) -> #DIV/0! | AB31: 02 - Carnes e miudezas, comestíveis | AC31: Bósnia-Herzegovina
F32: =F31-G31 -> #DIV/0! | M32: =SUM(M8:M31) -> 0 | O32: =SUM(O8:O31) -> #DIV/0! | AB32: 03 - Peixes e crustáceos, moluscos e outros invertebrados aquáticos | AC32: Botswana
AB33: 04 - Leite e lacticínios; ovos de aves; mel natural; produtos comestíveis de origem animal, não especificados nem compreendidos noutros capítulos | AC33: Brasil
AB34: 05 - Outros produtos de origem animal, não especificados nem compreendidos noutros capítulos | AC34: Brunei Darussalam
AB35: 06 - Plantas vivas e produtos de floricultura | AC35: Bulgária
AB36: 07 - Produtos hortícolas, plantas, raízes e tubérculos, comestíveis | AC36: Burkina Faso
AB37: 08 - Frutas; cascas de citrinos e de melões | AC37: Burundi
AB38: 09 - Café, chá, mate e especiarias | AC38: Butão
AB39: 10 - Cereais | AC39: Cabo Verde
AB40: 11 - Produtos da indústria de moagem; malte; amidos e féculas; inulina; glúten de trigo | AC40: Camarões
AB41: 12 - Sementes e frutos oleaginosos; grãos, sementes e frutos diversos; plantas industriais ou medicinais; palhas e forragens | AC41: Camboja
...

Sheet DR_Form
A1: DR Formulário Original
B2: =C2-1 -> 2017 | C2: =D2-1 -> 2018 | D2: =E2-1 -> 2019 | E2: =Pressupostos!C11 -> 2020 | F2: =E2+1 -> 2021 | G2: =F2+1 -> 2022 | H2: =G2+1 -> 2023 | I2: =H2+1 -> 2024 | J2: =I2+1 -> 2025 | K2: =J2+1 -> 2026 | L2: =K2+1 -> 2027
A3: Vendas e serviços prestados | B3: =DR!D6 -> 0 | C3: =DR!E6 -> 0 | D3: =DR!F6 -> 3479532.1 | E3: ='DR Empresa'!C5 -> 3690043.8 | F3: ='DR Empresa'!D5 -> 3913291.5 | G3: ='DR Empresa'!E5 -> 4150045.6 | H3: ='DR Empresa'!F5 -> 4401123.4 | I3: ='DR Empresa'!G5 -> 4489586 | J3: ='DR Empresa'!H5 -> 4579826.6 | K3: ='DR Empresa'!I5 -> 4671881.2 | L3: ='DR Empresa'!J5 -> 4765786
A4: Subsídios à exploração | B4: =DR!D7 -> 0 | C4: =DR!E7 -> 0 | D4: =DR!F7 -> 49.26 | E4: ='DR Empresa'!C6 -> 9281.3625 | F4: ='DR Empresa'!D6 -> 26253 | G4: ='DR Empresa'!E6 -> 6660 | H4: ='DR Empresa'!F6 -> 0 | I4: ='DR Empresa'!G6 -> 0 | J4: ='DR Empresa'!H6 -> 0 | K4: ='DR Empresa'!I6 -> 0 | L4: ='DR Empresa'!J6 -> 0
A5: Ganhos/perdas imputados de subsidiárias, associadas a empreendimentos conjuntos | B5: =DR!D8 -> 0 | C5: =DR!E8 -> 0 | D5: =DR!F8 -> 0 | E5: ='DR Empresa'!C7 -> 0 | F5: ='DR Empresa'!D7 -> 0 | G5: ='DR Empresa'!E7 -> 0 | H5: ='DR Empresa'!F7 -> 0 | I5: ='DR Empresa'!G7 -> 0 | J5: ='DR Empresa'!H7 -> 0 | K5: ='DR Empresa'!I7 -> 0 | L5: ='DR Empresa'!J7 -> 0
A6: Variação nos inventários da produção | B6: =DR!D9 -> 0 | C6: =DR!E9 -> 0 | D6: =DR!F9 -> 0 | E6: ='DR Empresa'!C8 -> 0 | F6: ='DR Empresa'!D8 -> 0 | G6: ='DR Empresa'!E8 -> 0 | H6: ='DR Empresa'!F8 -> 0 | I6: ='DR Empresa'!G8 -> 0 | J6: ='DR Empresa'!H8 -> 0 | K6: ='DR Empresa'!I8 -> 0 | L6: ='DR Empresa'!J8 -> 0
A7: Trabalhos para a própria entidade | B7: =DR!D10 -> 0 | C7: =DR!E10 -> 0 | D7: =DR!F10 -> 0 | E7: ='DR Empresa'!C9 -> 0 | F7: ='DR Empresa'!D9 -> 0 | G7: ='DR Empresa'!E9 -> 0 | H7: ='DR Empresa'!F9 -> 0 | I7: ='DR Empresa'!G9 -> 0 | J7: ='DR Empresa'!H9 -> 0 | K7: ='DR Empresa'!I9 -> 0 | L7: ='DR Empresa'!J9 -> 0
A8: Custo das mercadorias vendidas e das matérias consumidas | B8: =DR!D11 -> 0 | C8: =DR!E11 -> 0 | D8: =DR!F11 -> 2780591.1 | E8: ='DR Empresa'!C10 -> 2896684.4 | F8: ='DR Empresa'!D10 -> 3071933.8 | G8: ='DR Empresa'!E10 -> 3237035.6 | H8: ='DR Empresa'!F10 -> 3432876.2 | I8: ='DR Empresa'!G10 -> 3501877 | J8: ='DR Empresa'!H10 -> 3572264.8 | K8: ='DR Empresa'!I10 -> 3644067.3 | L8: ='DR Empresa'!J10 -> 3717313.1
A9: Fornecimentos e serviços externos | B9: =DR!D12 -> 0 | C9: =DR!E12 -> 0 | D9: =DR!F12 -> 506782.86 | E9: ='DR Empresa'!C11 -> 532475.94 | F9: ='DR Empresa'!D11 -> 546634.35 | G9: ='DR Empresa'!E11 -> 575056.16 | H9: ='DR Empresa'!F11 -> 594151.66 | I9: ='DR Empresa'!G11 -> 606094.1 | J9: ='DR Empresa'!H11 -> 618276.6 | K9: ='DR Empresa'!I11 -> 630703.96 | L9: ='DR Empresa'!J11 -> 643381.11
A10: Gastos com o pessoal | B10: =DR!D13 -> 0 | C10: =DR!E13 -> 0 | D10: =DR!F13 -> 169363.3 | E10: ='DR Empresa'!C12 -> 218097.59 | F10: ='DR Empresa'!D12 -> 254274.54 | G10: ='DR Empresa'!E12 -> 269965.03 | H10: ='DR Empresa'!F12 -> 275364.33 | I10: ='DR Empresa'!G12 -> 280871.62 | J10: ='DR Empresa'!H12 -> 286489.05 | K10: ='DR Empresa'!I12 -> 292218.83 | L10: ='DR Empresa'!J12 -> 298063.21
A11: Imparidade de inventários (perdas/reversões) | B11: =DR!D14 -> 0 | C11: =DR!E14 -> 0 | D11: =DR!F14 -> 0 | E11: ='DR Empresa'!C13 -> 0 | F11: ='DR Empresa'!D13 -> 0 | G11: ='DR Empresa'!E13 -> 0 | H11: ='DR Empresa'!F13 -> 0 | I11: ='DR Empresa'!G13 -> 0 | J11: ='DR Empresa'!H13 -> 0 | K11: ='DR Empresa'!I13 -> 0 | L11: ='DR Empresa'!J13 -> 0
A12: Imparidade de dívidas a receber (perdas/reversões) | B12: =DR!D15 -> 0 | C12: =DR!E15 -> 0 | D12: =DR!F15 -> 40.26 | E12: ='DR Empresa'!C14 -> 0 | F12: ='DR Empresa'!D14 -> 0 | G12: ='DR Empresa'!E14 -> 0 | H12: ='DR Empresa'!F14 -> 0 | I12: ='DR Empresa'!G14 -> 0 | J12: ='DR Empresa'!H14 -> 0 | K12: ='DR Empresa'!I14 -> 0 | L12: ='DR Empresa'!J14 -> 0
A13: Provisões (aumentos/reduções) | B13: =DR!D16 -> 0 | C13: =DR!E16 -> 0 | D13: =DR!F16 -> 0 | E13: ='DR Empresa'!C15 -> 0 | F13: ='DR Empresa'!D15 -> 0 | G13: ='DR Empresa'!E15 -> 0 | H13: ='DR Empresa'!F15 -> 0 | I13: ='DR Empresa'!G15 -> 0 | J13: ='DR Empresa'!H15 -> 0 | K13: ='DR Empresa'!I15 -> 0 | L13: ='DR Empresa'!J15 -> 0
A14: Imparidade de investimentos não depreciáveis/amortizáveis (perdas/reversões) | B14: =DR!D17 -> 0 | C14: =DR!E17 -> 0 | D14: =DR!F17 -> 0 | E14: ='DR Empresa'!C16 -> 0 | F14: ='DR Empresa'!D16 -> 0 | G14: ='DR Empresa'!E16 -> 0 | H14: ='DR Empresa'!F16 -> 0 | I14: ='DR Empresa'!G16 -> 0 | J14: ='DR Empresa'!H16 -> 0 | K14: ='DR Empresa'!I16 -> 0 | L14: ='DR Empresa'!J16 -> 0
... A16: Aumentos/reduções de justo valor | B16: =DR!D19 -> 0 | C16: =DR!E19 -> 0 | D16: =DR!F19 -> 0 | E16: ='DR Empresa'!C18 -> 0 | F16: ='DR Empresa'!D18 -> 0 | G16: ='DR Empresa'!E18 -> 0 | H16: ='DR Empresa'!F18 -> 0 | I16: ='DR Empresa'!G18 -> 0 | J16: ='DR Empresa'!H18 -> 0 | K16: ='DR Empresa'!I18 -> 0 | L16: ='DR Empresa'!J18 -> 0
A17: Outros rendimentos e ganhos
A18: Rendimentos suplementares
A19: Outros | B19: =DR!D20 -> 0 | C19: =DR!E20 -> 0 | D19: =DR!F20 -> 73417.34 | E19: ='DR Empresa'!C19 -> 0 | F19: ='DR Empresa'!D19 -> 27195.75 | G19: ='DR Empresa'!E19 -> 12616.875 | H19: ='DR Empresa'!F19 -> 3262.5 | I19: ='DR Empresa'!G19 -> 3262.5 | J19: ='DR Empresa'!H19 -> 0 | K19: ='DR Empresa'!I19 -> 0 | L19: ='DR Empresa'!J19 -> 0
A20: Outros gastos e perdas
