Workbook
Name a: #REF!
Name a: #REF!
Name ddd: #N/A
Name h: #REF!,#REF!
Name h: #REF!,#REF!
Name INDIC_ECOFIN: #REF!
Name INDIC_ECOFIN: #REF!

Sheet Índice

Sheet Pressupostos
C2: 2019 | D2: =+C2+1 -> 2020 | E2: =+D2+1 -> 2021 | F2: =+E2+1 -> 2022 | G2: =+F2+1 -> 2023 | H2: =+G2+1 -> 2024 | I2: =+H2+1 -> 2025 | J2: =+I2+1 -> 2026 | K2: =+J2+1 -> 2027 | ... Q2: =+P2+1 -> 2033
A3: Inflação | C3: 0.011 | D3: =+C3 -> 0.011 | E3: =+D3 -> 0.011 | F3: =+E3 -> 0.011 | G3: 0.055 | H3: 0.032 | I3: 0.021 | J3: 0.01 | K3: =+J3 -> 0.01 | L3: =+K3 -> 0.01 | M3: =+L3 -> 0.01 | N3: =+M3 -> 0.01 | O3: =+N3 -> 0.01 | P3: =+O3 -> 0.01 | Q3: =+P3 -> 0.01
A4: Índice Acumulado Inflação | C4: 1 | D4: =+C4*(1+D3) -> 1.011 | E4: =+D4*(1+E3) -> 1.022121 | F4: =+E4*(1+F3) -> 1.0333643 | G4: =+F4*(1+G3) -> 1.0901994 | H4: =+G4*(1+H3) -> 1.1250857 | I4: =+H4*(1+I3) -> 1.1487125 | J4: =+I4*(1+J3) -> 1.1601997 | K4: =+J4*(1+K3) -> 1.1718017 | ... Q4: =+P4*(1+Q3) -> 1.2438911
A6: Descrição
A7: Unidade monetária | B7: Euros
A8: 1º Ano actividade | B8: 2019
A10: Descrição
A11: Prazo médio de Recebimento (dias) | B11: 30
A12: Prazo médio de Pagamento (dias) | B12: 30
A13: Prazo médio de Stock (dias) | B13: 30
A14: Prazo Médio EOEP | B14: 30
A16: Descrição
A17: Taxa de IVA - Prestação Serviços | B17: 0.06
A18: Taxa de IVA - CMVMC | B18: 0.23
A19: Taxa de IVA - FSE | B19: 0.23
A20: Taxa de IVA - Investimento | B20: 0.23
A22: Descrição
A23: TSU - Entidade - órgãos sociais | B23: 0.2375
A24: TSU- Entidade - colaboradores | B24: 0.2375
A25: TSU - Pessoal - órgãos sociais | B25: 0.11
A26: TSU - Pessoal - colaboradores | B26: 0.11
A27: Taxa de IRC | B27: 0.21
A30: Índice

Sheet Previsão Receitas
A1: Descrição | B1: 2021 | C1: =+B1+1 -> 2022 | D1: =+C1+1 -> 2023 | E1: =+D1+1 -> 2024 | F1: =+E1+1 -> 2025 | G1: =+F1+1 -> 2026 | H1: =+G1+1 -> 2027 | I1: =+H1+1 -> 2028 | J1: =+I1+1 -> 2029 | ... L1: =+K1+1 -> 2031
B3: 7613376.1 | C3: 5617198 | D3: =+C3*1.05 -> 5898057.9 | E3: =+D3*1.1 -> 6487863.6 | F3: =+E3*1.05 -> 6812256.8 | G3: =+F3*1.15 -> 7834095.3 | H3: =+G3*1.1 -> 8617504.9 | I3: =+H3*1.1 -> 9479255.4 | J3: =+I3*1.1 -> 10427181 | K3: =+J3*1.1 -> 11469899 | L3: =+K3*1.1 -> 12616889
D4: =+C4*1.35 -> 0 | E4: =+D4*1.3 -> 0 | F4: =+E4*1.1 -> 0 | G4: =+F4*1.1 -> 0 | H4: =+G4*1.1 -> 0 | I4: =+H4*1.1 -> 0 | J4: =+I4*1.1 -> 0 | K4: =+J4*1.1 -> 0 | L4: =+K4*1.1 -> 0
D5: =+C5*1.35 -> 0 | E5: =+D5*1.3 -> 0 | F5: =+E5*1.2 -> 0 | G5: =+F5*1.1 -> 0 | H5: =+G5*1.1 -> 0 | I5: =+H5*1.1 -> 0 | J5: =+I5*1.1 -> 0 | K5: =+J5*1.1 -> 0 | L5: =+K5*1.1 -> 0
A8: TOTAL | B8: =SUM(B2:B7) -> 7613376.1 | C8: =SUM(C2:C7) -> 5617198 | D8: =SUM(D2:D7) -> 5898057.9 | E8: =SUM(E2:E7) -> 6487863.6 | F8: =SUM(F2:F7) -> 6812256.8 | G8: =SUM(G2:G7) -> 7834095.3 | H8: =SUM(H2:H7) -> 8617504.9 | I8: =SUM(I2:I7) -> 9479255.4 | ... L8: =SUM(L2:L7) -> 12616889
A11: VOLUME DE NEGÓCIOS POR MERCADO 2022
A12: Mercado Nacional | B12: 0.73 | E12: =+$F$8*B12 -> 4972947.5
A13: Eslóvenia | B13: 0.02 | E13: =+$F$8*B13 -> 136245.14
A14: França | B14: 0.05 | E14: =+$F$8*B14 -> 340612.84
A15: Inglaterra | B15: 0.05 | E15: =+$F$8*B15 -> 340612.84
A16: Espanha | B16: 0.05 | E16: =+$F$8*B16 -> 340612.84
A17: Alemanha | B17: 0.05 | E17: =+$F$8*B17 -> 340612.84
A18: Dinamarca | B18: 0.05 | E18: =+$F$8*B18 -> 340612.84
B19: =SUM(B12:B18) -> 1 | E19: =SUM(E12:E18) -> 6812256.8
B24: =100-27 -> 73

Sheet Fornecimento  Serviços Externos
A1: FSE´s PROJETO | B1: Valor Mês | C1: 2021 | D1: =+C1+1 -> 2022 | E1: =+D1+1 -> 2023 | F1: =+E1+1 -> 2024 | G1: =+F1+1 -> 2025 | H1: =+G1+1 -> 2026 | I1: =+H1+1 -> 2027 | J1: =+I1+1 -> 2028 | K1: =+J1+1 -> 2029 | ... M1: =+L1+1 -> 2031
B2: 1100 | E2: ='Previsão Receitas'!D8*0.23 -> 1356553.3 | F2: ='Previsão Receitas'!E8*0.23 -> 1492208.6 | G2: ='Previsão Receitas'!F8*0.22 -> 1498696.5 | H2: ='Previsão Receitas'!G8*0.21 -> 1645160 | I2: ='Previsão Receitas'!H8*0.2 -> 1723501 | J2: ='Previsão Receitas'!I8*0.15 -> 1421888.3 | K2: ='Previsão Receitas'!J8*0.15 -> 1564077.1 | L2: ='Previsão Receitas'!K8*0.15 -> 1720484.9 | M2: ='Previsão Receitas'!L8*0.15 -> 1892533.3
B3: 200 | E3: =+D3 -> 0 | F3: =+E3 -> 0 | G3: =+F3 -> 0 | H3: =+G3 -> 0 | I3: =+H3 -> 0 | J3: =+I3 -> 0 | K3: =+J3 -> 0 | L3: =+K3 -> 0 | M3: =+L3 -> 0
B4: 100 | E4: =+D4*E$13 -> 0 | F4: =+E4*F$13 -> 0 | G4: =+F4*G$13 -> 0 | H4: =+G4*H$13 -> 0 | I4: =+H4*I$13 -> 0 | J4: =+I4*J$13 -> 0 | K4: =+J4*K$13 -> 0 | L4: =+K4*L$13 -> 0 | M4: =+L4*M$13 -> 0
B5: 30 | E5: =+D5*E$13 -> 0 | F5: =+E5*F$13 -> 0 | G5: =+F5*G$13 -> 0 | H5: =+G5*H$13 -> 0 | I5: =+H5*I$13 -> 0 | J5: =+I5*J$13 -> 0 | K5: =+J5*K$13 -> 0 | L5: =+K5*L$13 -> 0 | M5: =+L5*M$13 -> 0
B6: 200 | E6: =+D6*E$13 -> 0 | F6: =+E6*F$13 -> 0 | G6: =+F6*G$13 -> 0 | H6: =+G6*H$13 -> 0 | I6: =+H6*I$13 -> 0 | J6: =+I6*J$13 -> 0 | K6: =+J6*K$13 -> 0 | L6: =+K6*L$13 -> 0 | M6: =+L6*M$13 -> 0
B7: 0 | E7: =+D7*E$13 -> 0 | F7: =+E7*F$13 -> 0 | G7: =+F7*G$13 -> 0 | H7: =+G7*H$13 -> 0 | I7: =+H7*I$13 -> 0 | J7: =+I7*J$13 -> 0 | K7: =+J7*K$13 -> 0 | L7: =+K7*L$13 -> 0 | M7: =+L7*M$13 -> 0
B8: 200 | E8: =+D8*E$13 -> 0 | F8: =+E8*F$13 -> 0 | G8: =+F8*G$13 -> 0 | H8: =+G8*H$13 -> 0 | I8: =+H8*I$13 -> 0 | J8: =+I8*J$13 -> 0 | K8: =+J8*K$13 -> 0 | L8: =+K8*L$13 -> 0 | M8: =+L8*M$13 -> 0
B9: 200 | E9: =+D9*E$14 -> 0 | F9: =+E9*F$14 -> 0 | G9: =+F9*G$14 -> 0 | H9: =+G9*H$14 -> 0 | I9: =+H9*I$14 -> 0 | J9: =+I9*J$14 -> 0 | K9: =+J9*K$14 -> 0 | L9: =+K9*L$14 -> 0 | M9: =+L9*M$14 -> 0
A10: 62- FSE´s Projeto | D10: ='MAPA INVESTIMENTOS'!B5 -> 0 | E10: ='MAPA INVESTIMENTOS'!C5 -> 2500 | F10: ='MAPA INVESTIMENTOS'!D5 -> 2500
C12: 1180801.4 | D12: 1309346.9 | E12: =SUM(E2:E11) -> 1359053.3 | F12: =SUM(F2:F11) -> 1494708.6 | G12: =SUM(G2:G11) -> 1498696.5 | H12: =SUM(H2:H11) -> 1645160 | I12: =SUM(I2:I11) -> 1723501 | J12: =SUM(J2:J11) -> 1421888.3 | K12: =SUM(K2:K11) -> 1564077.1 | L12: =SUM(L2:L11) -> 1720484.9 | M12: =SUM(M2:M11) -> 1892533.3
A13: Serviços especializados e RH related | D13: 1.05 | E13: 1.05 | F13: 1.05 | G13: 1.05 | H13: 1.05 | I13: 1.05 | J13: 1.05 | K13: 1.05 | L13: 1.05 | M13: 1.05
A14: Outros Serviços | D14: 1.1 | E14: 1.1 | F14: 1.1 | G14: 1.1 | H14: 1.1 | I14: 1.1 | J14: 1.1 | K14: 1.1 | L14: 1.1 | M14: 1.1
D17: 7613376.1 | E17: =C12*100/D17 -> 15.509563 | F17: 2021
D18: 5617198 | E18: =D12*100/D18 -> 23.309609 | F18: 2022

Sheet Capital Circulante
B1: 2021 | C1: =+B1+1 -> 2022 | D1: =+C1+1 -> 2023 | E1: =+D1+1 -> 2024 | F1: =+E1+1 -> 2025 | G1: =+F1+1 -> 2026 | H1: =+G1+1 -> 2027 | I1: =+H1+1 -> 2028 | J1: =+I1+1 -> 2029 | ... L1: =+K1+1 -> 2031
A2: Necessidades Financeiras de Exploração | B2: =SUM(B3:B4) -> 1047493.5 | C2: =SUM(C3:C4) -> 764261.13 | D2: =SUM(D3:D4) -> 737257.23 | E2: =SUM(E3:E4) -> 810982.96 | F2: =SUM(F3:F4) -> 851532.1 | G2: =SUM(G3:G4) -> 979261.92 | H2: =SUM(H3:H4) -> 1077188.1 | I2: =SUM(I3:I4) -> 1184906.9 | ... L2: =SUM(L3:L4) -> 1577111.1
A3: Clientes | B3: =+'Previsão Receitas'!B8/360*Pressupostos!$B$11 -> 634448 | C3: =+'Previsão Receitas'!C8/360*Pressupostos!$B$11 -> 468099.83 | D3: =+'Previsão Receitas'!D8/360*Pressupostos!$B$11 -> 491504.82 | E3: =+'Previsão Receitas'!E8/360*Pressupostos!$B$11 -> 540655.3 | F3: =+'Previsão Receitas'!F8/360*Pressupostos!$B$11 -> 567688.07 | G3: =+'Previsão Receitas'!G8/360*Pressupostos!$B$11 -> 652841.28 | H3: =+'Previsão Receitas'!H8/360*Pressupostos!$B$11 -> 718125.41 | I3: =+'Previsão Receitas'!I8/360*Pressupostos!$B$11 -> 789937.95 | ... L3: =+'Previsão Receitas'!L8/360*Pressupostos!$B$11 -> 1051407.4
A4: Existências | B4: =B13/360*Pressupostos!$B$13 -> 413045.47 | C4: =C13/360*Pressupostos!$B$13 -> 296161.3 | D4: =D13/360*Pressupostos!$B$13 -> 245752.41 | E4: =E13/360*Pressupostos!$B$13 -> 270327.65 | F4: =F13/360*Pressupostos!$B$13 -> 283844.03 | G4: =G13/360*Pressupostos!$B$13 -> 326420.64 | H4: =H13/360*Pressupostos!$B$13 -> 359062.7 | I4: =I13/360*Pressupostos!$B$13 -> 394968.97 | ... L4: =L13/360*Pressupostos!$B$13 -> 525703.7
A5: Recursos Financeiros de Exploração | B5: =SUM(B6:B6) -> 511445.58 | C5: =SUM(C6:C6) -> 405273.54 | D5: =SUM(D6:D6) -> 359006.85 | E5: =SUM(E6:E6) -> 394886.7 | F5: =SUM(F6:F6) -> 408735.41 | G5: =SUM(G6:G6) -> 463517.31 | H5: =SUM(H6:H6) -> 502687.78 | I5: =SUM(I6:I6) -> 513459.67 | ... L5: =SUM(L6:L6) -> 683414.82
A6: Fornecedores | B6: =(+'Fornecimento Serviços Externos'!C12+'Capital Circulante'!B18)/360*Pressupostos!$B$12 -> 511445.58 | C6: =(+'Fornecimento Serviços Externos'!D12+'Capital Circulante'!C18)/360*Pressupostos!$B$12 -> 405273.54 | D6: =(+'Fornecimento Serviços Externos'!E12+'Capital Circulante'!D18)/360*Pressupostos!$B$12 -> 359006.85 | E6: =(+'Fornecimento Serviços Externos'!F12+'Capital Circulante'!E18)/360*Pressupostos!$B$12 -> 394886.7 | F6: =(+'Fornecimento Serviços Externos'!G12+'Capital Circulante'!F18)/360*Pressupostos!$B$12 -> 408735.41 | G6: =(+'Fornecimento Serviços Externos'!H12+'Capital Circulante'!G18)/360*Pressupostos!$B$12 -> 463517.31 | H6: =(+'Fornecimento Serviços Externos'!I12+'Capital Circulante'!H18)/360*Pressupostos!$B$12 -> 502687.78 | I6: =(+'Fornecimento Serviços Externos'!J12+'Capital Circulante'!I18)/360*Pressupostos!$B$12 -> 513459.67 | ... L6: =(+'Fornecimento Serviços Externos'!M12+'Capital Circulante'!L18)/360*Pressupostos!$B$12 -> 683414.82
A7: Fundo Maneio | B7: =B2-B5 -> 536047.89 | C7: =C2-C5 -> 358987.59 | D7: =D2-D5 -> 378250.38 | E7: =E2-E5 -> 416096.25 | F7: =F2-F5 -> 442796.69 | G7: =G2-G5 -> 515744.61 | H7: =H2-H5 -> 574500.33 | I7: =I2-I5 -> 671447.26 | ... L7: =L2-L5 -> 893696.3
A8: Variação Fundo Maneio | B8: =B7 -> 536047.89 | C8: =+C7-B8 -> -177060.3 | D8: =+D7-C7 -> 19262.788 | E8: =+E7-D7 -> 37845.871 | F8: =+F7-E7 -> 26700.443 | G8: =+G7-F7 -> 72947.917 | H8: =+H7-G7 -> 58755.715 | I8: =+I7-H7 -> 96946.93 | J8: =+J7-I7 -> 67144.726 | K8: =+K7-J7 -> 73859.198 | L8: =+L7-K7 -> 81245.118
A10: Mapa das Compras
B12: 2021 | C12: =+B12+1 -> 2022 | D12: =+C12+1 -> 2023 | E12: =+D12+1 -> 2024 | F12: =+E12+1 -> 2025 | G12: =+F12+1 -> 2026 | H12: =+G12+1 -> 2027 | I12: =+H12+1 -> 2028 | J12: =+I12+1 -> 2029 | ... L12: =+K12+1 -> 2031
A13: CMVMC | B13: =+B18 -> 4956545.6 | C13: =+C18 -> 3553935.6 | D13: =+D18 -> 2949028.9 | E13: =+E18 -> 3243931.8 | F13: =+F18 -> 3406128.4 | G13: =+G18 -> 3917047.7 | H13: =+H18 -> 4308752.4 | I13: =+I18 -> 4739627.7 | ... L13: =+L18 -> 6308444.5
A14: + Existências Finais | B14: 0 | C14: 0 | D14: 0 | E14: 0 | F14: 0 | G14: 0 | H14: 0 | I14: 1 | J14: 2 | K14: 3 | L14: 4
A15: - Existências Iniciais | B15: 0 | C15: =B14 -> 0 | D15: =C14 -> 0 | E15: =D14 -> 0 | F15: =E14 -> 0 | G15: =F14 -> 0 | H15: =G14 -> 0 | I15: =H14 -> 0 | J15: =I14 -> 1 | ... L15: =K14 -> 3
A16: Compras | B16: =B13+B14-B15 -> 4956545.6 | C16: =C13+C14-C15 -> 3553935.6 | D16: =D13+D14-D15 -> 2949028.9 | E16: =E13+E14-E15 -> 3243931.8 | F16: =F13+F14-F15 -> 3406128.4 | G16: =G13+G14-G15 -> 3917047.7 | H16: =H13+H14-H15 -> 4308752.4 | I16: =I13+I14-I15 -> 4739628.7 | ... L16: =L13+L14-L15 -> 6308445.5
A18: CMVMC | B18: 4956545.6 | C18: 3553935.6 | D18: =+'Previsão Receitas'!D8*0.5 -> 2949028.9 | E18: =+'Previsão Receitas'!E8*0.5 -> 3243931.8 | F18: =+'Previsão Receitas'!F8*0.5 -> 3406128.4 | G18: =+'Previsão Receitas'!G8*0.5 -> 3917047.7 | H18: =+'Previsão Receitas'!H8*0.5 -> 4308752.4 | I18: =+'Previsão Receitas'!I8*0.5 -> 4739627.7 | J18: =+'Previsão Receitas'!J8*0.5 -> 5213590.5 | K18: =+'Previsão Receitas'!K8*0.5 -> 5734949.5 | L18: =+'Previsão Receitas'!L8*0.5 -> 6308444.5
A20: Índice

Sheet 63_G. Pess.
A1: Recursos Humanos | C1: Encargos Mensais pessoal | G1: Valor Ano
B2: N | C2: Vencimento Base | D2: Sub Almoço | E2: Encargos Sociais | F2: Total
A3: RECURSOS HUMANOS ATUAIS | B3: 38 | C3: 1000 | D3: =4.77*22 -> 104.94 | E3: =+C3*0.2375 -> 237.5 | F3: =+C3+E3+D3 -> 1342.44 | G3: =+F3*14*B3 -> 714178.08
A4: Eng Telecom | B4: 3 | C4: 1200 | D4: 104.94 | E4: =+C4*0.2375 -> 285 | F4: =+C4+E4+D4 -> 1589.94 | G4: =+F4*14*B4 -> 66777.48
A5: Tecnico | B5: 1 | C5: 850 | D5: 104.94 | E5: =+C5*0.2375 -> 201.875 | F5: =+C5+E5+D5 -> 1156.815 | G5: =+F5*14*B5 -> 16195.41 | H5: =+F5*14 -> 16195.41
A6: Tecnico | B6: 1 | C6: 850 | D6: 104.94 | E6: =+C6*0.2375 -> 201.875 | F6: =+C6+E6+D6 -> 1156.815 | G6: =+F6*14*B6 -> 16195.41
E7: =+C7*0.2375 -> 0 | F7: =+C7+E7+D7 -> 0
A11: TOTAL € | B11: =SUM(B3:B10) -> 43 | C11: =SUM(C3:C10) -> 3900 | D11: =SUM(D3:D10) -> 419.76 | E11: =SUM(E3:E10) -> 926.25 | F11: =SUM(F3:F3) -> 1342.44 | G11: =SUM(G3:G10) -> 813346.38
C14: 2021 | D14: =+C14+1 -> 2022 | E14: =+D14+1 -> 2023 | F14: =+E14+1 -> 2024 | G14: =+F14+1 -> 2025 | H14: =+G14+1 -> 2026 | I14: =+H14+1 -> 2027 | J14: =+I14+1 -> 2028 | K14: =+J14+1 -> 2029 | ... M14: =+L14+1 -> 2031
A15: Encargos Totais Com o Pessoal | C15: 731846.19 | D15: 1081626.9 | E15: =D15+G4+G5+G6 -> 1180795.2 | F15: =E15+G4+G5+G6 -> 1279963.5 | G15: =F15+H4+H5+H6 -> 1296158.9 | H15: =$G$15 -> 1296158.9 | I15: =$G$15 -> 1296158.9 | J15: =$G$15 -> 1296158.9 | K15: =$G$15 -> 1296158.9 | L15: =$G$15 -> 1296158.9 | M15: =$G$15 -> 1296158.9
A19: Índice

Sheet Amortizações
A1: Investimento | K1: Mapa Amortizações
A2: Nº | B2: DESIGNAÇÃO | C2: 2022 | D2: 2023 | E2: =+D2+1 -> 2024 | F2: =+E2+1 -> 2025 | G2: =+F2+1 -> 2026 | H2: =+G2+1 -> 2027 | I2: =+H2+1 -> 2028 | J2: =+I2+1 -> 2029 | K2: % | L2: 2022 | M2: =+L2+1 -> 2023 | N2: =+M2+1 -> 2024 | O2: =+N2+1 -> 2025 | P2: =+O2+1 -> 2026 | Q2: =+P2+1 -> 2027 | R2: =+Q2+1 -> 2028 | S2: =+R2+1 -> 2029 | T2: =+S2+1 -> 2030 | ... V2: =+U2+1 -> 2032
A4: ATIVO TANGÍVEL
B5: TOTAL | C5: =SUM(C6:C16) -> 127161.6 | D5: =SUM(D6:D16) -> 615244.79 | E5: =SUM(E6:E16) -> 2500 | F5: =SUM(F6:F16) -> 0 | G5: =SUM(G6:G16) -> 0 | H5: =SUM(H6:H16) -> 0 | I5: =SUM(I6:I16) -> 0 | J5: =SUM(J6:J16) -> 0
B6: ='MAPA INVESTIMENTOS'!A2 -> Equipamento Básico | C6: ='MAPA INVESTIMENTOS'!B2 -> 21917.5 | D6: ='MAPA INVESTIMENTOS'!C2 -> 240669.44 | E6: ='MAPA INVESTIMENTOS'!D2 -> 0 | F6: ='MAPA INVESTIMENTOS'!E2 -> 0 | G6: ='MAPA INVESTIMENTOS'!F2 -> 0 | H6: ='MAPA INVESTIMENTOS'!G2 -> 0 | I6: ='MAPA INVESTIMENTOS'!H2 -> 0 | J6: ='MAPA INVESTIMENTOS'!I2 -> 0 | K6: 0.2 | L6: 0 | M6: =C6*K6 -> 4383.5 | N6: =+C6*K6 -> 4383.5 | O6: =(+$C$6*$K$6)+($D$6*$K$6) -> 52517.388 | P6: =(+$C$6*$K$6)+($D$6*$K$6) -> 52517.388 | Q6: =(+$C$6*$K$6)+($D$6*$K$6) -> 52517.388 | R6: =+($D$6*$K$6) -> 48133.888
B7: ='MAPA INVESTIMENTOS'!A3 -> Obras | C7: ='MAPA INVESTIMENTOS'!B3 -> 38875 | D7: ='MAPA INVESTIMENTOS'!C3 -> 181449 | E7: ='MAPA INVESTIMENTOS'!D3 -> 0 | F7: ='MAPA INVESTIMENTOS'!E3 -> 0 | G7: ='MAPA INVESTIMENTOS'!F3 -> 0 | H7: ='MAPA INVESTIMENTOS'!G3 -> 0 | I7: ='MAPA INVESTIMENTOS'!H3 -> 0 | J7: ='MAPA INVESTIMENTOS'!I3 -> 0 | K7: 0.02 | M7: =$C$7*$K$7 -> 777.5 | N7: =$C$7*$K$7 -> 777.5 | O7: =($C$7*$K$7)+($D$7*$K$7) -> 4406.48 | P7: =($C$7*$K$7)+($D$7*$K$7) -> 4406.48 | Q7: =($C$7*$K$7)+($D$7*$K$7) -> 4406.48 | R7: =($C$7*$K$7)+($D$7*$K$7) -> 4406.48 | S7: =($C$7*$K$7)+($D$7*$K$7) -> 4406.48 | T7: =($C$7*$K$7)+($D$7*$K$7) -> 4406.48 | U7: =($C$7*$K$7)+($D$7*$K$7) -> 4406.48 | V7: =($C$7*$K$7)+($D$7*$K$7) -> 4406.48
B8: ='MAPA INVESTIMENTOS'!A4 -> Máquinas | C8: ='MAPA INVESTIMENTOS'!B4 -> 63426 | D8: ='MAPA INVESTIMENTOS'!C4 -> 179839 | E8: ='MAPA INVESTIMENTOS'!D4 -> 0 | F8: ='MAPA INVESTIMENTOS'!E4 -> 0 | G8: ='MAPA INVESTIMENTOS'!F4 -> 0 | H8: ='MAPA INVESTIMENTOS'!G4 -> 0 | I8: ='MAPA INVESTIMENTOS'!H4 -> 0 | J8: ='MAPA INVESTIMENTOS'!I4 -> 0 | K8: 0.2 | M8: =+$C$8*$K$8 -> 12685.2 | N8: =($C$8*$K$8)+($D$8*$K$8) -> 48653 | O8: =($C$8*$K$8)+($D$8*$K$8) -> 48653 | P8: =($C$8*$K$8)+($D$8*$K$8) -> 48653 | Q8: =($C$8*$K$8)+($D$8*$K$8) -> 48653 | R8: =+$D$8*$K$8 -> 35967.8
B9: ='MAPA INVESTIMENTOS'!A5 -> Prestação de serviços | C9: ='MAPA INVESTIMENTOS'!B5 -> 0 | D9: ='MAPA INVESTIMENTOS'!C5 -> 2500 | E9: ='MAPA INVESTIMENTOS'!D5 -> 2500 | F9: ='MAPA INVESTIMENTOS'!E5 -> 0 | G9: ='MAPA INVESTIMENTOS'!F5 -> 0 | H9: ='MAPA INVESTIMENTOS'!G5 -> 0 | I9: ='MAPA INVESTIMENTOS'!H5 -> 0 | J9: ='MAPA INVESTIMENTOS'!I5 -> 0 | K9: 0 | M9: =+$C$9*$K$9 -> 0 | N9: =+$C$9*$K$9 -> 0 | O9: =+$C$9*$K$9 -> 0 | P9: =+$C$9*$K$9 -> 0 | Q9: =+$C$9*$K$9 -> 0 | R9: =+$C$9*$K$9 -> 0 | S9: =+$C$9*$K$9 -> 0 | T9: =+$C$9*$K$9 -> 0 | ... V9: =+$C$9*$K$9 -> 0
B10: ='MAPA INVESTIMENTOS'!A6 -> Ferramentas | C10: ='MAPA INVESTIMENTOS'!B6 -> 0 | D10: ='MAPA INVESTIMENTOS'!C6 -> 291.35 | E10: ='MAPA INVESTIMENTOS'!D6 -> 0 | F10: ='MAPA INVESTIMENTOS'!E6 -> 0 | G10: ='MAPA INVESTIMENTOS'!F6 -> 0 | H10: ='MAPA INVESTIMENTOS'!G6 -> 0 | I10: ='MAPA INVESTIMENTOS'!H6 -> 0 | J10: ='MAPA INVESTIMENTOS'!I6 -> 0 | K10: 0.2 | M10: =+$C$10*$K$10 -> 0 | N10: =+$C$10*$K$10 -> 0 | O10: =+$C$10*$K$10 -> 0 | P10: =+$C$10*$K$10 -> 0 | Q10: =+$C$10*$K$10 -> 0 | R10: =+$C$10*$K$10 -> 0 | S10: =+$C$10*$K$10 -> 0 | T10: =+$C$10*$K$10 -> 0 | ... V10: =+$C$10*$K$10 -> 0
B11: ='MAPA INVESTIMENTOS'!A7 -> Eq Informático | C11: ='MAPA INVESTIMENTOS'!B7 -> 2943.1 | D11: ='MAPA INVESTIMENTOS'!C7 -> 10496 | E11: ='MAPA INVESTIMENTOS'!D7 -> 0 | F11: ='MAPA INVESTIMENTOS'!E7 -> 0 | G11: ='MAPA INVESTIMENTOS'!F7 -> 0 | H11: ='MAPA INVESTIMENTOS'!G7 -> 0 | I11: ='MAPA INVESTIMENTOS'!H7 -> 0 | J11: ='MAPA INVESTIMENTOS'!I7 -> 0 | K11: 0.1 | M11: =+$C$11*$K$11 -> 294.31 | N11: =($C$11*$K$11)+($D$11*$K$11) -> 1343.91 | O11: =($C$11*$K$11)+($D$11*$K$11) -> 1343.91 | P11: =($C$11*$K$11)+($D$11*$K$11) -> 1343.91 | Q11: =($C$11*$K$11)+($D$11*$K$11) -> 1343.91 | R11: =+$D$11*$K$11 -> 1049.6
B12: ='MAPA INVESTIMENTOS'!A8 -> Software | C12: ='MAPA INVESTIMENTOS'!B8 -> 0 | D12: =+C12 -> 0 | E12: =+D12-M12 -> 0 | F12: =+E12-N12 -> 0 | G12: =+F12-O12 -> 0 | H12: =+G12-P12 -> 0 | I12: =+H12-Q12 -> 0 | J12: =+I12-R12 -> 0 | K12: 0 | M12: =+$C$12*$K$12 -> 0 | N12: =+$C$12*$K$12 -> 0 | O12: =+$C$12*$K$12 -> 0 | P12: =+$C$12*$K$12 -> 0 | Q12: =+$C$12*$K$12 -> 0 | R12: =+$C$12*$K$12 -> 0 | S12: =+$C$12*$K$12 -> 0 | T12: =+$C$12*$K$12 -> 0 | ... V12: =+$C$12*$K$12 -> 0
B13: =+'MAPA INVESTIMENTOS'!A9 -> 0 | C13: =+'MAPA INVESTIMENTOS'!B9 -> 0 | D13: =+C13 -> 0 | E13: =+D13-M13 -> 0 | F13: =+E13-N13 -> 0 | G13: =+F13-O13 -> 0 | H13: =+G13-P13 -> 0 | I13: =+H13-Q13 -> 0 | J13: =+I13-R13 -> 0 | K13: 0 | M13: =+$C$13*$K$13 -> 0 | N13: =+$C$13*$K$13 -> 0 | O13: =+$C$13*$K$13 -> 0 | P13: =+$C$13*$K$13 -> 0 | Q13: =+$C$13*$K$13 -> 0 | R13: =+$C$13*$K$13 -> 0 | S13: =+$C$13*$K$13 -> 0 | T13: =+$C$13*$K$13 -> 0 | ... V13: =+$C$13*$K$13 -> 0
B14: =+'MAPA INVESTIMENTOS'!A11 -> 0 | C14: =+'MAPA INVESTIMENTOS'!C11 -> 0 | E14: =+C14 -> 0 | F14: =+E14-N14 -> 0 | G14: =+F14-O14 -> 0 | H14: =+G14-P14 -> 0 | I14: =+H14-Q14 -> 0 | J14: =+I14-R14 -> 0 | K14: 0 | M14: 0 | N14: =+$C$14*$K$14 -> 0 | O14: =+$C$14*$K$14 -> 0 | P14: =+$C$14*$K$14 -> 0 | Q14: =+$C$14*$K$14 -> 0 | R14: =+$C$14*$K$14 -> 0 | S14: =+$C$14*$K$14 -> 0 | T14: =+$C$14*$K$14 -> 0 | U14: =+$C$14*$K$14 -> 0 | V14: =+$C$14*$K$14 -> 0
C15: =+'MAPA INVESTIMENTOS'!B12 -> 0
A17: ATIVO INTANGÍVEL
B18: TOTAL | C18: =SUM(C19:C20) -> 0 | D18: =SUM(D19:D20) -> 7706.9 | E18: =SUM(E19:E20) -> 0 | F18: =SUM(F19:F20) -> -2568.7098 | G18: =SUM(G19:G20) -> -5137.4195 | H18: =SUM(H19:H20) -> -7706.1293 | I18: =SUM(I19:I20) -> -10274.839 | J18: =SUM(J19:J20) -> -10274.839
B19: Software | C19: =+'MAPA INVESTIMENTOS'!C10 -> 0 | D19: ='MAPA INVESTIMENTOS'!C8 -> 7706.9 | E19: =+'MAPA INVESTIMENTOS'!C10 -> 0 | F19: =+C19-N19 -> -2568.7098 | G19: =+F19-N19 -> -5137.4195 | H19: =+G19-O19 -> -7706.1293 | I19: =+H19-P19 -> -10274.839 | J19: =+I19-Q19 -> -10274.839 | K19: 0.3333 | M19: 0 | N19: =$D$19*$K$19 -> 2568.7098 | O19: =$D$19*$K$19 -> 2568.7098 | P19: =$D$19*$K$19 -> 2568.7098 | Q19: =+$C$19*$K$19 -> 0 | R19: =+$C$19*$K$19 -> 0 | S19: =+$C$19*$K$19 -> 0 | T19: =+$C$19*$K$19 -> 0 | U19: =+$C$19*$K$19 -> 0 | V19: =+$C$19*$K$19 -> 0
C21: =+C18+C5 -> 127161.6 | D21: =D5+D18 -> 622951.69 | E21: =SUM(E19:E20) -> 0 | F21: =SUM(F19:F20) -> -2568.7098 | G21: =SUM(G19:G20) -> -5137.4195 | H21: =SUM(H19:H20) -> -7706.1293 | I21: =SUM(I19:I20) -> -10274.839 | L21: =SUM(L6:L20) -> 0 | M21: =SUM(M6:M20) -> 18140.51 | N21: =SUM(N6:N20) -> 57726.62 | O21: =SUM(O6:O20) -> 109489.49 | P21: =SUM(P6:P20) -> 109489.49 | Q21: =SUM(Q6:Q20) -> 106920.78 | R21: =SUM(R6:R20) -> 89557.768 | S21: =SUM(S6:S20) -> 4406.48 | ... V21: =SUM(V6:V20) -> 4406.48
A25: Índice

Sheet Serviço da Divida Emp. Bancario
A1: FINANCIAMENTO BANCO
A3: Rubricas | C3: 2021 | D3: =+C3+1 -> 2022 | E3: =+D3+1 -> 2023 | F3: =+E3+1 -> 2024 | G3: =+F3+1 -> 2025 | H3: =+G3+1 -> 2026 | I3: =+H3+1 -> 2027 | J3: =+I3+1 -> 2028 | K3: =+J3+1 -> 2029 | L3: =+K3+1 -> 2030
A5: Capital em dívida (início período) | B5: =+'MAPA INVESTIMENTOS'!E22 -> 451567.97 | C5: =+'MAPA INVESTIMENTOS'!B24 -> 0 | D5: =+C5+'MAPA INVESTIMENTOS'!C24 -> 0 | E5: 0 | F5: =B5 -> 451567.97 | G5: =+F8 -> 387058.26 | H5: =+G8 -> 322548.55 | I5: =+H8 -> 258038.84 | J5: =+I8 -> 193529.13 | K5: =+J8 -> 129019.42 | L5: =+K8 -> 64509.711
A6: Juro Anual | C6: =+C5*$B$10 -> 0 | D6: =+D5*$B$10 -> 0 | E6: 0 | F6: =+F5*$B$10 -> 20320.559 | G6: =+G5*$B$10 -> 17417.622 | H6: =+H5*$B$10 -> 14514.685 | I6: =+I5*$B$10 -> 11611.748 | J6: =+J5*$B$10 -> 8708.8109 | K6: =+K5*$B$10 -> 5805.874 | L6: =+L5*$B$10 -> 2902.937
A7: Reembolso Anual | C7: 0 | D7: 0 | E7: 0 | F7: =+$B$5/B12 -> 64509.711 | G7: =+$B$5/B12 -> 64509.711 | H7: =+$B$5/B12 -> 64509.711 | I7: =+$B$5/B12 -> 64509.711 | J7: =+$B$5/B12 -> 64509.711 | K7: =+$B$5/B12 -> 64509.711 | L7: =+$B$5/7 -> 64509.711
A8: Valor em dívida | C8: =+C5-C7 -> 0 | D8: =+D5-D7 -> 0 | E8: 0 | F8: =+F5-F7 -> 387058.26 | G8: =+G5-G7 -> 322548.55 | H8: =+H5-H7 -> 258038.84 | I8: =+I5-I7 -> 193529.13 | J8: =+J5-J7 -> 129019.42 | K8: =+K5-K7 -> 64509.711 | L8: =+L5-L7 -> -7.2759576e-11
A10: Taxa de juro associada | B10: 0.045
A12: Nº DE ANOS REEMBOLSO | B12: 7
A14: FINANCIAMENTO EXISTENTE NA EMPRESA
A16: Rubricas | C16: 2020 | D16: =+C16+1 -> 2021 | E16: =+D16+1 -> 2022 | F16: =+E16+1 -> 2023 | G16: =+F16+1 -> 2024 | H16: =+G16+1 -> 2025 | I16: =+H16+1 -> 2026 | J16: =+I16+1 -> 2027 | K16: =+J16+1 -> 2028 | L16: =+K16+1 -> 2029
A18: Capital em dívida (início período) | B18: 0 | C18: =+B18 -> 0 | D18: =+C21 -> 0 | E18: =+D21 -> 0 | F18: =+E21 -> 0 | G18: =+F21 -> 0 | H18: =+G21 -> 0 | I18: =+H21 -> 0 | J18: =+I21 -> 0 | K18: =+J21 -> 0 | L18: =+K21 -> 0
A19: Juro Anual | C19: =+C18*$B$23 -> 0 | D19: =+D18*$B$23 -> 0 | E19: =+E18*$B$23 -> 0 | F19: =+F18*$B$23 -> 0 | G19: =+G18*$B$23 -> 0 | H19: =+H18*$B$23 -> 0 | I19: =+I18*$B$23 -> 0 | J19: =+J18*$B$23 -> 0 | ... L19: =+L18*$B$23 -> 0
A20: Reembolso Anual | E20: =+$B$18/8 -> 0 | F20: =+$B$18/8 -> 0 | G20: =+$B$18/8 -> 0 | H20: =+$B$18/8 -> 0 | I20: =+$B$18/8 -> 0 | J20: =+$B$18/8 -> 0 | K20: =+$B$18/8 -> 0 | L20: =+$B$18/8 -> 0
A21: Valor em dívida | C21: =+C18-C20 -> 0 | D21: =+D18-D20 -> 0 | E21: =+E18-E20 -> 0 | F21: =+F18-F20 -> 0 | G21: =+G18-G20 -> 0 | H21: =+H18-H20 -> 0 | I21: =+I18-I20 -> 0 | J21: =+J18-J20 -> 0 | ... L21: =+L18-L20 -> 0
A23: Taxa de juro associada | B23: 0.04
A25: Nº DE ANOS REEMBOLSO | B25: 10

Sheet Mov dos Impostos S Rendi
A3: Rubricas | B3: 2021 | C3: =+B3+1 -> 2022 | D3: =+C3+1 -> 2023 | E3: =+D3+1 -> 2024 | F3: =+E3+1 -> 2025 | G3: =+F3+1 -> 2026 | H3: =+G3+1 -> 2027
A4: Colecta de IRC 17% | B4: =-'DR SNC'!C29 -> 2550 | C4: =-'DR SNC'!D29 -> 0 | D4: =-'DR SNC'!E29 -> 2550 | E4: =-'DR SNC'!F29 -> 2550 | F4: =-'DR SNC'!G29 -> 2550 | G4: =-'DR SNC'!H29 -> 2550 | H4: =-'DR SNC'!I29 -> 2550
A5: Colecta de IRC 21% | B5: =-'DR SNC'!C30 -> 116195.82 | C5: =-'DR SNC'!D30 -> 0 | D5: =-'DR SNC'!E30 -> 89649.95 | E5: =-'DR SNC'!F30 -> 135599.88 | F5: =-'DR SNC'!G30 -> 102434.53 | G5: =-'DR SNC'!H30 -> 178760.24 | H5: =-'DR SNC'!I30 -> 245106.07
A6: Provisão para Impostos | B6: =SUM(B4:B5) -> 118745.82 | C6: =SUM(C4:C5) -> 0 | D6: =SUM(D4:D5) -> 92199.95 | E6: =SUM(E4:E5) -> 138149.88 | F6: =SUM(F4:F5) -> 104984.53 | G6: =SUM(G4:G5) -> 181310.24 | H6: =SUM(H4:H5) -> 247656.07
A9: Índice

Sheet MEIOS LIBERTOS PROJETO
A1: Rubricas | B1: 2021 | C1: =+B1+1 -> 2022 | D1: =+C1+1 -> 2023 | E1: =+D1+1 -> 2024 | F1: =+E1+1 -> 2025 | G1: =+F1+1 -> 2026 | H1: =+G1+1 -> 2027
A2: Recebimentos do Ano
A3: Vendas do Ano | B3: =+'DR SNC'!C7 -> 7613376.1 | C3: =+'DR SNC'!D7 -> 5617198 | D3: =+'DR SNC'!E7 -> 5898057.9 | E3: =+'DR SNC'!F7 -> 6487863.6 | F3: =+'DR SNC'!G7 -> 6812256.8 | G3: =+'DR SNC'!H7 -> 7834095.3 | H3: =+'DR SNC'!I7 -> 8617504.9
A4: (+) Total dos Recebimentos | B4: =SUM(B3:B3) -> 7613376.1 | C4: =SUM(C3:C3) -> 5617198 | D4: =SUM(D3:D3) -> 5898057.9 | E4: =SUM(E3:E3) -> 6487863.6 | F4: =SUM(F3:F3) -> 6812256.8 | G4: =SUM(G3:G3) -> 7834095.3 | H4: =SUM(H3:H3) -> 8617504.9
A5: Pagamentos do Ano
A6: Compras pagas no ano | B6: =+'Capital Circulante'!B18 -> 4956545.6 | C6: =+'Capital Circulante'!C18 -> 3553935.6 | D6: =+'Capital Circulante'!D18 -> 2949028.9 | E6: =+'Capital Circulante'!E18 -> 3243931.8 | F6: =+'Capital Circulante'!F18 -> 3406128.4 | G6: =+'Capital Circulante'!G18 -> 3917047.7 | H6: =+'Capital Circulante'!H18 -> 4308752.4
A7: Encargos com Pessoal | B7: =+'63_G. Pess.'!C15 -> 731846.19 | C7: =+'63_G. Pess.'!D15 -> 1081626.9 | D7: =+'63_G. Pess.'!E15 -> 1180795.2 | E7: =+'63_G. Pess.'!F15 -> 1279963.5 | F7: =+'63_G. Pess.'!G15 -> 1296158.9 | G7: =+'63_G. Pess.'!H15 -> 1296158.9 | H7: =+'63_G. Pess.'!I15 -> 1296158.9
A8: Fornecimentos e Serviços externos | B8: =+'Fornecimento Serviços Externos'!C12 -> 1180801.4 | C8: =+'Fornecimento Serviços Externos'!D12 -> 1309346.9 | D8: =+'Fornecimento Serviços Externos'!E12 -> 1359053.3 | E8: =+'Fornecimento Serviços Externos'!F12 -> 1494708.6 | F8: =+'Fornecimento Serviços Externos'!G12 -> 1498696.5 | G8: =+'Fornecimento Serviços Externos'!H12 -> 1645160 | H8: =+'Fornecimento Serviços Externos'!I12 -> 1723501
A9: Encargos Financeiros ( Juros + Amort Capital) | B9: =+'Serviço da Divida Emp. Bancario'!C6+'Serviço da Divida Emp. Bancario'!C7 -> 0 | C9: =+'Serviço da Divida Emp. Bancario'!D6+'Serviço da Divida Emp. Bancario'!D7 -> 0 | D9: =+'Serviço da Divida Emp. Bancario'!E6+'Serviço da Divida Emp. Bancario'!E7 -> 0 | E9: =+'Serviço da Divida Emp. Bancario'!F6+'Serviço da Divida Emp. Bancario'!F7 -> 84830.269 | F9: =+'Serviço da Divida Emp. Bancario'!G6+'Serviço da Divida Emp. Bancario'!G7 -> 81927.332 | G9: =+'Serviço da Divida Emp. Bancario'!H6+'Serviço da Divida Emp. Bancario'!H7 -> 79024.395 | H9: =+'Serviço da Divida Emp. Bancario'!I6+'Serviço da Divida Emp. Bancario'!I7 -> 76121.458
A10: Imposto sobre o Rendimento | B10: =+'Mov dos Impostos S Rendi'!B6 -> 118745.82 | C10: =+'Mov dos Impostos S Rendi'!C6 -> 0 | D10: =+'Mov dos Impostos S Rendi'!D6 -> 92199.95 | E10: =+'Mov dos Impostos S Rendi'!E6 -> 138149.88 | F10: =+'Mov dos Impostos S Rendi'!F6 -> 104984.53 | G10: =+'Mov dos Impostos S Rendi'!G6 -> 181310.24 | H10: =+'Mov dos Impostos S Rendi'!H6 -> 247656.07
A11: (-) Total dos Pagamentos | B11: =SUM(B6:B10) -> 6987938.9 | C11: =SUM(C6:C10) -> 5944909.4 | D11: =SUM(D6:D10) -> 5581077.4 | E11: =SUM(E6:E10) -> 6241584.1 | F11: =SUM(F6:F10) -> 6387895.7 | G11: =SUM(G6:G10) -> 7118701.3 | H11: =SUM(H6:H10) -> 7652189.9
A12: (=) Saldo do Ano | B12: =+B4-B11 -> 625437.12 | C12: =+C4-C11 -> -327711.48 | D12: =+D4-D11 -> 316980.44 | E12: =+E4-E11 -> 246279.51 | F12: =+F4-F11 -> 424361.11 | G12: =+G4-G11 -> 715394.08 | H12: =+H4-H11 -> 965315
A15: Índice

Sheet Plano Financeiro 
B1: 2021 | C1: =+B1+1 -> 2022 | D1: =+C1+1 -> 2023 | E1: =+D1+1 -> 2024 | F1: =+E1+1 -> 2025 | G1: =+F1+1 -> 2026 | H1: =+G1+1 -> 2027
A2: Necessidades Financeiras
A3: Investimento em Imobilizado | B3: =+'MAPA INVESTIMENTOS'!B5+'MAPA INVESTIMENTOS'!B6+'MAPA INVESTIMENTOS'!B7+'MAPA INVESTIMENTOS'!B8+'MAPA INVESTIMENTOS'!B9 -> 2943.1 | C3: =+'MAPA INVESTIMENTOS'!C2+'MAPA INVESTIMENTOS'!C4+'MAPA INVESTIMENTOS'!C10+'MAPA INVESTIMENTOS'!C11 -> 420508.44 | D3: =+'MAPA INVESTIMENTOS'!D3 -> 0 | E3: 0 | F3: 0 | G3: 0 | H3: 0
A4: Investimento em Fundo Maneio | B4: =IF('Capital Circulante'!B8>0,'Capital Circulante'!B8,0) -> 536047.89 | C4: =IF('Capital Circulante'!C8>0,'Capital Circulante'!C8,0) -> 0 | D4: =IF('Capital Circulante'!D8>0,'Capital Circulante'!D8,0) -> 19262.788 | E4: =IF('Capital Circulante'!E8>0,'Capital Circulante'!E8,0) -> 37845.871 | F4: =IF('Capital Circulante'!F8>0,'Capital Circulante'!F8,0) -> 26700.443 | G4: =IF('Capital Circulante'!G8>0,'Capital Circulante'!G8,0) -> 72947.917 | H4: =IF('Capital Circulante'!H8>0,'Capital Circulante'!H8,0) -> 58755.715
A5: Reembolso de Empréstimos MLP | B5: =+'Serviço da Divida Emp. Bancario'!C7+'Serviço da Divida Emp. Bancario'!C20 -> 0 | C5: =+'Serviço da Divida Emp. Bancario'!D7+'Serviço da Divida Emp. Bancario'!D20 -> 0 | D5: =+'Serviço da Divida Emp. Bancario'!E7+'Serviço da Divida Emp. Bancario'!E20 -> 0 | E5: =+'Serviço da Divida Emp. Bancario'!F7+'Serviço da Divida Emp. Bancario'!F20 -> 64509.711 | F5: =+'Serviço da Divida Emp. Bancario'!G7+'Serviço da Divida Emp. Bancario'!G20 -> 64509.711 | G5: =+'Serviço da Divida Emp. Bancario'!H7+'Serviço da Divida Emp. Bancario'!H20 -> 64509.711 | H5: =+'Serviço da Divida Emp. Bancario'!I7+'Serviço da Divida Emp. Bancario'!I20 -> 64509.711
A6: IRC | B6: =+'Mov dos Impostos S Rendi'!B6 -> 118745.82 | C6: =+'Mov dos Impostos S Rendi'!C6 -> 0 | D6: =+'Mov dos Impostos S Rendi'!D6 -> 92199.95 | E6: =+'Mov dos Impostos S Rendi'!E6 -> 138149.88 | F6: =+'Mov dos Impostos S Rendi'!F6 -> 104984.53 | G6: =+'Mov dos Impostos S Rendi'!G6 -> 181310.24 | H6: =+'Mov dos Impostos S Rendi'!H6 -> 247656.07
A7: Juros de Empréstimos MLP | B7: =+'Serviço da Divida Emp. Bancario'!C19 -> 0 | C7: =+'Serviço da Divida Emp. Bancario'!D19 -> 0 | D7: =+'Serviço da Divida Emp. Bancario'!E19 -> 0 | E7: =+'Serviço da Divida Emp. Bancario'!F19 -> 0 | F7: =+'Serviço da Divida Emp. Bancario'!G19 -> 0 | G7: =+'Serviço da Divida Emp. Bancario'!H19 -> 0 | H7: =+'Serviço da Divida Emp. Bancario'!I19 -> 0
A8: Total | B8: =SUM(B3:B7) -> 657736.82 | C8: =SUM(C3:C7) -> 420508.44 | D8: =SUM(D3:D7) -> 111462.74 | E8: =SUM(E3:E7) -> 240505.46 | F8: =SUM(F3:F7) -> 196194.69 | G8: =SUM(G3:G7) -> 318767.86 | H8: =SUM(H3:H7) -> 370921.49
A9: Recursos Financeiros
A10: Aumento de Capital | B10: 2000
A11: Prestações Suplementares | B11: =+'MAPA INVESTIMENTOS'!B22 -> 76296.96 | C11: =+'MAPA INVESTIMENTOS'!C22 -> 373771.01 | D11: =+'MAPA INVESTIMENTOS'!D22 -> 1500
A12: EBITDA | B12: =+'DR SNC'!C18 -> 722016.36 | C12: =+'DR SNC'!D18 -> -328302.32 | D12: =+'DR SNC'!E18 -> 460045.03 | E12: =+'DR SNC'!F18 -> 718440.33 | F12: =+'DR SNC'!G18 -> 612272.97 | G12: =+'DR SNC'!H18 -> 975728.71 | H12: =+'DR SNC'!I18 -> 1289092.5
A13: Desinvestimento em Fundo Maneio | B13: =IF('Capital Circulante'!B8<0,-'Capital Circulante'!B8,0) -> 0 | C13: =IF('Capital Circulante'!C8<0,-'Capital Circulante'!C8,0) -> 177060.3 | D13: =IF('Capital Circulante'!D8<0,-'Capital Circulante'!D8,0) -> 0 | E13: =IF('Capital Circulante'!E8<0,-'Capital Circulante'!E8,0) -> 0 | F13: =IF('Capital Circulante'!F8<0,-'Capital Circulante'!F8,0) -> 0 | G13: =IF('Capital Circulante'!G8<0,-'Capital Circulante'!G8,0) -> 0 | H13: =IF('Capital Circulante'!H8<0,-'Capital Circulante'!H8,0) -> 0
A14: Suprimentos Sócios | B14: 20000
A15: Empréstimos MLP P2020 | B15: =+'MAPA INVESTIMENTOS'!B24 -> 0 | C15: =+'MAPA INVESTIMENTOS'!C24 -> 0 | D15: =+'MAPA INVESTIMENTOS'!D24 -> 0 | E15: =[1]MapaServiçoDívida!H5 -> 0 | F15: =[1]MapaServiçoDívida!I5 -> 0 | G15: 0 | H15: 0
A16: Total | B16: =SUM(B10:B15) -> 820313.32 | C16: =SUM(C10:C15) -> 222529 | D16: =SUM(D10:D15) -> 461545.03 | E16: =SUM(E10:E15) -> 718440.33 | F16: =SUM(F10:F15) -> 612272.97 | G16: =SUM(G10:G15) -> 975728.71 | H16: =SUM(H10:H15) -> 1289092.5
A17: Saldo Anual | B17: =B16-B8 -> 162576.5 | C17: =C16-C8 -> -197979.44 | D17: =D16-D8 -> 350082.29 | E17: =E16-E8 -> 477934.87 | F17: =F16-F8 -> 416078.29 | G17: =G16-G8 -> 656960.85 | H17: =H16-H8 -> 918171.03
A18: Disponibilidades Iniciais | B18: 0 | C18: =B19 -> 162576.5 | D18: =C19 -> -35402.941 | E18: =D19 -> 314679.35 | F18: =E19 -> 792614.22 | G18: =F19 -> 1208692.5 | H18: =G19 -> 1865653.4
A19: Disponibilidades Finais | B19: =B18+B17 -> 162576.5 | C19: =C18+C17 -> -35402.941 | D19: =D18+D17 -> 314679.35 | E19: =E18+E17 -> 792614.22 | F19: =F18+F17 -> 1208692.5 | G19: =G18+G17 -> 1865653.4 | H19: =H18+H17 -> 2783824.4
A21: Índice

Sheet DR SNC
A3: Rúbricas | C3: 2021 | D3: 2022 | E3: 2023 | F3: 2024 | G3: 2025 | H3: 2026 | I3: 2027 | J3: 2028 | K3: 2029 | L3: 2030
A5: RENDIMENTOS E GASTOS
A7: Vendas e serviços prestados | C7: =+'Previsão Receitas'!B8 -> 7613376.1 | D7: =+'Previsão Receitas'!C8 -> 5617198 | E7: =+'Previsão Receitas'!D8 -> 5898057.9 | F7: =+'Previsão Receitas'!E8 -> 6487863.6 | G7: =+'Previsão Receitas'!F8 -> 6812256.8 | H7: =+'Previsão Receitas'!G8 -> 7834095.3 | I7: =+'Previsão Receitas'!H8 -> 8617504.9 | J7: =+'Previsão Receitas'!I8 -> 9479255.4 | ... L7: =+'Previsão Receitas'!K8 -> 11469899
A8: Subsídios à exploração | C8: 7157.47 | D8: 3722.78
A9: Ganhos/perdas imputados de subsidiárias, associadas e empreend
A10: Variação nos inventários da produção
A11: Custo das mercadorias vendidas e das matérias consumidas | C11: =-'Capital Circulante'!B18 -> -4956545.6 | D11: =-'Capital Circulante'!C18 -> -3553935.6 | E11: =-'Capital Circulante'!D18 -> -2949028.9 | F11: =-'Capital Circulante'!E18 -> -3243931.8 | G11: =-'Capital Circulante'!F18 -> -3406128.4 | H11: =-'Capital Circulante'!G18 -> -3917047.7 | I11: =-'Capital Circulante'!H18 -> -4308752.4 | J11: =-'Capital Circulante'!I18 -> -4739627.7 | ... L11: =-'Capital Circulante'!K18 -> -5734949.5
A12: Fornecimentos e serviços externos | C12: =-'Fornecimento Serviços Externos'!C12 -> -1180801.4 | D12: =-'Fornecimento Serviços Externos'!D12 -> -1309346.9 | E12: =-'Fornecimento Serviços Externos'!E12 -> -1359053.3 | F12: =-'Fornecimento Serviços Externos'!F12 -> -1494708.6 | G12: =-'Fornecimento Serviços Externos'!G12 -> -1498696.5 | H12: =-'Fornecimento Serviços Externos'!H12 -> -1645160 | I12: =-'Fornecimento Serviços Externos'!I12 -> -1723501 | J12: =-'Fornecimento Serviços Externos'!J12 -> -1421888.3 | ... L12: =-'Fornecimento Serviços Externos'!L12 -> -1720484.9
A13: Gastos com o pessoal | C13: =-'63_G. Pess.'!C15 -> -731846.19 | D13: =-'63_G. Pess.'!D15 -> -1081626.9 | E13: =-'63_G. Pess.'!E15 -> -1180795.2 | F13: =-'63_G. Pess.'!F15 -> -1279963.5 | G13: =-'63_G. Pess.'!G15 -> -1296158.9 | H13: =-'63_G. Pess.'!H15 -> -1296158.9 | I13: =-'63_G. Pess.'!I15 -> -1296158.9 | J13: =-'63_G. Pess.'!J15 -> -1296158.9 | ... L13: =-'63_G. Pess.'!L15 -> -1296158.9
A14: Imparidade de inventários (perdas/reversões)
A15: Outros rendimentos e ganhos | C15: 2813.8 | D15: 25285.84 | E15: =+'MAPA INVESTIMENTOS'!B23 -> 50864.64 | F15: =+'MAPA INVESTIMENTOS'!C23 -> 249180.68 | G15: =+'MAPA INVESTIMENTOS'!D23 -> 1000
A16: Outros gastos e perdas | C16: -32137.85 | D16: -29599.46
A18: Resultados antes de deprec, gastos de finan e impostos | C18: =SUM(C7:C17) -> 722016.36 | D18: =SUM(D7:D17) -> -328302.32 | E18: =SUM(E7:E17) -> 460045.03 | F18: =SUM(F7:F17) -> 718440.33 | G18: =SUM(G7:G17) -> 612272.97 | H18: =SUM(H7:H17) -> 975728.71 | I18: =SUM(I7:I17) -> 1289092.5 | J18: =SUM(J7:J17) -> 2021580.4 | ... L18: =SUM(L7:L17) -> 2718305.7
A20: Gastos/reversões de depreciação e de amortização | C20: -127990.92 | D20: -57770.64 | E20: =-Amortizações!M21 -> -18140.51 | F20: =-Amortizações!N21 -> -57726.62 | G20: =-Amortizações!O21 -> -109489.49 | H20: =-Amortizações!P21 -> -109489.49 | I20: =-Amortizações!Q21 -> -106920.78 | J20: =-Amortizações!R21 -> -89557.768 | K20: =-Amortizações!S21 -> -4406.48 | L20: =-Amortizações!T21 -> -4406.48
A21: Imparidade de invest depreciáveis/amortizáveis (perdas/reversões)
A23: Resultado operacional (antes de gastos de financiamento e impostos) | C23: =+C18+C20+C21 -> 594025.44 | D23: =+D18+D20+D21 -> -386072.96 | E23: =+E18+E20+E21 -> 441904.52 | F23: =+F18+F20+F21 -> 660713.71 | G23: =+G18+G20+G21 -> 502783.48 | H23: =+H18+H20+H21 -> 866239.22 | I23: =+I18+I20+I21 -> 1182171.7 | J23: =+J18+J20+J21 -> 1932022.7 | ... L23: =+L18+L20+L21 -> 2713899.2
A25: Juros e rendimentos similares obtidos
A26: Juros e gastos similares suportados | C26: -25711.99 | D26: -38486.67 | E26: =-'Serviço da Divida Emp. Bancario'!F19 -> 0 | F26: =-'Serviço da Divida Emp. Bancario'!G19 -> 0 | G26: =-'Serviço da Divida Emp. Bancario'!H19 -> 0 | H26: =-'Serviço da Divida Emp. Bancario'!I19 -> 0 | I26: =-'Serviço da Divida Emp. Bancario'!J19 -> 0 | J26: =-'Serviço da Divida Emp. Bancario'!K19 -> 0 | K26: =-'Serviço da Divida Emp. Bancario'!L19 -> 0 | L26: =-'Serviço da Divida Emp. Bancario'!M19 -> 0
A28: Resultado antes de impostos | C28: =SUM(C23:C26) -> 568313.45 | D28: =SUM(D23:D26) -> -424559.63 | E28: =SUM(E23:E26) -> 441904.52 | F28: =SUM(F23:F26) -> 660713.71 | G28: =SUM(G23:G26) -> 502783.48 | H28: =SUM(H23:H26) -> 866239.22 | I28: =SUM(I23:I26) -> 1182171.7 | J28: =SUM(J23:J26) -> 1932022.7 | ... L28: =SUM(L23:L26) -> 2713899.2
B29: 0.17 | C29: =-15000*$B$29 -> -2550 | D29: 0 | E29: =-15000*$B$29 -> -2550 | F29: =-15000*$B$29 -> -2550 | G29: =-15000*$B$29 -> -2550 | H29: =-15000*$B$29 -> -2550 | I29: =-15000*$B$29 -> -2550 | J29: =-15000*$B$29 -> -2550 | K29: =-15000*$B$29 -> -2550 | L29: =-15000*$B$29 -> -2550
A30: Imposto sobre o rendimento do período | B30: 0.21 | C30: =-(C28-15000)*$B$30 -> -116195.82 | D30: 0 | E30: =-(E28-15000)*$B$30 -> -89649.95 | F30: =-(F28-15000)*$B$30 -> -135599.88 | G30: =-(G28-15000)*$B$30 -> -102434.53 | H30: =-(H28-15000)*$B$30 -> -178760.24 | I30: =-(I28-15000)*$B$30 -> -245106.07 | J30: =-(J28-15000)*$B$30 -> -402574.76 | K30: =-(K28-15000)*$B$30 -> -490129.06 | L30: =-(L28-15000)*$B$30 -> -566768.84
A31: Resultado líquido do período | C31: =+C28+C29+C30 -> 449567.63 | D31: =SUM(D28:D30) -> -424559.63 | E31: =SUM(E28:E30) -> 349704.57 | F31: =SUM(F28:F30) -> 522563.83 | G31: =SUM(G28:G30) -> 397798.95 | H31: =SUM(H28:H30) -> 684928.99 | I31: =SUM(I28:I30) -> 934515.68 | J31: =SUM(J28:J30) -> 1526897.9 | K31: =SUM(K28:K30) -> 1856268.8 | L31: =SUM(L28:L30) -> 2144580.4
A35: Índice

Sheet Balanço SNC
A1: RUBRICAS | B1: Exercício
C2: 2021 | D2: 2022 | E2: 2023 | F2: =+E2+1 -> 2024 | G2: =+F2+1 -> 2025 | H2: =+G2+1 -> 2026 | I2: =+H2+1 -> 2027 | J2: =+I2+1 -> 2028 | K2: =+J2+1 -> 2029
A3: ACTIVO
A5: Activo não corrente:
A6: Activos fixos tangíveis | C6: 371234.14 | D6: 574837.67 | E6: =+Amortizações!D5 -> 615244.79 | F6: =+Amortizações!E5 -> 2500 | G6: =+Amortizações!F5 -> 0 | H6: =+Amortizações!G5 -> 0 | I6: =+Amortizações!H5 -> 0 | J6: =+Amortizações!I5 -> 0 | K6: =+Amortizações!J5 -> 0
A7: Activos intangíveis | C7: 16433.2 | D7: 18177.63 | E7: =+Amortizações!D18 -> 7706.9 | F7: =+Amortizações!E18 -> 0 | G7: =+Amortizações!F18 -> -2568.7098 | H7: =+Amortizações!G18 -> -5137.4195 | I7: =+Amortizações!H18 -> -7706.1293 | J7: =+Amortizações!I18 -> -10274.839 | K7: =+Amortizações!J18 -> -10274.839
A8: Participações Financeiras - Outros Métodos | C8: 5482.82 | D8: 12633.05
A9: Investimentos Financeiros | C9: 16145 | D9: 500000
D10: 16145
B11: =SUM(B6:B8) -> 0 | C11: =SUM(C6:C9) -> 409295.16 | D11: =SUM(D6:D10) -> 1121793.4 | E11: =SUM(E6:E7) -> 622951.69 | F11: =SUM(F6:F7) -> 2500 | G11: =SUM(G6:G7) -> -2568.7098 | H11: =SUM(H6:H7) -> -5137.4195 | I11: =SUM(I6:I7) -> -7706.1293 | J11: =SUM(J6:J7) -> -10274.839 | K11: =SUM(K6:K9) -> -10274.839
A13: Activo corrente:
A14: Inventários | C14: 1149471.3 | D14: 1602410.5 | E14: =+'Capital Circulante'!B4 -> 413045.47 | F14: =+'Capital Circulante'!C4 -> 296161.3 | G14: =+'Capital Circulante'!D4 -> 245752.41 | H14: =+'Capital Circulante'!E4 -> 270327.65 | I14: =+'Capital Circulante'!F4 -> 283844.03 | J14: =+'Capital Circulante'!G4 -> 326420.64 | K14: =+'Capital Circulante'!H4 -> 359062.7
A15: Clientes | C15: 2586768.2 | D15: 2419623 | E15: =+'Capital Circulante'!B3 -> 634448 | F15: =+'Capital Circulante'!C3 -> 468099.83 | G15: =+'Capital Circulante'!D3 -> 491504.82 | H15: =+'Capital Circulante'!E3 -> 540655.3 | I15: =+'Capital Circulante'!F3 -> 567688.07 | J15: =+'Capital Circulante'!G3 -> 652841.28 | K15: =+'Capital Circulante'!H3 -> 718125.41
A16: Adiantamentos a Fornecedores
A17: Estado E Outras Entes Públicas | C17: 29321.41
A18: Outras Contas a Receber | C18: 939964.66
A19: Diferimentos | C19: 2777.73 | D19: 2777.73
A20: Ativos financeiros detidos para negociação | C20: 2200 | D20: 2200
A21: Caixa e depósitos bancários | C21: 32174.29 | D21: 208162.51 | E21: =+'Plano Financeiro '!B19 -> 162576.5 | F21: =+'Plano Financeiro '!C19 -> -35402.941 | G21: =+'Plano Financeiro '!D19 -> 314679.35 | H21: =+'Plano Financeiro '!E19 -> 792614.22 | I21: =+'Plano Financeiro '!F19 -> 1208692.5 | J21: =+'Plano Financeiro '!G19 -> 1865653.4 | K21: =+'Plano Financeiro '!H19 -> 2783824.4
B22: =SUM(B14:B21) -> 0 | C22: =SUM(C14:C21) -> 4742677.6 | D22: =SUM(D14:D21) -> 4235173.7 | E22: =SUM(E14:E21) -> 1210070 | F22: =SUM(F14:F21) -> 728858.19 | G22: =SUM(G14:G21) -> 1051936.6 | H22: =SUM(H14:H21) -> 1603597.2 | I22: =SUM(I14:I21) -> 2060224.6 | ... K22: =SUM(K14:K21) -> 3861012.5
A24: Total do Activo | B24: =+B11+B22 -> 0 | C24: =+C11+C22 -> 5151972.8 | D24: =+D11+D22 -> 5356967.1 | E24: =+E11+E22 -> 1833021.7 | F24: =+F11+F22 -> 731358.19 | G24: =+G11+G22 -> 1049367.9 | H24: =+H11+H22 -> 1598459.8 | I24: =+I11+I22 -> 2052518.5 | ... K24: =+K11+K22 -> 3850737.7
A27: CAPITAL PRÓPRIO E PASSIVO
A29: Capital próprio:
A30: Capital realizado | C30: 200000 | D30: 200000 | E30: 200000 | F30: 200000 | G30: 200000 | H30: 200000 | I30: 200000 | J30: 200000 | K30: 200000
A31: Acções (quotas) próprias
A32: Outros instrumentos de capital próprio | C32: 117496.81 | D32: 117496.81 | E32: =+'MAPA INVESTIMENTOS'!B22 -> 76296.96 | F32: =+E32+'MAPA INVESTIMENTOS'!C22 -> 450067.97 | G32: =+F32+'MAPA INVESTIMENTOS'!D22 -> 451567.97 | H32: =+G32 -> 451567.97 | I32: =+H32 -> 451567.97 | J32: =+I32 -> 451567.97 | K32: =+J32 -> 451567.97
A33: Reservas legais | C33: 38350.23 | D33: 38350.23
A34: Outras reservas | C34: 73055.74 | D34: 73055.74
A35: Resultados transitados | C35: 975329.78 | D35: 1425031.5 | E35: 0 | F35: =+E35+E38 -> 449567.63 | G35: =+F35+F38 -> 25007.995 | H35: =+G35+G38 -> 374712.57 | I35: =+H35+H38 -> 897276.4 | J35: =+I35+I38 -> 1295075.4 | K35: =+J35+J38 -> 1980004.3
A38: Resultado líquido do período | B38: 0 | C38: 449701.68 | D38: -424559.63 | E38: =+'DR SNC'!C31 -> 449567.63 | F38: =+'DR SNC'!D31 -> -424559.63 | G38: =+'DR SNC'!E31 -> 349704.57 | H38: =+'DR SNC'!F31 -> 522563.83 | I38: =+'DR SNC'!G31 -> 397798.95 | J38: =+'DR SNC'!H31 -> 684928.99 | K38: =+'DR SNC'!I31 -> 934515.68
A39: Interesses minoritários
A41: Total do capital próprio | B41: =SUM(B30:B40) -> 0 | C41: =SUM(C30:C40) -> 1853934.2 | D41: =SUM(D30:D40) -> 1429374.6 | E41: =SUM(E30:E40) -> 725864.59 | F41: =SUM(F30:F40) -> 675075.97 | G41: =SUM(G29:G40) -> 1026280.5 | H41: =SUM(H29:H40) -> 1548844.4 | I41: =SUM(I29:I40) -> 1946643.3 | J41: =SUM(J29:J40) -> 2631572.3 | K41: =SUM(K29:K40) -> 3566088
A43: Passivo
A45: Passivo não corrente:
A46: Financiamentos obtidos | C46: 1445646.4 | D46: 2690253.8 | E46: =+'Serviço da Divida Emp. Bancario'!C8 -> 0 | F46: =+'Serviço da Divida Emp. Bancario'!D8 -> 0 | G46: =+'Serviço da Divida Emp. Bancario'!E8 -> 0 | H46: =+'Serviço da Divida Emp. Bancario'!F8 -> 387058.26 | I46: =+'Serviço da Divida Emp. Bancario'!G8 -> 322548.55 | J46: =+'Serviço da Divida Emp. Bancario'!H8 -> 258038.84 | K46: =+'Serviço da Divida Emp. Bancario'!I8 -> 193529.13
A47: Outras contas a pagar | E47: =+'Plano Financeiro '!$B$14 -> 20000 | F47: =+'Plano Financeiro '!$B$14 -> 20000 | G47: =+'Plano Financeiro '!$B$14 -> 20000 | H47: =+'Plano Financeiro '!$B$14 -> 20000 | I47: =+'Plano Financeiro '!$B$14 -> 20000 | J47: =+'Plano Financeiro '!$B$14 -> 20000 | K47: =+'Plano Financeiro '!$B$14 -> 20000
B49: =SUM(B46:B48) -> 0 | C49: =SUM(C46:C48) -> 1445646.4 | D49: =SUM(D46:D48) -> 2690253.8 | E49: =SUM(E46:E48) -> 20000 | F49: =SUM(F46:F48) -> 20000 | G49: =SUM(G46:G48) -> 20000 | H49: =SUM(H46:H48) -> 407058.26 | I49: =SUM(I46:I48) -> 342548.55 | ... K49: =SUM(K46:K48) -> 213529.13
A50: Passivo corrente:
A51: Fornecedores | C51: 1425400.5 | D51: 724908.82 | E51: =+'Capital Circulante'!B6 -> 511445.58 | F51: =+'Capital Circulante'!C6 -> 405273.54 | G51: =+'Capital Circulante'!D6 -> 359006.85 | H51: =+'Capital Circulante'!E6 -> 394886.7 | I51: =+'Capital Circulante'!F6 -> 408735.41 | J51: =+'Capital Circulante'!G6 -> 463517.31 | K51: =+'Capital Circulante'!H6 -> 502687.78
A52: Adiantamento de Clientes | C52: 191383.69 | D52: 191383.69
...

Sheet Avaliação Investimento
A1: Rubricas | B1: 0 | C1: 2021 | D1: =+C1+1 -> 2022 | E1: =+D1+1 -> 2023 | F1: =+E1+1 -> 2024 | G1: =+F1+1 -> 2025 | H1: =+G1+1 -> 2026 | I1: =+H1+1 -> 2027 | J1: =+I1+1 -> 2028 | K1: =+J1+1 -> 2029 | L1: =+K1+1 -> 2030
A2: Resultado Liquido | B2: 0 | C2: =+'DR SNC'!C31 -> 449567.63 | D2: =+'DR SNC'!D31 -> -424559.63 | E2: =+'DR SNC'!E31 -> 349704.57 | F2: =+'DR SNC'!F31 -> 522563.83 | G2: =+'DR SNC'!G31 -> 397798.95 | H2: =+'DR SNC'!H31 -> 684928.99 | I2: =+'DR SNC'!I31 -> 934515.68 | J2: =+'DR SNC'!J31 -> 1526897.9 | ... L2: =+'DR SNC'!L31 -> 2144580.4
A3: Amortizações | B3: 0 | C3: =-'DR SNC'!C20 -> 127990.92 | D3: =-'DR SNC'!D20 -> 57770.64 | E3: =-'DR SNC'!E20 -> 18140.51 | F3: =-'DR SNC'!F20 -> 57726.62 | G3: =-'DR SNC'!G20 -> 109489.49 | H3: =-'DR SNC'!H20 -> 109489.49 | I3: =-'DR SNC'!I20 -> 106920.78 | J3: =-'DR SNC'!J20 -> 89557.768 | ... L3: =-'DR SNC'!L20 -> 4406.48
A4: Cash Flow de Exploração | B4: =SUM(B2:B3) -> 0 | C4: =SUM(C2:C3) -> 577558.55 | D4: =SUM(D2:D3) -> -366788.99 | E4: =SUM(E2:E3) -> 367845.08 | F4: =SUM(F2:F3) -> 580290.45 | G4: =SUM(G2:G3) -> 507288.44 | H4: =SUM(H2:H3) -> 794418.47 | I4: =SUM(I2:I3) -> 1041436.5 | ... L4: =SUM(L2:L3) -> 2148986.9
A5: Investimento em Capital Circulante
A6: Investimento em Capital Fixo | D6: =-Amortizações!C21 -> -127161.6 | E6: =-Amortizações!D21 -> -622951.69
A7: Cash Flow Total | D7: =D6 -> -127161.6 | E7: =+D4+D5+E6 -> -989740.68 | F7: =+F4+F5+F6 -> 580290.45 | G7: =+G4+G5+G6 -> 507288.44 | H7: =+H4+H5+H6 -> 794418.47 | I7: =+I4+I5+I6 -> 1041436.5 | J7: =+J4+J5+J6 -> 1616455.7 | K7: =+K4+K5+K6 -> 1860675.3 | L7: =+L4+L5+L6 -> 2148986.9
A8: Cash Flow Acumulado | D8: =+D7 -> -127161.6 | E8: =+D8+E7 -> -1116902.3 | F8: =+E8+F7 -> -536611.83 | G8: =+F8+G7 -> -29323.39 | H8: =+G8+H7 -> 765095.08 | I8: =+H8+I7 -> 1806531.5 | J8: =+I8+J7 -> 3422987.2 | K8: =+J8+K7 -> 5283662.5 | L8: =+K8+L7 -> 7432649.4
A10: TIR | B10: =IRR(D7:L7) -> 0.62618552
A11: VAL | B11: =NPV(B17,D7,D7:I7) -> 1116396.1
A13: Descrição | B13: %
A14: Taxa de Aplicações Sem Risco (Rf) | B14: 0.02
A15: Taxa de Rendibilidade do Mercado Accionista (Rm) | B15: 0.05
A16: Beta Negócio Sem Efeito de Alavanca (Bu) | B16: 1
A17: Taxa Rendibilidade Desejada (Keu) | B17: 0.05

Sheet MAPA INVESTIMENTOS
A1: Designação | B1: INVESTIMENTO 2022 | C1: INVESTIMENTO 2023 | D1: INVESTIMENTO 2024 | J1: =+SUM(B2:D2) -> 262586.94
A2: Equipamento Básico | B2: 21917.5 | C2: 240669.44 | D2: 0 | J2: =+SUM(B3:D3) -> 220324
A3: Obras | B3: 38875 | C3: 181449 | D3: 0 | J3: =+SUM(B4:D4) -> 243265
A4: Máquinas | B4: 63426 | C4: 179839 | D4: 0 | J4: =+SUM(B5:D5) -> 5000
A5: Prestação de serviços | B5: 0 | C5: 2500 | D5: 2500 | J5: =+SUM(B6:D6) -> 291.35
A6: Ferramentas | B6: 0 | C6: 291.35 | D6: 0 | J6: =+SUM(B7:D7) -> 13439.1
A7: Eq Informático | B7: 2943.1 | C7: 10496 | D7: 0 | J7: =+SUM(B8:D8) -> 7706.9
A8: Software | B8: 0 | C8: 7706.9 | D8: 0 | J8: =+SUM(B9:D9) -> 0
J9: =+SUM(B10:D10) -> 0
J10: =+SUM(B11:D11) -> 0
J11: =+SUM(B12:D12) -> 0
J12: =+SUM(B13:D13) -> 0
B15: =SUM(B2:B14) -> 127161.6 | C15: =SUM(C2:C14) -> 622951.69 | D15: =SUM(D2:D14) -> 2500 | E15: =SUM(J1:J12) -> 752613.29
A17: SUB TOTAL FES´S | B17: =+B9+B13 -> 0 | C17: =+C9+C13 -> 0 | D17: =+D9+D13 -> 0
A19: INVESTIMENTO TOTAL | B19: =+B15+C15+D15 -> 752613.29
A20: FINANCIAMENTO P2020 GLOBAL | B20: =+B15*0.4 -> 50864.64 | C20: =+C15*0.4 -> 249180.68 | D20: =+D15*0.4 -> 1000 | E20: =SUM(B20:D20) -> 301045.32
A22: CAPITAIS PRÓPRIOS | B22: =+B15*0.6 -> 76296.96 | C22: =+C15*0.6 -> 373771.01 | D22: =+D15*0.6 -> 1500 | E22: =SUM(B22:D22) -> 451567.97 | F22: =+E22*0.25 -> 112891.99
A23: FINANCIAMENTO P2020 FUNDO PERDIDO 100% DO VALOR GLOBAL | B23: =+B20*1 -> 50864.64 | C23: =+C20*1 -> 249180.68 | D23: =+D20*1 -> 1000 | E23: =SUM(B23:D23) -> 301045.32
A24: FINANCIAMENTO P2020 REEMBOLSÁVEL 50% DO VALOR GLOBAL | B24: 0 | C24: 0 | D24: 0 | E24: =SUM(B24:D24) -> 0
A25: TOTAL FINANCIAMENTO | B25: =SUM(B22:B24) -> 127161.6 | C25: =SUM(C22:C24) -> 622951.69 | D25: =SUM(D22:D24) -> 2500 | E25: =SUM(E22:E24) -> 752613.29
