Workbook
Name a: #REF!
Name a: #REF!
Name ddd: #N/A
Name h: #REF!,#REF!
Name h: #REF!,#REF!
Name INDIC_ECOFIN: #REF!
Name INDIC_ECOFIN: #REF!

Sheet Índice

Sheet Pressupostos
C2: 2024 | D2: =+C2+1 -> 2025 | E2: =+D2+1 -> 2026 | F2: =+E2+1 -> 2027 | G2: =+F2+1 -> 2028 | H2: =+G2+1 -> 2029 | I2: =+H2+1 -> 2030 | J2: =+I2+1 -> 2031 | K2: =+J2+1 -> 2032 | ... Q2: =+P2+1 -> 2038
A3: Inflação | C3: 0.022 | D3: 0.022 | E3: 0.021 | F3: =+E3 -> 0.021 | G3: 0.02 | H3: =+G3 -> 0.02 | I3: 0.019 | J3: =+I3 -> 0.019 | K3: 0.018 | L3: =+K3 -> 0.018 | M3: 0.017 | N3: =+M3 -> 0.017 | O3: =+N3 -> 0.017 | P3: =+O3 -> 0.017 | Q3: =+P3 -> 0.017
A4: Índice Acumulado Inflação | C4: 1 | D4: =+C4*(1+D3) -> 1.022 | E4: =+D4*(1+E3) -> 1.043462 | F4: =+E4*(1+F3) -> 1.0653747 | G4: =+F4*(1+G3) -> 1.0866822 | H4: =+G4*(1+H3) -> 1.1084158 | I4: =+H4*(1+I3) -> 1.1294757 | J4: =+I4*(1+J3) -> 1.1509358 | K4: =+J4*(1+K3) -> 1.1716526 | ... Q4: =+P4*(1+Q3) -> 1.2976316
A6: Descrição
A7: Unidade monetária | B7: Euros
A8: 1º Ano actividade | B8: 2024
A10: Descrição
A11: Prazo médio de Recebimento (dias) | B11: 60
A12: Prazo médio de Pagamento (dias) | B12: 55
A13: Prazo médio de Stock (dias) | B13: 15
A14: Prazo Médio EOEP | B14: 30
A16: Descrição
A17: Taxa de IVA - Prestação Serviços | B17: 0.23
A18: Taxa de IVA - CMVMC | B18: 0.23
A19: Taxa de IVA - FSE | B19: 0.23
A20: Taxa de IVA - Investimento | B20: 0.23
A22: Descrição
A23: TSU - Entidade - órgãos sociais | B23: 0.2375
A24: TSU- Entidade - colaboradores | B24: 0.2375
A25: TSU - Pessoal - órgãos sociais | B25: 0.11
A26: TSU - Pessoal - colaboradores | B26: 0.11
A27: Taxa de IRC | B27: 0.21
A30: Índice

Sheet Previsão Receitas
A1: Descrição | B1: 2024 | C1: =+B1+1 -> 2025 | D1: =+C1+1 -> 2026 | E1: =+D1+1 -> 2027 | F1: =+E1+1 -> 2028 | G1: =+F1+1 -> 2029 | H1: =+G1+1 -> 2030
A3: Produtos atuais | B3: 10701564 | C3: 10560493 | D3: 12144567 | E3: 14087698 | F3: 15073836 | G3: =F3*1.02 -> 15375313 | H3: =G3*1.02 -> 15682819
A4: Novos produtos
A8: TOTAL | B8: =SUM(B2:B7) -> 10701564 | C8: =SUM(C2:C7) -> 10560493 | D8: =SUM(D2:D7) -> 12144567 | E8: =SUM(E2:E7) -> 14087698 | F8: =SUM(F2:F7) -> 15073836 | G8: =SUM(G2:G7) -> 15375313 | H8: =SUM(H2:H7) -> 15682819
C9: =C8/B8 -> 0.98681773 | D9: =D8/C8 -> 1.15 | E9: =E8/D8 -> 1.16 | F9: =F8/E8 -> 1.0699999 | G9: =G8/F8 -> 1.02 | H9: =H8/G8 -> 1.02
A11: VOLUME DE NEGÓCIOS POR MERCADO 2022
A12: Mercado Nacional | B12: 1 | E12: =+$F$8*B12 -> 15073836 | F12: 448909.7
A13: França | B13: 0 | E13: =+$F$8*B13 -> 0 | F13: 138126.06
A14: Marrocos | B14: 0 | E14: =+$F$8*B14 -> 0 | F14: 34531.515
A15: Alemanha | B15: 0 | E15: =+$F$8*B15 -> 0 | F15: 34531.515
A16: Espanha | B16: 0 | E16: =+$F$8*B16 -> 0 | F16: 34531.515
B17: =SUM(B12:B16) -> 1 | E17: =SUM(E12:E16) -> 15073836
D20: =+D8*0.05 -> 607228.35 | E20: =+(F8-304916.94)/F8 -> 0.97977178

Sheet Fornecimento  Serviços Externos
A1: FSE´s PROJETO | B1: Valor Mês | C1: 2024 | D1: =+C1+1 -> 2025 | E1: =+D1+1 -> 2026 | F1: =+E1+1 -> 2027 | G1: =+F1+1 -> 2028 | H1: =+G1+1 -> 2029 | I1: =+H1+1 -> 2030 | J1: =+I1+1 -> 2031 | K1: =+J1+1 -> 2032 | L1: =+K1+1 -> 2033
A2: 621 - Subcontratos | B2: 0 | C2: 0 | D2: =+$B$2*12 -> 0 | E2: =D2*E19 -> 0 | F2: =E2*F19 -> 0 | G2: =F2*G19 -> 0 | H2: =G2*H19 -> 0 | I2: =H2*I19 -> 0 | J2: =I2*J19 -> 0 | K2: =J2*K19 -> 0 | L2: =K2*L19 -> 0
A3: 622 - Serviços Especializados | B3: 69500 | C3: 832693.66 | D3: =+$B$3*12 -> 834000 | E3: =D3*E19 -> 917400 | F3: =E3*F19 -> 1009140 | G3: =F3*G19 -> 1059597 | H3: =G3*H19 -> 1091384.9 | I3: =H3*I19 -> 1124126.5 | J3: =I3*J19 -> 1157850.3 | K3: =J3*K19 -> 1192585.8 | L3: =K3*L19 -> 1228363.3
A4: 623 - Materiais | B4: 8850 | C4: 105235.32 | D4: =+B4*12 -> 106200 | E4: =D4*E19 -> 116820 | F4: =E4*F19 -> 128502 | G4: =F4*G19 -> 134927.1 | H4: =G4*H19 -> 138974.91 | I4: =H4*I19 -> 143144.16 | J4: =I4*J19 -> 147438.49 | K4: =J4*K19 -> 151861.64 | L4: =K4*L19 -> 156417.49
A5: 624 - Energia e Fluidos | B5: 8900 | C5: 106213.96 | D5: =+B5*12 -> 106800 | E5: =D5*E20 -> 114810 | F5: =E5*F20 -> 123420.75 | G5: =F5*G20 -> 128357.58 | H5: =G5*H20 -> 130924.73 | I5: =H5*I20 -> 133543.23 | J5: =I5*J20 -> 136214.09 | K5: =J5*K20 -> 138938.37 | L5: =K5*L20 -> 141717.14
A6: 625- Deslocações, Estadas e transportes | B6: 7750 | C6: 93186.09 | D6: =+$B$6*12 -> 93000 | E6: =D6*E19 -> 102300 | F6: =E6*F19 -> 112530 | G6: =F6*G19 -> 118156.5 | H6: =G6*H19 -> 121701.2 | I6: =H6*I19 -> 125352.23 | J6: =I6*J19 -> 129112.8 | K6: =J6*K19 -> 132986.18 | L6: =K6*L19 -> 136975.77
A7: 626 - Serviços Diversos | B7: 46250 | C7: 553579.66 | D7: =+$B$7*12 -> 555000 | E7: =D7*E20 -> 596625 | F7: =E7*F20 -> 641371.88 | G7: =F7*G20 -> 667026.75 | H7: =G7*H20 -> 680367.29 | I7: =H7*I20 -> 693974.63 | J7: =I7*J20 -> 707854.12 | K7: =J7*K20 -> 722011.21 | L7: =K7*L20 -> 736451.43
D8: =+$B$8*12 -> 0 | E8: =D8*E20 -> 0 | F8: =E8*F20 -> 0 | G8: =F8*G20 -> 0 | H8: =G8*H20 -> 0 | I8: =H8*I20 -> 0 | J8: =I8*J20 -> 0 | K8: =J8*K20 -> 0 | L8: =K8*L20 -> 0
D9: =+$B$9*12 -> 0 | E9: =D9*E19 -> 0 | F9: =E9*F19 -> 0 | G9: =F9*G19 -> 0 | H9: =G9*H19 -> 0 | I9: =H9*I19 -> 0 | J9: =I9*J19 -> 0 | K9: =J9*K19 -> 0 | L9: =K9*L19 -> 0
D10: =+$B$10*12 -> 0 | E10: =D10*E19 -> 0 | F10: =E10*F19 -> 0 | G10: =F10*G19 -> 0 | H10: =G10*H19 -> 0 | I10: =H10*I19 -> 0 | J10: =I10*J19 -> 0 | K10: =J10*K19 -> 0 | L10: =K10*L19 -> 0
D11: =+$B$11*12 -> 0 | E11: =D11*E20 -> 0 | F11: =E11*F20 -> 0 | G11: =F11*G20 -> 0 | H11: =G11*H20 -> 0 | I11: =H11*I20 -> 0 | J11: =I11*J20 -> 0 | K11: =J11*K20 -> 0 | L11: =K11*L20 -> 0
D12: =+$B$12*12 -> 0 | E12: =D12*E19 -> 0 | F12: =E12*F19 -> 0 | G12: =F12*G19 -> 0 | H12: =G12*H19 -> 0 | I12: =H12*I19 -> 0 | J12: =I12*J19 -> 0 | K12: =J12*K19 -> 0 | L12: =K12*L19 -> 0
D13: =+$B$13*12 -> 0 | E13: =D13*E19 -> 0 | F13: =E13*F19 -> 0 | G13: =F13*G19 -> 0 | H13: =G13*H19 -> 0 | I13: =H13*I19 -> 0 | J13: =I13*J19 -> 0 | K13: =J13*K19 -> 0 | L13: =K13*L19 -> 0
D14: =+$B$14*12 -> 0 | E14: =D14*E19 -> 0 | F14: =E14*F19 -> 0 | G14: =F14*G19 -> 0 | H14: =G14*H19 -> 0 | I14: =H14*I19 -> 0 | J14: =I14*J19 -> 0 | K14: =J14*K19 -> 0 | L14: =K14*L19 -> 0
D15: =+$B$15*12 -> 0 | E15: =D15*E19 -> 0 | F15: =E15*F19 -> 0 | G15: =F15*G19 -> 0 | H15: =G15*H19 -> 0 | I15: =H15*I19 -> 0 | J15: =I15*J19 -> 0 | K15: =J15*K19 -> 0 | L15: =K15*L19 -> 0
A16: 62- FSE´s Projeto
C18: =SUM(C2:C17) -> 1690908.7 | D18: =SUM(D2:D17) -> 1695000 | E18: =SUM(E2:E17) -> 1847955 | F18: =SUM(F2:F17) -> 2014964.6 | G18: =SUM(G2:G17) -> 2108064.9 | H18: =SUM(H2:H17) -> 2163353 | I18: =SUM(I2:I17) -> 2220140.7 | J18: =SUM(J2:J17) -> 2278469.7 | ... L18: =SUM(L2:L17) -> 2399925.2
A19: Serviços especializados e RH related | D19: =D18/C18 -> 1.0024196 | E19: 1.1 | F19: 1.1 | G19: 1.05 | H19: 1.03 | I19: 1.03 | J19: 1.03 | K19: 1.03 | L19: 1.03
A20: Outros Serviços | E20: 1.075 | F20: 1.075 | G20: 1.04 | H20: 1.02 | I20: 1.02 | J20: 1.02 | K20: 1.02 | L20: 1.02
E21: =E18/D18 -> 1.0902389 | F21: =F18/E18 -> 1.0903754 | G21: =G18/F18 -> 1.0462044 | H21: =H18/G18 -> 1.0262269 | I21: =I18/H18 -> 1.0262498 | J21: =J18/I18 -> 1.0262727 | K21: =K18/J18 -> 1.0262955 | L21: =L18/K18 -> 1.0263182

Sheet Capital Circulante
B1: 2024 | C1: =+B1+1 -> 2025 | D1: =+C1+1 -> 2026 | E1: =+D1+1 -> 2027 | F1: =+E1+1 -> 2028 | G1: =+F1+1 -> 2029 | H1: =+G1+1 -> 2030
A2: Necessidades Financeiras de Exploração | B2: =SUM(B3:B4) -> 2068816.2 | C2: =SUM(C3:C4) -> 2041544.5 | D2: =SUM(D3:D4) -> 2347776.2 | E2: =SUM(E3:E4) -> 2723420.4 | F2: =SUM(F3:F4) -> 2907778.9 | G2: =SUM(G3:G4) -> 2972340.9 | H2: =SUM(H3:H4) -> 3031787.7
A3: Clientes | B3: =+'Previsão Receitas'!B8/360*Pressupostos!$B$11 -> 1783594 | C3: =+'Previsão Receitas'!C8/360*Pressupostos!$B$11 -> 1760082.2 | D3: =+'Previsão Receitas'!D8/360*Pressupostos!$B$11 -> 2024094.5 | E3: =+'Previsão Receitas'!E8/360*Pressupostos!$B$11 -> 2347949.7 | F3: =+'Previsão Receitas'!F8/360*Pressupostos!$B$11 -> 2512306 | G3: =+'Previsão Receitas'!G8/360*Pressupostos!$B$11 -> 2562552.1 | H3: =+'Previsão Receitas'!H8/360*Pressupostos!$B$11 -> 2613803.2
A4: Existências | B4: =B13/360*Pressupostos!$B$13 -> 285222.21 | C4: =C13/360*Pressupostos!$B$13 -> 281462.33 | D4: =D13/360*Pressupostos!$B$13 -> 323681.68 | E4: =E13/360*Pressupostos!$B$13 -> 375470.76 | F4: =F13/360*Pressupostos!$B$13 -> 395472.92 | G4: =G13/360*Pressupostos!$B$13 -> 409788.76 | H4: =H13/360*Pressupostos!$B$13 -> 417984.54
A5: Recursos Financeiros de Exploração | B5: =SUM(B6:B6) -> 1045814.8 | C5: =SUM(C6:C6) -> 1032028.5 | D5: =SUM(D6:D6) -> 1186832.8 | E5: =SUM(E6:E6) -> 1376726.1 | F5: =SUM(F6:F6) -> 1450067.4 | G5: =SUM(G6:G6) -> 1502558.8 | H5: =SUM(H6:H6) -> 1532610
A6: Fornecedores | B6: =(+'Fornecimento Serviços Externos'!C2+B18)/360*Pressupostos!$B$12 -> 1045814.8 | C6: =(+'Fornecimento Serviços Externos'!D2+C18)/360*Pressupostos!$B$12 -> 1032028.5 | D6: =(+'Fornecimento Serviços Externos'!E2+D18)/360*Pressupostos!$B$12 -> 1186832.8 | E6: =(+'Fornecimento Serviços Externos'!F2+E18)/360*Pressupostos!$B$12 -> 1376726.1 | F6: =(+'Fornecimento Serviços Externos'!G2+F18)/360*Pressupostos!$B$12 -> 1450067.4 | G6: =(+'Fornecimento Serviços Externos'!H2+G18)/360*Pressupostos!$B$12 -> 1502558.8 | H6: =(+'Fornecimento Serviços Externos'!I2+H18)/360*Pressupostos!$B$12 -> 1532610
A7: Fundo Maneio | B7: =B2-B5 -> 1023001.4 | C7: =C2-C5 -> 1009516 | D7: =D2-D5 -> 1160943.4 | E7: =E2-E5 -> 1346694.3 | F7: =F2-F5 -> 1457711.5 | G7: =G2-G5 -> 1469782.1 | H7: =H2-H5 -> 1499177.7
A8: Variação Fundo Maneio | B8: =B7 -> 1023001.4 | C8: =C7-B7 -> -13485.485 | D8: =D7-C7 -> 151427.4 | E8: =E7-D7 -> 185750.96 | F8: =F7-E7 -> 111017.23 | G8: =G7-F7 -> 12070.55 | H8: =H7-G7 -> 29395.642
A10: Mapa das Compras
B12: 2024 | C12: =+B12+1 -> 2025 | D12: =+C12+1 -> 2026 | E12: =+D12+1 -> 2027 | F12: =+E12+1 -> 2028 | G12: =+F12+1 -> 2029 | H12: =+G12+1 -> 2030
A13: CMVMC | B13: =+B18 -> 6845333 | C13: =+C18 -> 6755095.9 | D13: =+D18 -> 7768360.3 | E13: =+E18 -> 9011298.1 | F13: =+F18 -> 9491350.1 | G13: =+G18 -> 9834930.2 | H13: =+H18 -> 10031629
A14: + Existências Finais | B14: 0 | C14: 0 | D14: 0 | E14: 0 | F14: 0 | G14: 0 | H14: 0
A15: - Existências Iniciais | B15: 0 | C15: =B14 -> 0 | D15: =C14 -> 0 | E15: =D14 -> 0 | F15: =E14 -> 0 | G15: =F14 -> 0 | H15: =G14 -> 0
A16: Compras | B16: =B13+B14-B15 -> 6845333 | C16: =C13+C14-C15 -> 6755095.9 | D16: =D13+D14-D15 -> 7768360.3 | E16: =E13+E14-E15 -> 9011298.1 | F16: =F13+F14-F15 -> 9491350.1 | G16: =G13+G14-G15 -> 9834930.2 | H16: =H13+H14-H15 -> 10031629
A18: CMVMC | B18: 6845333 | C18: =+'Previsão Receitas'!C8*$B$22 -> 6755095.9 | D18: =+'Previsão Receitas'!D8*$B$22 -> 7768360.3 | E18: =+'Previsão Receitas'!E8*$B$22 -> 9011298.1 | F18: =+'Previsão Receitas'!F8*($B$22-0.01) -> 9491350.1 | G18: =+'Previsão Receitas'!G8*$B$22 -> 9834930.2 | H18: =+'Previsão Receitas'!H8*$B$22 -> 10031629
A20: Índice
A22: Peso dos CMVMC sobre as Vendas | B22: =B18/'Previsão Receitas'!B8 -> 0.63965725

Sheet 63_G. Pess.
A1: Recursos Humanos | C1: Encargos Mensais pessoal | G1: Valor Ano
B2: N | C2: Vencimento Base | D2: Outros encargos mensais | E2: Encargos Sociais | F2: Total
A3: RECURSOS HUMANOS ATUAIS | B3: 72 | C3: 1200 | D3: 39.80047 | E3: =+C3*0.2165 -> 259.8 | F3: =+C3+E3+D3 -> 1499.6005 | G3: =+F3*14*B3 -> 1511597.3 | H3: Nota: Encargos patronais alterados para 21,65% por causa do IES 2024. Futuramente corrigir para 23,75%
A4: Técnico Informática | B4: 1 | C4: 1450 | D4: 0 | E4: =+C4*0.2375 -> 344.375 | F4: =+C4+E4+D4 -> 1794.375 | G4: =+F4*14*B4+0.25 -> 25121.5
A11: TOTAL € | B11: =SUM(B3:B10) -> 73 | C11: =SUM(C3:C10) -> 2650 | D11: =SUM(D3:D10) -> 39.80047 | E11: =SUM(E3:E10) -> 604.175 | F11: =SUM(F3:F3) -> 1499.6005 | G11: =SUM(G3:G10) -> 1536718.8
C14: 2024 | D14: =+C14+1 -> 2025 | E14: =+D14+1 -> 2026 | F14: =+E14+1 -> 2027 | G14: =+F14+1 -> 2028 | H14: =+G14+1 -> 2029 | I14: =+H14+1 -> 2030
A15: Encargos Totais Com o Pessoal | C15: =+G3 -> 1511597.3 | D15: =C15*1.05 -> 1587177.1 | E15: =+$G$11*1.1 -> 1690390.7 | F15: =E15*1.1 -> 1859429.7 | G15: =F15*1.075 -> 1998886.9 | H15: =G15*1.05 -> 2098831.3 | I15: =H15*1.05 -> 2203772.9
A19: Índice

Sheet Amortizações
A1: Investimento | L1: Mapa Amortizações
A2: Nº | B2: DESIGNAÇÃO | C2: 0 | D2: 2024 | E2: =+D2+1 -> 2025 | F2: =+E2+1 -> 2026 | G2: =+F2+1 -> 2027 | H2: =+G2+1 -> 2028 | I2: =+H2+1 -> 2029 | J2: =+I2+1 -> 2030 | K2: 2026 | L2: % | M2: 2024 | N2: =+M2+1 -> 2025 | O2: =+N2+1 -> 2026 | P2: =+O2+1 -> 2027 | Q2: =+P2+1 -> 2028 | R2: =+Q2+1 -> 2029 | S2: =+R2+1 -> 2030 | T2: =+S2+1 -> 2031
A4: ATIVO TANGÍVEL
B5: TOTAL | C5: =SUM(C6:C12) -> 439738.42 | D5: =SUM(D6:D12) -> 434738.42 | E5: =SUM(E6:E12) -> 326671.54 | F5: =SUM(F6:F12) -> 224399.95 | G5: =SUM(G6:G12) -> 117128.37 | H5: =SUM(H6:H12) -> 9856.7854 | I5: =SUM(I6:I12) -> -0.0046114559 | J5: =SUM(J6:J12) -> -0.0046114559
B6: Imobilizado Existente na Empresa | C6: 432693.12 | D6: =C6 -> 432693.12 | E6: =+D6-N6 -> 326671.54 | F6: =+E6-O6 -> 220649.95 | G6: =+F6-P6 -> 114628.37 | H6: =+G6-Q6 -> 8606.7854 | I6: =+H6-R6 -> -0.0046114559 | J6: =+I6-S6 -> -0.0046114559 | L6: 0.2450272 | N6: =+$C$6*$L$6 -> 106021.58 | O6: =+$C$6*$L$6 -> 106021.58 | P6: =+$C$6*$L$6 -> 106021.58 | Q6: =+$C$6*$L$6 -> 106021.58 | R6: 8606.79
B7: Imobilizado intangivel | C7: 2045.3 | D7: 2045.3 | E7: =+C7-N7 -> 0 | F7: =+E7-O7 -> 0 | G7: =+F7-P7 -> 0 | H7: =+G7-Q7 -> 0 | I7: =+H7-R7 -> 0 | L7: 1 | N7: =+$C$7*$L$7 -> 2045.3
B8: ='MAPA INVESTIMENTOS'!A7 -> Aquisição de Hardware (Ecrans e Impressoras) | C8: 5000 | F8: =+C8-O8 -> 3750 | G8: =+F8-P8 -> 2500 | H8: =+G8-Q8 -> 1250 | I8: =+H8-R8 -> 0 | L8: 0.25 | O8: =+$C$8*$L$8 -> 1250 | P8: =+$C$8*$L$8 -> 1250 | Q8: =+$C$8*$L$8 -> 1250 | R8: =+$C$8*$L$8 -> 1250
E9: =+C9-N9 -> 0 | F9: =+E9-O9 -> 0 | G9: =+F9-P9 -> 0 | H9: =+G9-Q9 -> 0 | I9: =+H9-R9 -> 0 | L9: 0.2 | N9: =+$C$9*$L$9 -> 0 | O9: =+$C$9*$L$9 -> 0 | P9: =+$C$9*$L$9 -> 0 | Q9: =+$C$9*$L$9 -> 0 | R9: =+$C$9*$L$9 -> 0
E10: =+C10-N10 -> 0 | F10: =+E10-O10 -> 0 | G10: =+F10-P10 -> 0 | H10: =+G10-Q10 -> 0 | I10: =+H10-R10 -> 0 | L10: 0.2 | N10: =+$C$10*$L$10 -> 0 | O10: =+$C$10*$L$10 -> 0 | P10: =+$C$10*$L$10 -> 0 | Q10: =+$C$10*$L$10 -> 0 | R10: =+$C$10*$L$10 -> 0
A13: ATIVO INTANGÍVEL
B14: TOTAL | C14: =SUM(C15:C19) -> 61500 | D14: =SUM(D15:D19) -> 0 | E14: =SUM(E15:E19) -> 0 | F14: =SUM(F15:F19) -> 30750 | G14: =SUM(G15:G19) -> 52500 | H14: =SUM(H15:H19) -> 32000 | I14: =SUM(I15:I19) -> 11500 | J14: =SUM(J15:J19) -> 0
B15: ='MAPA INVESTIMENTOS'!A2 -> Aquisição de Software (MÊS "Digital Factory") | C15: 15000 | F15: 7500 | G15: =+F15-O15+7500 -> 12500 | H15: =+G15-P15 -> 7500 | I15: =+H15-Q15 -> 2500 | J15: 0 | L15: 0.33333333 | N15: =+$E$15*$L$15 -> 0 | O15: =F15*L15 -> 2500 | P15: =+$C$15*$L$15 -> 5000 | Q15: =+$C$15*$L$15 -> 5000 | R15: =+$C$15*$L$15-2500 -> 2500 | S15: 0 | T15: =+$E$15*$L$15 -> 0
B16: ='MAPA INVESTIMENTOS'!A3 -> Licenças e Ferramentas (SaaS e APIs) | C16: 4000 | F16: 2000 | G16: =+F16-O16+2000 -> 3333.3333 | H16: =+G16-P16 -> 2000 | I16: =+H16-Q16 -> 666.66667 | L16: 0.33333333 | O16: =F16*L16 -> 666.66667 | P16: =+$C$16*$L$16 -> 1333.3333 | Q16: =+$C$16*$L$16 -> 1333.3333 | R16: =+$C$16*$L$16-666.67 -> 666.66333 | S16: =+$E$16*$L$16 -> 0
B17: ='MAPA INVESTIMENTOS'!A4 -> Consultoria (Desenvolvimento e IA) | C17: 40000 | F17: 20000 | G17: =+F17-O17+20000 -> 33333.333 | H17: =+G17-P17 -> 20000 | I17: =+H17-Q17 -> 6666.6667 | J17: 0 | L17: 0.33333333 | N17: =+$E$15*$L$15 -> 0 | O17: =F17*L17 -> 6666.6667 | P17: =+$C$17*$L$17 -> 13333.333 | Q17: =+$C$17*$L$17 -> 13333.333 | R17: =+$C$17*$L$17-6666.67 -> 6666.6633 | S17: 0 | T17: =+$E$15*$L$15 -> 0
B18: ='MAPA INVESTIMENTOS'!A5 -> Validação de Despesas | C18: 2500 | F18: 1250 | G18: =+F18-O18+2500 -> 3333.3333 | H18: =+G18-P18 -> 2500 | I18: =+H18-Q18 -> 1666.6667 | J18: 0 | L18: 0.33333333 | N18: =+$E$15*$L$15 -> 0 | O18: =F18*L18 -> 416.66667 | P18: =+$C$18*$L$18 -> 833.33333 | Q18: =+$C$18*$L$18 -> 833.33333 | R18: =+$C$18*$L$18-416.67 -> 416.66333 | S18: 0 | T18: =+$E$15*$L$15 -> 0
L19: 0.33333333
D20: =SUM(D15:D19) -> 0 | E20: =SUM(E15:E19) -> 0 | F20: =SUM(F15:F19) -> 30750 | G20: =SUM(G15:G19) -> 52500 | H20: =SUM(H15:H19) -> 32000 | I20: =SUM(I15:I19) -> 11500 | M20: =SUM(M6:M16) -> 0 | N20: =SUM(N6:N16) -> 108066.88 | O20: =SUM(O6:O16) -> 110438.25 | P20: =SUM(P6:P16) -> 113604.92 | Q20: =SUM(Q6:Q16) -> 113604.92 | R20: =SUM(R6:R16) -> 13023.453 | S20: =SUM(S6:S16) -> 0 | T20: =SUM(T6:T16) -> 0
A24: Índice
B29: Desenvolvimento e Banco de Dados | C29: 12500 | D29: 12500 | E29: 167370.81
B30: Licenças e Ferramentas | C30: 4855 | D30: 4855
B31: Consumo de Tokens | C31: 4000 | D31: 4000
B32: Consultoria (Integração e formação) | C32: 15000 | D32: 15000

Sheet Serviço da Divida Emp. Bancario
A1: FINANCIAMENTO REEMBOLSÁVEL P2020
A3: Rubricas | C3: 2025 | D3: =+C3+1 -> 2026 | E3: =+D3+1 -> 2027 | F3: =+E3+1 -> 2028 | G3: =+F3+1 -> 2029 | H3: =+G3+1 -> 2030 | I3: =+H3+1 -> 2031 | J3: =+I3+1 -> 2032 | K3: =+J3+1 -> 2033 | L3: =+K3+1 -> 2034
A5: Capital em dívida (início período) | B5: =+'MAPA INVESTIMENTOS'!B20+'MAPA INVESTIMENTOS'!C20 -> 0 | C5: =+B5 -> 0 | D5: =+C5 -> 0 | E5: =+B5 -> 0 | F5: =+E8 -> 0 | G5: =+F8 -> 0 | H5: =+G8 -> 0 | I5: =+H8 -> 0 | J5: =+I8 -> 0 | K5: =+J8 -> 0 | L5: =+K8 -> 0
A6: Juro Anual | C6: =+C5*$B$10 -> 0 | D6: =+D5*$B$10 -> 0 | E6: =+E5*$B$10 -> 0 | F6: =+F5*$B$10 -> 0 | G6: =+G5*$B$10 -> 0 | H6: =+H5*$B$10 -> 0 | I6: =+I5*$B$10 -> 0 | J6: =+J5*$B$10 -> 0 | ... L6: =+L5*$B$10 -> 0
A7: Reembolso Anual | C7: 0 | D7: 0 | E7: =+$B$5/8 -> 0 | F7: =+$B$5/8 -> 0 | G7: =+$B$5/8 -> 0 | H7: =+$B$5/8 -> 0 | I7: =+$B$5/8 -> 0 | J7: =+$B$5/8 -> 0 | K7: =+$B$5/8 -> 0 | L7: =+$B$5/8 -> 0
A8: Valor em dívida | C8: =+C5-C7 -> 0 | D8: =+D5-D7 -> 0 | E8: =+E5-E7 -> 0 | F8: =+F5-F7 -> 0 | G8: =+G5-G7 -> 0 | H8: =+H5-H7 -> 0 | I8: =+I5-I7 -> 0 | J8: =+J5-J7 -> 0 | ... L8: =+L5-L7 -> 0
A10: Taxa de juro associada | B10: 0
A12: Nº DE ANOS REEMBOLSO | B12: 8
A14: FINANCIAMENTO EXISTENTE NA EMPRESA
A16: Rubricas | C16: 2024 | D16: =+C16+1 -> 2025 | E16: =+D16+1 -> 2026 | F16: =+E16+1 -> 2027 | G16: =+F16+1 -> 2028 | H16: =+G16+1 -> 2029 | I16: =+H16+1 -> 2030 | J16: =+I16+1 -> 2031 | K16: =+J16+1 -> 2032 | L16: =+K16+1 -> 2033
A18: Capital em dívida (início período) | B18: =136771.42+1455995.87 -> 1592767.3 | C18: =+B18 -> 1592767.3 | D18: =+C21 -> 1592767.3 | E18: =+D21 -> 1433490.6 | F18: =+E21 -> 1274213.8 | G18: =+F21 -> 1114937.1 | H18: =+G21 -> 955660.37 | I18: =+H21 -> 796383.64 | J18: =+I21 -> 637106.92 | K18: =+J21 -> 438011
A19: Juro Anual | C19: 126488.01 | D19: =+D18*$B$23 -> 126488.02 | E19: =+E18*$B$23 -> 113839.22 | F19: =+F18*$B$23 -> 101190.42 | G19: =+G18*$B$23 -> 88541.615 | H19: =+H18*$B$23 -> 75892.813 | I19: =+I18*$B$23 -> 63244.011 | J19: =+J18*$B$23 -> 50595.209 | K19: =+K18*$B$23 -> 34784.206 | L19: =+L18*$B$23 -> 0
A20: Reembolso Anual | D20: =+$B$18/$B$25 -> 159276.73 | E20: =+$B$18/$B$25 -> 159276.73 | F20: =+$B$18/$B$25 -> 159276.73 | G20: =+$B$18/$B$25 -> 159276.73 | H20: =+$B$18/$B$25 -> 159276.73 | I20: =+$B$18/$B$25 -> 159276.73 | J20: =+$B$18/8 -> 199095.91 | K20: =+$B$18/8 -> 199095.91 | L20: =+$B$18/$B$25 -> 159276.73
A21: Valor em dívida | C21: =+C18-C20 -> 1592767.3 | D21: =+D18-D20 -> 1433490.6 | E21: =+E18-E20 -> 1274213.8 | F21: =+F18-F20 -> 1114937.1 | G21: =+G18-G20 -> 955660.37 | H21: =+H18-H20 -> 796383.64 | I21: =+I18-I20 -> 637106.92 | J21: =+J18-J20 -> 438011 | ... L21: =+L18-L20 -> -159276.73
A23: Taxa de juro associada | B23: 0.079414
A25: Nº DE ANOS REEMBOLSO | B25: 10

Sheet Mov dos Impostos S Rendi
A3: Rubricas | B3: 2025 | C3: =+B3+1 -> 2026 | D3: =+C3+1 -> 2027 | E3: =+D3+1 -> 2028 | F3: =+E3+1 -> 2029 | G3: =+F3+1 -> 2030 | H3: =+G3+1 -> 2031
A4: Colecta de IRC 17% | B4: =-'DR SNC'!F30 -> 4250 | C4: =-'DR SNC'!G30 -> 4250 | D4: =-'DR SNC'!H30 -> 4250 | E4: =-'DR SNC'!I30 -> 4250 | F4: =-'DR SNC'!J30 -> 4250 | G4: =-'DR SNC'!K30 -> 0 | H4: =-'DR SNC'!L30 -> 0
A5: Colecta de IRC 21% | B5: =-'DR SNC'!F31 -> -2903.872 | C5: =-'DR SNC'!G31 -> 58694.78 | D5: =-'DR SNC'!H31 -> 120574.59 | E5: =-'DR SNC'!I31 -> 164432.58 | F5: =-'DR SNC'!J31 -> 146589.27 | G5: =-'DR SNC'!K31 -> 0 | H5: =-'DR SNC'!L31 -> 0
A6: Provisão para Impostos | B6: =SUM(B4:B5) -> 1346.128 | C6: =SUM(C4:C5) -> 62944.78 | D6: =SUM(D4:D5) -> 124824.59 | E6: =SUM(E4:E5) -> 168682.58 | F6: =SUM(F4:F5) -> 150839.27 | G6: =SUM(G4:G5) -> 0 | H6: =SUM(H4:H5) -> 0
A9: Índice

Sheet MEIOS LIBERTOS PROJETO
A1: Rubricas | B1: 2025 | C1: =+B1+1 -> 2026 | D1: =+C1+1 -> 2027 | E1: =+D1+1 -> 2028 | F1: =+E1+1 -> 2029 | G1: =+F1+1 -> 2030 | H1: =+G1+1 -> 2031
A2: Recebimentos do Ano
A3: Vendas do Ano | B3: =+'DR SNC'!F7 -> 10560493 | C3: =+'DR SNC'!G7 -> 12144567 | D3: =+'DR SNC'!H7 -> 14087698 | E3: =+'DR SNC'!I7 -> 15073836 | F3: =+'DR SNC'!J7 -> 15375313 | G3: =+'DR SNC'!K7 -> 0 | H3: =+'DR SNC'!L7 -> 0
A4: (+) Total dos Recebimentos | B4: =SUM(B3:B3) -> 10560493 | C4: =SUM(C3:C3) -> 12144567 | D4: =SUM(D3:D3) -> 14087698 | E4: =SUM(E3:E3) -> 15073836 | F4: =SUM(F3:F3) -> 15375313 | G4: =SUM(G3:G3) -> 0 | H4: =SUM(H3:H3) -> 0
A5: Pagamentos do Ano
A6: Compras pagas no ano | B6: =+'Capital Circulante'!B18 -> 6845333 | C6: =+'Capital Circulante'!C18 -> 6755095.9 | D6: =+'Capital Circulante'!D18 -> 7768360.3 | E6: =+'Capital Circulante'!E18 -> 9011298.1 | F6: =+'Capital Circulante'!F18 -> 9491350.1 | G6: =+'Capital Circulante'!G18 -> 9834930.2 | H6: =+'Capital Circulante'!H18 -> 10031629
A7: Encargos com Pessoal | B7: =+'63_G. Pess.'!C15 -> 1511597.3 | C7: =+'63_G. Pess.'!D15 -> 1587177.1 | D7: =+'63_G. Pess.'!E15 -> 1690390.7 | E7: =+'63_G. Pess.'!F15 -> 1859429.7 | F7: =+'63_G. Pess.'!G15 -> 1998886.9 | G7: =+'63_G. Pess.'!H15 -> 2098831.3 | H7: =+'63_G. Pess.'!I15 -> 2203772.9
A8: Fornecimentos e Serviços externos | B8: =+'Fornecimento Serviços Externos'!C18 -> 1690908.7 | C8: =+'Fornecimento Serviços Externos'!D18 -> 1695000 | D8: =+'Fornecimento Serviços Externos'!E18 -> 1847955 | E8: =+'Fornecimento Serviços Externos'!F18 -> 2014964.6 | F8: =+'Fornecimento Serviços Externos'!G18 -> 2108064.9 | G8: =+'Fornecimento Serviços Externos'!H18 -> 2163353 | H8: =+'Fornecimento Serviços Externos'!I18 -> 2220140.7
A9: Encargos Financeiros ( Juros + Amort Capital) | B9: =+'Serviço da Divida Emp. Bancario'!C6+'Serviço da Divida Emp. Bancario'!C7 -> 0 | C9: =+'Serviço da Divida Emp. Bancario'!D6+'Serviço da Divida Emp. Bancario'!D7 -> 0 | D9: =+'Serviço da Divida Emp. Bancario'!E6+'Serviço da Divida Emp. Bancario'!E7 -> 0 | E9: =+'Serviço da Divida Emp. Bancario'!F6+'Serviço da Divida Emp. Bancario'!F7 -> 0 | F9: =+'Serviço da Divida Emp. Bancario'!G6+'Serviço da Divida Emp. Bancario'!G7 -> 0 | G9: =+'Serviço da Divida Emp. Bancario'!H6+'Serviço da Divida Emp. Bancario'!H7 -> 0 | H9: =+'Serviço da Divida Emp. Bancario'!I6+'Serviço da Divida Emp. Bancario'!I7 -> 0
A10: Imposto sobre o Rendimento | B10: =+'Mov dos Impostos S Rendi'!B6 -> 1346.128 | C10: =+'Mov dos Impostos S Rendi'!C6 -> 62944.78 | D10: =+'Mov dos Impostos S Rendi'!D6 -> 124824.59 | E10: =+'Mov dos Impostos S Rendi'!E6 -> 168682.58 | F10: =+'Mov dos Impostos S Rendi'!F6 -> 150839.27 | G10: =+'Mov dos Impostos S Rendi'!G6 -> 0 | H10: =+'Mov dos Impostos S Rendi'!H6 -> 0
A11: (-) Total dos Pagamentos | B11: =SUM(B6:B10) -> 10049185 | C11: =SUM(C6:C10) -> 10100218 | D11: =SUM(D6:D10) -> 11431531 | E11: =SUM(E6:E10) -> 13054375 | F11: =SUM(F6:F10) -> 13749141 | G11: =SUM(G6:G10) -> 14097115 | H11: =SUM(H6:H10) -> 14455542
A12: (=) Saldo do Ano | B12: =+B4-B11 -> 511307.96 | C12: =+C4-C11 -> 2044349.2 | D12: =+D4-D11 -> 2656167.4 | E12: =+E4-E11 -> 2019460.9 | F12: =+F4-F11 -> 1626171.5 | G12: =+G4-G11 -> -14097115 | H12: =+H4-H11 -> -14455542
A15: Índice

Sheet Plano Financeiro 
B1: 2025 | C1: =+B1+1 -> 2026 | D1: =+C1+1 -> 2027 | E1: =+D1+1 -> 2028 | F1: =+E1+1 -> 2029 | G1: =+F1+1 -> 2030 | H1: =+G1+1 -> 2031
A2: Necessidades Financeiras
A3: Investimento em Imobilizado | C3: =Amortizações!F20 -> 30750 | D3: =Amortizações!G20 -> 52500 | E3: =Amortizações!H20 -> 32000 | F3: =Amortizações!I20 -> 11500 | G3: =Amortizações!J20 -> 0 | H3: =Amortizações!K20 -> 0
A4: Investimento em Fundo Maneio | B4: =IF('Capital Circulante'!B8>0,'Capital Circulante'!B8,0) -> 1023001.4 | C4: =IF('Capital Circulante'!C8>0,'Capital Circulante'!C8,0) -> 0 | D4: =IF('Capital Circulante'!D8>0,'Capital Circulante'!D8,0) -> 151427.4 | E4: =IF('Capital Circulante'!E8>0,'Capital Circulante'!E8,0) -> 185750.96 | F4: =IF('Capital Circulante'!F8>0,'Capital Circulante'!F8,0) -> 111017.23 | G4: =IF('Capital Circulante'!G8>0,'Capital Circulante'!G8,0) -> 12070.55 | H4: =IF('Capital Circulante'!H8>0,'Capital Circulante'!H8,0) -> 29395.642
A5: Reembolso de Empréstimos MLP | B5: =+'Serviço da Divida Emp. Bancario'!C7+'Serviço da Divida Emp. Bancario'!C20 -> 0 | C5: =+'Serviço da Divida Emp. Bancario'!D7+'Serviço da Divida Emp. Bancario'!D20 -> 159276.73 | D5: =+'Serviço da Divida Emp. Bancario'!E7+'Serviço da Divida Emp. Bancario'!E20 -> 159276.73 | E5: =+'Serviço da Divida Emp. Bancario'!F7+'Serviço da Divida Emp. Bancario'!F20 -> 159276.73 | F5: =+'Serviço da Divida Emp. Bancario'!G7+'Serviço da Divida Emp. Bancario'!G20 -> 159276.73 | G5: =+'Serviço da Divida Emp. Bancario'!H7+'Serviço da Divida Emp. Bancario'!H20 -> 159276.73 | H5: =+'Serviço da Divida Emp. Bancario'!I7+'Serviço da Divida Emp. Bancario'!I20 -> 159276.73
A6: IRC | B6: =+'Mov dos Impostos S Rendi'!B6 -> 1346.128 | C6: =+'Mov dos Impostos S Rendi'!C6 -> 62944.78 | D6: =+'Mov dos Impostos S Rendi'!D6 -> 124824.59 | E6: =+'Mov dos Impostos S Rendi'!E6 -> 168682.58 | F6: =+'Mov dos Impostos S Rendi'!F6 -> 150839.27 | G6: =+'Mov dos Impostos S Rendi'!G6 -> 0 | H6: =+'Mov dos Impostos S Rendi'!H6 -> 0
A7: Juros de Empréstimos MLP | B7: =+'Serviço da Divida Emp. Bancario'!C19 -> 126488.01 | C7: =+'Serviço da Divida Emp. Bancario'!D19 -> 126488.02 | D7: =+'Serviço da Divida Emp. Bancario'!E19 -> 113839.22 | E7: =+'Serviço da Divida Emp. Bancario'!F19 -> 101190.42 | F7: =+'Serviço da Divida Emp. Bancario'!G19 -> 88541.615 | G7: =+'Serviço da Divida Emp. Bancario'!H19 -> 75892.813 | H7: =+'Serviço da Divida Emp. Bancario'!I19 -> 63244.011
A8: Total | B8: =SUM(B3:B7) -> 1150835.6 | C8: =SUM(C3:C7) -> 379459.53 | D8: =SUM(D3:D7) -> 601867.93 | E8: =SUM(E3:E7) -> 646900.69 | F8: =SUM(F3:F7) -> 521174.84 | G8: =SUM(G3:G7) -> 247240.09 | H8: =SUM(H3:H7) -> 251916.38
A9: Recursos Financeiros
A10: Aumento de Capital | B10: 0
A11: Prestações Suplementares | B11: 0 | C11: =+'MAPA INVESTIMENTOS'!B18 -> 14592.875 | D11: =+'MAPA INVESTIMENTOS'!C18 -> 14592.875
A12: EBITDA | B12: =+'DR SNC'!F19 -> 257726.93 | C12: =+'DR SNC'!G19 -> 553425.23 | D12: =+'DR SNC'!H19 -> 838608.84 | E12: =+'DR SNC'!I19 -> 1034807.6 | F12: =+'DR SNC'!J19 -> 836609.21 | G12: =+'DR SNC'!K19 -> 0 | H12: =+'DR SNC'!L19 -> 0
A13: Desinvestimento em Fundo Maneio | B13: =IF('Capital Circulante'!B8<0,-'Capital Circulante'!B8,0) -> 0 | C13: =IF('Capital Circulante'!C8<0,-'Capital Circulante'!C8,0) -> 13485.485 | D13: =IF('Capital Circulante'!D8<0,-'Capital Circulante'!D8,0) -> 0 | E13: =IF('Capital Circulante'!E8<0,-'Capital Circulante'!E8,0) -> 0 | F13: =IF('Capital Circulante'!F8<0,-'Capital Circulante'!F8,0) -> 0 | G13: =IF('Capital Circulante'!G8<0,-'Capital Circulante'!G8,0) -> 0 | H13: =IF('Capital Circulante'!H8<0,-'Capital Circulante'!H8,0) -> 0
A14: Empréstimos MLP P2020 | C14: =+'Serviço da Divida Emp. Bancario'!C5 -> 0 | D14: =[1]MapaServiçoDívida!G5 -> 0 | E14: =[1]MapaServiçoDívida!H5 -> 0 | F14: =[1]MapaServiçoDívida!I5 -> 0 | G14: 0 | H14: 0
A15: Total | B15: =SUM(B10:B14) -> 257726.93 | C15: =SUM(C10:C14) -> 581503.58 | D15: =SUM(D10:D14) -> 853201.71 | E15: =SUM(E10:E14) -> 1034807.6 | F15: =SUM(F10:F14) -> 836609.21 | G15: =SUM(G10:G14) -> 0 | H15: =SUM(H10:H14) -> 0
A16: Saldo Anual | B16: =B15-B8 -> -893108.65 | C16: =C15-C8 -> 202044.05 | D16: =D15-D8 -> 251333.78 | E16: =E15-E8 -> 387906.91 | F16: =F15-F8 -> 315434.37 | G16: =G15-G8 -> -247240.09 | H16: =H15-H8 -> -251916.38
A17: Disponibilidades Iniciais | B17: =+'Balanço SNC'!D21 -> 20361.27 | C17: =B18 -> -872747.38 | D17: =C18 -> -670703.32 | E17: =D18 -> -419369.54 | F17: =E18 -> -31462.631 | G17: =F18 -> 283971.74 | H17: =G18 -> 36731.643
A18: Disponibilidades Finais | B18: =B17+B16 -> -872747.38 | C18: =C17+C16 -> -670703.32 | D18: =D17+D16 -> -419369.54 | E18: =E17+E16 -> -31462.631 | F18: =F17+F16 -> 283971.74 | G18: =G17+G16 -> 36731.643 | H18: =H17+H16 -> -215184.74
A20: Índice

Sheet DR SNC
A3: Rúbricas | C3: 2022 | D3: 2023 | E3: 2024 | F3: 2025 | G3: 2026 | H3: 2027 | I3: 2028 | J3: 2029 | K3: 2030 | L3: 2031
A5: RENDIMENTOS E GASTOS
A7: Vendas e serviços prestados | E7: =+'Previsão Receitas'!B8 -> 10701564 | F7: =+'Previsão Receitas'!C8 -> 10560493 | G7: =+'Previsão Receitas'!D8 -> 12144567 | H7: =+'Previsão Receitas'!E8 -> 14087698 | I7: =+'Previsão Receitas'!F8 -> 15073836 | J7: =+'Previsão Receitas'!G8 -> 15375313
A8: Subsídios à exploração | G8: =+'MAPA INVESTIMENTOS'!B19 -> 43778.625 | H8: =+'MAPA INVESTIMENTOS'!C19 -> 43778.625
A9: Ganhos/perdas imputados de subsidiárias, associadas e empreend
A10: Variação nos inventários da produção | E10: 3604.78
A11: Custo das mercadorias vendidas e das matérias consumidas | E11: =-'Capital Circulante'!B18 -> -6845333 | F11: =-'Capital Circulante'!C18 -> -6755095.9 | G11: =-'Capital Circulante'!D18 -> -7768360.3 | H11: =-'Capital Circulante'!E18 -> -9011298.1 | I11: =-'Capital Circulante'!F18 -> -9491350.1 | J11: =-'Capital Circulante'!G18 -> -9834930.2
A12: Fornecimentos e serviços externos | E12: =-'Fornecimento Serviços Externos'!C18 -> -1690908.7 | F12: =-'Fornecimento Serviços Externos'!D18 -> -1695000 | G12: =-'Fornecimento Serviços Externos'!E18 -> -1847955 | H12: =-'Fornecimento Serviços Externos'!F18 -> -2014964.6 | I12: =-'Fornecimento Serviços Externos'!G18 -> -2108064.9 | J12: =-'Fornecimento Serviços Externos'!H18 -> -2163353
A13: Gastos com o pessoal | E13: =-'63_G. Pess.'!C15 -> -1511597.3 | F13: =-'63_G. Pess.'!D15 -> -1587177.1 | G13: =-'63_G. Pess.'!E15 -> -1690390.7 | H13: =-'63_G. Pess.'!F15 -> -1859429.7 | I13: =-'63_G. Pess.'!G15 -> -1998886.9 | J13: =-'63_G. Pess.'!H15 -> -2098831.3
A14: Imparidade de dividas a receber (perdas/reversões) | E14: -21484.75
A15: Aumentos/reduções de justo valor
A16: Outros rendimentos e ganhos | E16: 263393.26 | F16: 228974.44 | G16: =F16*1.05 -> 240423.16 | H16: =G16*1.05 -> 252444.32 | I16: =H16*1.05 -> 265066.54 | J16: =I16*1.05 -> 278319.86 | M16: Receitas suplementares
A17: Outros gastos e perdas | E17: -556934.01 | F17: -494467.47 | G17: =F17/F7*G7 -> -568637.59 | H17: =G17/G7*H7 -> -659619.62 | I17: =H17/H7*I7 -> -705792.95 | J17: =I17/I7*J7 -> -719908.81 | M17: Descontos de pronto pagamento concedidos
A19: Resultados antes de deprec, gastos de finan e impostos | C19: =SUM(C7:C18) -> 0 | E19: =SUM(E7:E18) -> 342304.31 | F19: =SUM(F7:F18) -> 257726.93 | G19: =SUM(G7:G18) -> 553425.23 | H19: =SUM(H7:H18) -> 838608.84 | I19: =SUM(I7:I18) -> 1034807.6 | J19: =SUM(J7:J18) -> 836609.21 | K19: =SUM(K7:K18) -> 0 | L19: =SUM(L7:L18) -> 0
A21: Gastos/reversões de depreciação e de amortização | E21: -108066.68 | F21: =-Amortizações!N20 -> -108066.88 | G21: =-Amortizações!O20 -> -110438.25 | H21: =-Amortizações!P20 -> -113604.92 | I21: =-Amortizações!Q20 -> -113604.92 | J21: =-Amortizações!R20 -> -13023.453
A22: Imparidade de invest depreciáveis/amortizáveis (perdas/reversões)
A24: Resultado operacional (antes de gastos de financiamento e impostos) | C24: =+C19+C21+C22 -> 0 | E24: =+E19+E21+E22 -> 234237.63 | F24: =+F19+F21+F22 -> 149660.05 | G24: =+G19+G21+G22 -> 442986.98 | H24: =+H19+H21+H22 -> 725003.92 | I24: =+I19+I21+I22 -> 921202.68 | J24: =+J19+J21+J22 -> 823585.75
A26: Juros e rendimentos similares obtidos
A27: Juros e gastos similares suportados | E27: -126488.01 | F27: =-'Serviço da Divida Emp. Bancario'!C19-12000 -> -138488.01 | G27: =-'Serviço da Divida Emp. Bancario'!D19-12000 -> -138488.02 | H27: =-'Serviço da Divida Emp. Bancario'!E19-12000 -> -125839.22 | I27: =-'Serviço da Divida Emp. Bancario'!F19-12000 -> -113190.42 | J27: =-'Serviço da Divida Emp. Bancario'!G19-12000 -> -100541.62
A29: Resultado antes de impostos | C29: =SUM(C24:C27) -> 0 | E29: =SUM(E24:E27) -> 107749.62 | F29: =SUM(F24:F27) -> 11172.038 | G29: =SUM(G24:G27) -> 304498.95 | H29: =SUM(H24:H27) -> 599164.7 | I29: =SUM(I24:I27) -> 808012.27 | J29: =SUM(J24:J27) -> 723044.14
B30: 0.17 | E30: -21617.37 | F30: =-25000*$B$30 -> -4250 | G30: =-25000*$B$30 -> -4250 | H30: =-25000*$B$30 -> -4250 | I30: =-25000*$B$30 -> -4250 | J30: =-25000*$B$30 -> -4250
A31: Imposto sobre o rendimento do período | B31: 0.21 | F31: =-(F29-25000)*$B$31 -> 2903.872 | G31: =-(G29-25000)*$B$31 -> -58694.78 | H31: =-(H29-25000)*$B$31 -> -120574.59 | I31: =-(I29-25000)*$B$31 -> -164432.58 | J31: =-(J29-25000)*$B$31 -> -146589.27 | M31: =4250+119189.88 -> 123439.88
A32: Resultado líquido do período | C32: =SUM(C29:C31) -> 0 | E32: =SUM(E29:E31) -> 86132.246 | F32: =SUM(F29:F31) -> 9825.9103 | G32: =SUM(G29:G31) -> 241554.17 | H32: =SUM(H29:H31) -> 474340.11 | I32: =SUM(I29:I31) -> 639329.69 | J32: =SUM(J29:J31) -> 572204.87
A36: Índice
A40: VBP | B40: Pré-Projeto 2024 | C40: Pós-Projeto 2028
A41: Volume de Negócios | B41: =E7 -> 10701564 | C41: =I7 -> 15073836
A42: Variação nos inventários da produção | B42: =E10 -> 3604.78 | C42: 0 | I42: =I7 -> 15073836 | J42: 100
A43: Trabalhos para a própria entidade | B43: 0 | C43: 0 | I43: x | J43: 20
A44: Rendimentos Suplementares | B44: =E16 -> 263393.26 | C44: =I16 -> 265066.54
A45: Subsídios à Exploração | B45: =E8 -> 0 | C45: =I8 -> 0 | I45: x | J45: =J43*I42/J42 -> 3014767.2 | L45: 3014767.2
A46: Total | B46: =SUM(B41:B45) -> 10968562 | C46: =SUM(C41:C45) -> 15338903
A47: CI | B47: Pré-Projeto | C47: Pós-Projeto | I47: =E7 -> 10701564 | J47: 100
A48: CMVMC | B48: =-E11 -> 6845333 | C48: =-I11 -> 9491350.1 | I48: 1330927.1 | J48: x
A49: FSE | B49: =-E12 -> 1690908.7 | C49: =-I12 -> 2108064.9 | I49: x | J49: =I48*J47/I47 -> 12.436754
A50: Impostos Indiretos | B50: 0 | C50: 0
A51: Total | B51: =SUM(B48:B50) -> 8536241.6 | C51: =SUM(C48:C50) -> 11599415
A52: VAB | B52: =B46-B51 -> 2432320.3 | C52: =C46-C51 -> 3739487.5
B55: =B52 -> 2432320.3 | C55: 100
B56: =C52 -> 3739487.5 | C56: X
B58: X | C58: =B56*C55/B55 -> 153.74157
...

Sheet Balanço SNC
A1: RUBRICAS | B1: Exercício
B2: 2022 | C2: 2023 | D2: 2024 | E2: 2025 | F2: =+E2+1 -> 2026 | G2: =+F2+1 -> 2027 | H2: =+G2+1 -> 2028 | I2: =+H2+1 -> 2029 | J2: =+I2+1 -> 2030 | K2: =+J2+1 -> 2031
A3: ACTIVO
A5: Activo não corrente:
A6: Activos fixos tangíveis | D6: 432693.12 | E6: =Amortizações!E6 -> 326671.54 | F6: =Amortizações!F6 -> 220649.95 | G6: =Amortizações!G6*1.15 -> 131822.62 | H6: =Amortizações!H6*1.3 -> 11188.821 | L6: 858742.88
A7: Propriedades de investimento | E7: =D7 -> 0 | F7: =E7 -> 0 | G7: =F7 -> 0 | H7: =G7 -> 0 | I7: =H7 -> 0 | L7: 236590.85
A8: Activos intangíveis | D8: 2045.3 | E8: =+Amortizações!E14 -> 0 | F8: =+Amortizações!F14 -> 30750 | G8: =+Amortizações!G14 -> 52500 | H8: =+Amortizações!H14 -> 32000 | I8: =+Amortizações!I14 -> 11500 | L8: 37605
A9: Participações Financeiras - Método da equivalência patrimonial | E9: =D9 -> 0 | F9: =E9 -> 0 | G9: =F9 -> 0 | H9: =G9 -> 0 | I9: =H9 -> 0 | L9: 102416.64
A10: Investimentos Financeiros
B11: =SUM(B6:B9) -> 0 | D11: =SUM(D6:D10) -> 434738.42 | E11: =SUM(E6:E10) -> 326671.54 | F11: =SUM(F6:F10) -> 251399.95 | G11: =SUM(G6:G10) -> 184322.62 | H11: =SUM(H6:H10) -> 43188.821 | I11: =SUM(I6:I10) -> 11500 | L11: 1235355.4
A13: Activo corrente:
A14: Inventários | D14: 284714.37 | E14: =+'Capital Circulante'!B4 -> 285222.21 | F14: =+'Capital Circulante'!C4 -> 281462.33 | G14: =+'Capital Circulante'!D4 -> 323681.68 | H14: =+'Capital Circulante'!E4 -> 375470.76 | I14: =+'Capital Circulante'!F4 -> 395472.92 | L14: 294938.73
A15: Ativos Biológicos | D15: 3604.78
A16: Clientes | D16: 1802545.7 | E16: =+'Capital Circulante'!C3 -> 1760082.2 | F16: =+'Capital Circulante'!D3 -> 2024094.5 | G16: =+'Capital Circulante'!E3 -> 2347949.7 | H16: =+'Capital Circulante'!F3 -> 2512306 | I16: =+'Capital Circulante'!G3 -> 2562552.1 | L16: 1803906.6
A17: Adiantamentos a Fornecedores | D17: 78586.32 | E17: =D17*1.01 -> 79372.183 | F17: =E17*1.01 -> 80165.905 | G17: =F17*1.01 -> 80967.564 | H17: =G17*1.01 -> 81777.24 | I17: =H17*1.01 -> 82595.012
A18: Estado E Outros Entes Públicos | D18: 318043.34 | E18: =D18*1.04 -> 330765.07 | F18: =E18*1.03 -> 340688.03 | G18: =F18*1.02 -> 347501.79 | H18: =G18*1.02 -> 354451.82 | I18: =H18*1.02 -> 361540.86 | L18: 438748.81
A19: Outras Contas a Receber | D19: 401500.8 | E19: =D19 -> 401500.8 | F19: =E19 -> 401500.8 | G19: =F19 -> 401500.8 | H19: =G19 -> 401500.8 | I19: =H19 -> 401500.8 | L19: 463434.78
A20: Diferimentos | D20: 29971.55 | E20: =D20*1.04 -> 31170.412 | F20: =E20*1.03 -> 32105.524 | G20: =F20*1.02 -> 32747.635 | H20: =G20*1.02 -> 33402.588 | I20: =H20*1.02 -> 34070.639 | L20: 38864.659
A21: Caixa e depósitos bancários | D21: 20361.27 | E21: =+'Plano Financeiro '!B18+939838.77 -> 67091.394 | F21: =+'Plano Financeiro '!C18+665844.81 -> -4858.512 | G21: =+'Plano Financeiro '!D18+653596.67 -> 234227.13 | H21: =+'Plano Financeiro '!E18+896067.71 -> 864605.08 | I21: =+'Plano Financeiro '!F18+1001925.12 -> 1285896.9 | L21: 1407459
B22: =SUM(B14:B21) -> 0 | D22: =SUM(D14:D21) -> 2939328.1 | E22: =SUM(E14:E21) -> 2955204.2 | F22: =SUM(F14:F21) -> 3155158.6 | G22: =SUM(G14:G21) -> 3768576.3 | H22: =SUM(H14:H21) -> 4623514.3 | I22: =SUM(I14:I21) -> 5123629.2 | L22: 4447352.6
A24: Total do Activo | B24: =+B11+B22 -> 0 | D24: =+D11+D22 -> 3374066.5 | E24: =+E11+E22 -> 3281875.8 | F24: =+F11+F22 -> 3406558.5 | G24: =+G11+G22 -> 3952898.9 | H24: =+H11+H22 -> 4666703.1 | I24: =+I11+I22 -> 5135129.2 | L24: 5682708
A27: CAPITAL PRÓPRIO E PASSIVO
A29: Capital próprio:
A30: Capital realizado | D30: 50000 | E30: =D30 -> 50000 | F30: =E30 -> 50000 | G30: =F30 -> 50000 | H30: =G30 -> 50000 | I30: =H30 -> 50000 | L30: 50000
A31: Acções (quotas) próprias
A32: Outros instrumentos de capital próprio | D32: 200000 | E32: =D32 -> 200000 | F32: =+'MAPA INVESTIMENTOS'!B18+E32 -> 214592.88 | G32: =+F32+'MAPA INVESTIMENTOS'!C18 -> 229185.75 | H32: =+G32 -> 229185.75 | I32: =+H32 -> 229185.75 | L32: 37427
A33: Reservas legais | D33: 10000 | E33: =D33 -> 10000 | F33: =E33 -> 10000 | G33: =F33 -> 10000 | H33: =G33 -> 10000 | I33: =H33 -> 10000 | L33: 1000
A34: Outras reservas
A35: Resultados transitados | D35: 158170.42 | E35: =+D35+D38 -> 244302.67 | F35: =+E35+E38 -> 254128.58 | G35: =+F35+F38 -> 495682.75 | H35: =+G35+G38 -> 970022.86 | I35: =+H35+H38 -> 1609352.6 | L35: 1749417.7
A36: Outras variações no capital próprio | E36: =D36 -> 0 | F36: =E36 -> 0 | G36: =F36 -> 0 | H36: =G36 -> 0 | I36: =H36 -> 0 | L36: 47991.79
A38: Resultado líquido do período | B38: 0 | D38: =+'DR SNC'!E32 -> 86132.246 | E38: =+'DR SNC'!F32 -> 9825.9103 | F38: =+'DR SNC'!G32 -> 241554.17 | G38: =+'DR SNC'!H32 -> 474340.11 | H38: =+'DR SNC'!I32 -> 639329.69 | I38: =+'DR SNC'!J32 -> 572204.87 | L38: 469130.96
A39: Interesses minoritários
A41: Total do capital próprio | B41: =SUM(B30:B40) -> 0 | D41: =SUM(D30:D39) -> 504302.67 | E41: =SUM(E30:E40) -> 514128.58 | F41: =SUM(F30:F40) -> 770275.62 | G41: =SUM(G29:G40) -> 1259208.6 | H41: =SUM(H29:H40) -> 1898538.3 | I41: =SUM(I29:I40) -> 2470743.2 | L41: 2354967.4
A43: Passivo
A45: Passivo não corrente:
A46: Financiamentos obtidos | D46: 136771.42 | E46: =D46*0.75 -> 102578.57 | F46: =D46*0.5 -> 68385.71 | G46: =D46*0.25 -> 34192.855 | H46: 0 | I46: 0 | L46: 149838.52
A47: Outras contas a pagar
B49: =SUM(B46:B48) -> 0 | D49: =SUM(D46:D48) -> 136771.42 | E49: =SUM(E46:E48) -> 102578.57 | F49: =SUM(F46:F48) -> 68385.71 | G49: =SUM(G46:G48) -> 34192.855 | H49: =SUM(H46:H48) -> 0 | I49: =SUM(I46:I48) -> 0 | L49: 149838.52
A50: Passivo corrente:
A51: Fornecedores | D51: 987726.43 | E51: =+'Capital Circulante'!B6 -> 1045814.8 | F51: =+'Capital Circulante'!C6 -> 1032028.5 | G51: =+'Capital Circulante'!D6 -> 1186832.8 | H51: =+'Capital Circulante'!E6 -> 1376726.1 | I51: =+'Capital Circulante'!F6 -> 1450067.4 | L51: 2528046.3
...

Sheet Avaliação Investimento
A1: Rubricas | B1: 0 | C1: 2024 | D1: =+C1+1 -> 2025 | E1: =+D1+1 -> 2026 | F1: =+E1+1 -> 2027 | G1: =+F1+1 -> 2028 | H1: =+G1+1 -> 2029 | I1: =+H1+1 -> 2030
A2: Resultado Liquido | B2: 0 | C2: =+'DR SNC'!F32 -> 9825.9103 | D2: =+'DR SNC'!G32 -> 241554.17 | E2: =+'DR SNC'!H32 -> 474340.11 | F2: =+'DR SNC'!I32 -> 639329.69 | G2: =+'DR SNC'!J32 -> 572204.87 | H2: =+'DR SNC'!K32 -> 0 | I2: =+'DR SNC'!L32 -> 0
A3: Amortizações | B3: 0 | C3: =-'DR SNC'!F21 -> 108066.88 | D3: =-'DR SNC'!G21 -> 110438.25 | E3: =-'DR SNC'!H21 -> 113604.92 | F3: =-'DR SNC'!I21 -> 113604.92 | G3: =-'DR SNC'!J21 -> 13023.453 | H3: =-'DR SNC'!K21 -> 0 | I3: =-'DR SNC'!L21 -> 0
A4: Cash Flow de Exploração | B4: =SUM(B2:B3) -> 0 | C4: =SUM(C2:C3) -> 117892.79 | D4: =SUM(D2:D3) -> 351992.42 | E4: =SUM(E2:E3) -> 587945.03 | F4: =SUM(F2:F3) -> 752934.61 | G4: =SUM(G2:G3) -> 585228.32 | H4: =SUM(H2:H3) -> 0 | I4: =SUM(I2:I3) -> 0
A5: Investimento em Capital Circulante
A6: Investimento em Capital Fixo | B6: =+'MAPA INVESTIMENTOS'!B2+'MAPA INVESTIMENTOS'!B3+'MAPA INVESTIMENTOS'!C3+'MAPA INVESTIMENTOS'!C4 -> 31500
A7: Cash Flow Total | B7: =-B6 -> -31500 | C7: =+C4+C5+C6 -> 117892.79 | D7: =+D4+D5+D6 -> 351992.42 | E7: =+E4+E5+E6 -> 587945.03 | F7: =+F4+F5+F6 -> 752934.61 | G7: =+G4+G5+G6 -> 585228.32 | H7: =+H4+H5+H6 -> 0 | I7: =+I4+I5+I6 -> 0
A8: Cash Flow Acumulado | B8: =+B7 -> -31500 | C8: =+B8+C7 -> 86392.794 | D8: =+C8+D7 -> 438385.22 | E8: =+D8+E7 -> 1026330.2 | F8: =+E8+F7 -> 1779264.9 | G8: =+F8+G7 -> 2364493.2 | H8: =+G8+H7 -> 2364493.2 | I8: =+H8+I7 -> 2364493.2
A10: TIR | B10: =IRR(B7:I7) -> 5.1624452
A11: VAL | B11: =NPV(B17,B7,C7:I7) -> 1891350.7
A13: Descrição | B13: %
A14: Taxa de Aplicações Sem Risco (Rf) | B14: 0.02
A15: Taxa de Rendibilidade do Mercado Accionista (Rm) | B15: 0.05
A16: Beta Negócio Sem Efeito de Alavanca (Bu) | B16: 1
A17: Taxa Rendibilidade Desejada (Keu) | B17: 0.05
B19: PAY BACK PERIOD
B21: ANO | C21: Cash-Flows | D21: Cash Flows acumulados
A22: 0 | B22: 0 | C22: =+B8 -> -31500 | D22: =+C22 -> -31500
A23: 2019 | B23: 1 | C23: =+C7 -> 117892.79 | D23: =+D22+C23 -> 86392.794
A24: =+A23+1 -> 2020 | B24: =+B23+1 -> 2 | C24: =+D7 -> 351992.42 | D24: =+D23+C24 -> 438385.22
A25: =+A24+1 -> 2021 | B25: =+B24+1 -> 3 | C25: =+E7 -> 587945.03 | D25: =+D24+C25 -> 1026330.2
A26: =+A25+1 -> 2022 | B26: =+B25+1 -> 4 | C26: =+F7 -> 752934.61 | D26: =+D25+C26 -> 1779264.9
A27: =+A26+1 -> 2023 | B27: =+B26+1 -> 5 | C27: =+G7 -> 585228.32 | D27: =+D26+C27 -> 2364493.2
B30: Payback Simples | C30: =5+(1-D27/C27) -> 1.9597082 | D30: ANOS
A33: Índice

Sheet MAPA INVESTIMENTOS
A1: Designação | B1: INVESTIMENTO 2026 | C1: INVESTIMENTO 2027
A2: Aquisição de Software (MÊS "Digital Factory") | B2: 7500 | C2: 7500
A3: Licenças e Ferramentas (SaaS e APIs) | B3: 2000 | C3: 2000
A4: Consultoria (Desenvolvimento e IA) | B4: 20000 | C4: 20000
A5: Validação de Despesas | B5: 1250 | C5: 1250
A6: Contratação RH | B6: 25121.5 | C6: 25121.5
A7: Aquisição de Hardware (Ecrans e Impressoras) | B7: 2500 | C7: 2500
B11: =SUM(B2:B10) -> 58371.5 | C11: =SUM(C2:C10) -> 58371.5
A13: SUB TOTAL FES´S | B13: =+B8+B9 -> 0 | C13: =+C8+C9 -> 0
A15: INVESTIMENTO TOTAL | B15: =+B11+C11 -> 116743
A16: FINANCIAMENTO PRR GLOBAL | B16: =+B11*0.75 -> 43778.625 | C16: =+C11*0.75 -> 43778.625
A18: CAPITAIS PRÓPRIOS | B18: =+B11*0.25 -> 14592.875 | C18: =+C11*0.25 -> 14592.875 | D18: =SUM(B18:C18) -> 29185.75
A19: FINANCIAMENTO P2020 FUNDO PERDIDO 75% DO VALOR GLOBAL | B19: =+B11*0.75 -> 43778.625 | C19: =+C11*0.75 -> 43778.625 | D19: =SUM(B19:C19) -> 87557.25
A20: FINANCIAMENTO P2020 REEMBOLSÁVEL 0% DO VALOR GLOBAL | B20: =+B16*0 -> 0 | C20: =+C16*0 -> 0 | D20: =SUM(B20:C20) -> 0
A21: TOTAL FINANCIAMENTO | B21: =SUM(B18:B20) -> 58371.5 | C21: =SUM(C18:C20) -> 58371.5 | D21: =SUM(B21:C21) -> 116743
